[2025-03-19 23:51:48,687] [ERROR] [data_collection] - Erro na coleta de dados para caracteristicas_fundo
(<class 'ValueError'>, ValueError('Invalid frequency: ME'), <traceback object at 0x0000025EF9CE9280>)
Traceback (most recent call last):
  File "offsets.pyx", line 4447, in pandas._libs.tslibs.offsets._get_offset
KeyError: 'ME'

The above exception was the direct cause of the following exception:

Traceback (most recent call last):
  File "offsets.pyx", line 4549, in pandas._libs.tslibs.offsets.to_offset
  File "offsets.pyx", line 4453, in pandas._libs.tslibs.offsets._get_offset
ValueError: Invalid frequency: ME

The above exception was the direct cause of the following exception:

Traceback (most recent call last):
  File "c:\Users\joaop\Downloads\Projetos Cursor\FIDCs 2.0\src\data\data_collection.py", line 32, in collect_cvm_data
    df = importa_dados(nome_arquivo_fonte=arquivo, data_inicio=data_inicio)
         ^^^^^^^^^^^^^^^^^^^^^^^^^^^^^^^^^^^^^^^^^^^^^^^^^^^^^^^^^^^^^^^^^^
  File "c:\Users\joaop\Downloads\Projetos Cursor\FIDCs 2.0\src\scraping\cvm_scraper.py", line 63, in importa_dados
    datas_a_baixar = pd.date_range(start=data_inicio, end=data_atual, freq='ME')
                     ^^^^^^^^^^^^^^^^^^^^^^^^^^^^^^^^^^^^^^^^^^^^^^^^^^^^^^^^^^^
  File "C:\Users\joaop\AppData\Local\Packages\PythonSoftwareFoundation.Python.3.12_qbz5n2kfra8p0\LocalCache\local-packages\Python312\site-packages\pandas\core\indexes\datetimes.py", line 1009, in date_range
    dtarr = DatetimeArray._generate_range(
            ^^^^^^^^^^^^^^^^^^^^^^^^^^^^^^
  File "C:\Users\joaop\AppData\Local\Packages\PythonSoftwareFoundation.Python.3.12_qbz5n2kfra8p0\LocalCache\local-packages\Python312\site-packages\pandas\core\arrays\datetimes.py", line 404, in _generate_range
    freq = to_offset(freq)
           ^^^^^^^^^^^^^^^
  File "offsets.pyx", line 4460, in pandas._libs.tslibs.offsets.to_offset
  File "offsets.pyx", line 4557, in pandas._libs.tslibs.offsets.to_offset
ValueError: Invalid frequency: ME
[2025-03-19 23:51:48,692] [ERROR] [data_collection] - Erro na coleta de dados para patrimonio_liquido
(<class 'ValueError'>, ValueError('Invalid frequency: ME'), <traceback object at 0x0000025EF9CE92C0>)
Traceback (most recent call last):
  File "offsets.pyx", line 4447, in pandas._libs.tslibs.offsets._get_offset
KeyError: 'ME'

The above exception was the direct cause of the following exception:

Traceback (most recent call last):
  File "offsets.pyx", line 4549, in pandas._libs.tslibs.offsets.to_offset
  File "offsets.pyx", line 4453, in pandas._libs.tslibs.offsets._get_offset
ValueError: Invalid frequency: ME

The above exception was the direct cause of the following exception:

Traceback (most recent call last):
  File "c:\Users\joaop\Downloads\Projetos Cursor\FIDCs 2.0\src\data\data_collection.py", line 32, in collect_cvm_data
    df = importa_dados(nome_arquivo_fonte=arquivo, data_inicio=data_inicio)
         ^^^^^^^^^^^^^^^^^^^^^^^^^^^^^^^^^^^^^^^^^^^^^^^^^^^^^^^^^^^^^^^^^^
  File "c:\Users\joaop\Downloads\Projetos Cursor\FIDCs 2.0\src\scraping\cvm_scraper.py", line 63, in importa_dados
    datas_a_baixar = pd.date_range(start=data_inicio, end=data_atual, freq='ME')
                     ^^^^^^^^^^^^^^^^^^^^^^^^^^^^^^^^^^^^^^^^^^^^^^^^^^^^^^^^^^^
  File "C:\Users\joaop\AppData\Local\Packages\PythonSoftwareFoundation.Python.3.12_qbz5n2kfra8p0\LocalCache\local-packages\Python312\site-packages\pandas\core\indexes\datetimes.py", line 1009, in date_range
    dtarr = DatetimeArray._generate_range(
            ^^^^^^^^^^^^^^^^^^^^^^^^^^^^^^
  File "C:\Users\joaop\AppData\Local\Packages\PythonSoftwareFoundation.Python.3.12_qbz5n2kfra8p0\LocalCache\local-packages\Python312\site-packages\pandas\core\arrays\datetimes.py", line 404, in _generate_range
    freq = to_offset(freq)
           ^^^^^^^^^^^^^^^
  File "offsets.pyx", line 4460, in pandas._libs.tslibs.offsets.to_offset
  File "offsets.pyx", line 4557, in pandas._libs.tslibs.offsets.to_offset
ValueError: Invalid frequency: ME
[2025-03-19 23:51:48,694] [ERROR] [data_collection] - Erro na coleta de dados para carteira_ativos
(<class 'ValueError'>, ValueError('Invalid frequency: ME'), <traceback object at 0x0000025EF9D60F80>)
Traceback (most recent call last):
  File "offsets.pyx", line 4447, in pandas._libs.tslibs.offsets._get_offset
KeyError: 'ME'

The above exception was the direct cause of the following exception:

Traceback (most recent call last):
  File "offsets.pyx", line 4549, in pandas._libs.tslibs.offsets.to_offset
  File "offsets.pyx", line 4453, in pandas._libs.tslibs.offsets._get_offset
ValueError: Invalid frequency: ME

The above exception was the direct cause of the following exception:

Traceback (most recent call last):
  File "c:\Users\joaop\Downloads\Projetos Cursor\FIDCs 2.0\src\data\data_collection.py", line 32, in collect_cvm_data
    df = importa_dados(nome_arquivo_fonte=arquivo, data_inicio=data_inicio)
         ^^^^^^^^^^^^^^^^^^^^^^^^^^^^^^^^^^^^^^^^^^^^^^^^^^^^^^^^^^^^^^^^^^
  File "c:\Users\joaop\Downloads\Projetos Cursor\FIDCs 2.0\src\scraping\cvm_scraper.py", line 63, in importa_dados
    datas_a_baixar = pd.date_range(start=data_inicio, end=data_atual, freq='ME')
                     ^^^^^^^^^^^^^^^^^^^^^^^^^^^^^^^^^^^^^^^^^^^^^^^^^^^^^^^^^^^
  File "C:\Users\joaop\AppData\Local\Packages\PythonSoftwareFoundation.Python.3.12_qbz5n2kfra8p0\LocalCache\local-packages\Python312\site-packages\pandas\core\indexes\datetimes.py", line 1009, in date_range
    dtarr = DatetimeArray._generate_range(
            ^^^^^^^^^^^^^^^^^^^^^^^^^^^^^^
  File "C:\Users\joaop\AppData\Local\Packages\PythonSoftwareFoundation.Python.3.12_qbz5n2kfra8p0\LocalCache\local-packages\Python312\site-packages\pandas\core\arrays\datetimes.py", line 404, in _generate_range
    freq = to_offset(freq)
           ^^^^^^^^^^^^^^^
  File "offsets.pyx", line 4460, in pandas._libs.tslibs.offsets.to_offset
  File "offsets.pyx", line 4557, in pandas._libs.tslibs.offsets.to_offset
ValueError: Invalid frequency: ME
[2025-03-19 23:51:48,696] [ERROR] [data_collection] - Erro na coleta de dados para passivos_derivativos
(<class 'ValueError'>, ValueError('Invalid frequency: ME'), <traceback object at 0x0000025EF9D61040>)
Traceback (most recent call last):
  File "offsets.pyx", line 4447, in pandas._libs.tslibs.offsets._get_offset
KeyError: 'ME'

The above exception was the direct cause of the following exception:

Traceback (most recent call last):
  File "offsets.pyx", line 4549, in pandas._libs.tslibs.offsets.to_offset
  File "offsets.pyx", line 4453, in pandas._libs.tslibs.offsets._get_offset
ValueError: Invalid frequency: ME

The above exception was the direct cause of the following exception:

Traceback (most recent call last):
  File "c:\Users\joaop\Downloads\Projetos Cursor\FIDCs 2.0\src\data\data_collection.py", line 32, in collect_cvm_data
    df = importa_dados(nome_arquivo_fonte=arquivo, data_inicio=data_inicio)
         ^^^^^^^^^^^^^^^^^^^^^^^^^^^^^^^^^^^^^^^^^^^^^^^^^^^^^^^^^^^^^^^^^^
  File "c:\Users\joaop\Downloads\Projetos Cursor\FIDCs 2.0\src\scraping\cvm_scraper.py", line 63, in importa_dados
    datas_a_baixar = pd.date_range(start=data_inicio, end=data_atual, freq='ME')
                     ^^^^^^^^^^^^^^^^^^^^^^^^^^^^^^^^^^^^^^^^^^^^^^^^^^^^^^^^^^^
  File "C:\Users\joaop\AppData\Local\Packages\PythonSoftwareFoundation.Python.3.12_qbz5n2kfra8p0\LocalCache\local-packages\Python312\site-packages\pandas\core\indexes\datetimes.py", line 1009, in date_range
    dtarr = DatetimeArray._generate_range(
            ^^^^^^^^^^^^^^^^^^^^^^^^^^^^^^
  File "C:\Users\joaop\AppData\Local\Packages\PythonSoftwareFoundation.Python.3.12_qbz5n2kfra8p0\LocalCache\local-packages\Python312\site-packages\pandas\core\arrays\datetimes.py", line 404, in _generate_range
    freq = to_offset(freq)
           ^^^^^^^^^^^^^^^
  File "offsets.pyx", line 4460, in pandas._libs.tslibs.offsets.to_offset
  File "offsets.pyx", line 4557, in pandas._libs.tslibs.offsets.to_offset
ValueError: Invalid frequency: ME
[2025-03-19 23:51:48,698] [ERROR] [data_collection] - Erro na coleta de dados para prazos_creditos
(<class 'ValueError'>, ValueError('Invalid frequency: ME'), <traceback object at 0x0000025EF9D61080>)
Traceback (most recent call last):
  File "offsets.pyx", line 4447, in pandas._libs.tslibs.offsets._get_offset
KeyError: 'ME'

The above exception was the direct cause of the following exception:

Traceback (most recent call last):
  File "offsets.pyx", line 4549, in pandas._libs.tslibs.offsets.to_offset
  File "offsets.pyx", line 4453, in pandas._libs.tslibs.offsets._get_offset
ValueError: Invalid frequency: ME

The above exception was the direct cause of the following exception:

Traceback (most recent call last):
  File "c:\Users\joaop\Downloads\Projetos Cursor\FIDCs 2.0\src\data\data_collection.py", line 32, in collect_cvm_data
    df = importa_dados(nome_arquivo_fonte=arquivo, data_inicio=data_inicio)
         ^^^^^^^^^^^^^^^^^^^^^^^^^^^^^^^^^^^^^^^^^^^^^^^^^^^^^^^^^^^^^^^^^^
  File "c:\Users\joaop\Downloads\Projetos Cursor\FIDCs 2.0\src\scraping\cvm_scraper.py", line 63, in importa_dados
    datas_a_baixar = pd.date_range(start=data_inicio, end=data_atual, freq='ME')
                     ^^^^^^^^^^^^^^^^^^^^^^^^^^^^^^^^^^^^^^^^^^^^^^^^^^^^^^^^^^^
  File "C:\Users\joaop\AppData\Local\Packages\PythonSoftwareFoundation.Python.3.12_qbz5n2kfra8p0\LocalCache\local-packages\Python312\site-packages\pandas\core\indexes\datetimes.py", line 1009, in date_range
    dtarr = DatetimeArray._generate_range(
            ^^^^^^^^^^^^^^^^^^^^^^^^^^^^^^
  File "C:\Users\joaop\AppData\Local\Packages\PythonSoftwareFoundation.Python.3.12_qbz5n2kfra8p0\LocalCache\local-packages\Python312\site-packages\pandas\core\arrays\datetimes.py", line 404, in _generate_range
    freq = to_offset(freq)
           ^^^^^^^^^^^^^^^
  File "offsets.pyx", line 4460, in pandas._libs.tslibs.offsets.to_offset
  File "offsets.pyx", line 4557, in pandas._libs.tslibs.offsets.to_offset
ValueError: Invalid frequency: ME
[2025-03-19 23:51:48,700] [ERROR] [data_collection] - Erro na coleta de dados para inadimplencia
(<class 'ValueError'>, ValueError('Invalid frequency: ME'), <traceback object at 0x0000025EF9D61BC0>)
Traceback (most recent call last):
  File "offsets.pyx", line 4447, in pandas._libs.tslibs.offsets._get_offset
KeyError: 'ME'

The above exception was the direct cause of the following exception:

Traceback (most recent call last):
  File "offsets.pyx", line 4549, in pandas._libs.tslibs.offsets.to_offset
  File "offsets.pyx", line 4453, in pandas._libs.tslibs.offsets._get_offset
ValueError: Invalid frequency: ME

The above exception was the direct cause of the following exception:

Traceback (most recent call last):
  File "c:\Users\joaop\Downloads\Projetos Cursor\FIDCs 2.0\src\data\data_collection.py", line 32, in collect_cvm_data
    df = importa_dados(nome_arquivo_fonte=arquivo, data_inicio=data_inicio)
         ^^^^^^^^^^^^^^^^^^^^^^^^^^^^^^^^^^^^^^^^^^^^^^^^^^^^^^^^^^^^^^^^^^
  File "c:\Users\joaop\Downloads\Projetos Cursor\FIDCs 2.0\src\scraping\cvm_scraper.py", line 63, in importa_dados
    datas_a_baixar = pd.date_range(start=data_inicio, end=data_atual, freq='ME')
                     ^^^^^^^^^^^^^^^^^^^^^^^^^^^^^^^^^^^^^^^^^^^^^^^^^^^^^^^^^^^
  File "C:\Users\joaop\AppData\Local\Packages\PythonSoftwareFoundation.Python.3.12_qbz5n2kfra8p0\LocalCache\local-packages\Python312\site-packages\pandas\core\indexes\datetimes.py", line 1009, in date_range
    dtarr = DatetimeArray._generate_range(
            ^^^^^^^^^^^^^^^^^^^^^^^^^^^^^^
  File "C:\Users\joaop\AppData\Local\Packages\PythonSoftwareFoundation.Python.3.12_qbz5n2kfra8p0\LocalCache\local-packages\Python312\site-packages\pandas\core\arrays\datetimes.py", line 404, in _generate_range
    freq = to_offset(freq)
           ^^^^^^^^^^^^^^^
  File "offsets.pyx", line 4460, in pandas._libs.tslibs.offsets.to_offset
  File "offsets.pyx", line 4557, in pandas._libs.tslibs.offsets.to_offset
ValueError: Invalid frequency: ME
[2025-03-19 23:51:48,703] [ERROR] [data_collection] - Erro na coleta de dados para cedentes_tomadores
(<class 'ValueError'>, ValueError('Invalid frequency: ME'), <traceback object at 0x0000025EF9D61CC0>)
Traceback (most recent call last):
  File "offsets.pyx", line 4447, in pandas._libs.tslibs.offsets._get_offset
KeyError: 'ME'

The above exception was the direct cause of the following exception:

Traceback (most recent call last):
  File "offsets.pyx", line 4549, in pandas._libs.tslibs.offsets.to_offset
  File "offsets.pyx", line 4453, in pandas._libs.tslibs.offsets._get_offset
ValueError: Invalid frequency: ME

The above exception was the direct cause of the following exception:

Traceback (most recent call last):
  File "c:\Users\joaop\Downloads\Projetos Cursor\FIDCs 2.0\src\data\data_collection.py", line 32, in collect_cvm_data
    df = importa_dados(nome_arquivo_fonte=arquivo, data_inicio=data_inicio)
         ^^^^^^^^^^^^^^^^^^^^^^^^^^^^^^^^^^^^^^^^^^^^^^^^^^^^^^^^^^^^^^^^^^
  File "c:\Users\joaop\Downloads\Projetos Cursor\FIDCs 2.0\src\scraping\cvm_scraper.py", line 63, in importa_dados
    datas_a_baixar = pd.date_range(start=data_inicio, end=data_atual, freq='ME')
                     ^^^^^^^^^^^^^^^^^^^^^^^^^^^^^^^^^^^^^^^^^^^^^^^^^^^^^^^^^^^
  File "C:\Users\joaop\AppData\Local\Packages\PythonSoftwareFoundation.Python.3.12_qbz5n2kfra8p0\LocalCache\local-packages\Python312\site-packages\pandas\core\indexes\datetimes.py", line 1009, in date_range
    dtarr = DatetimeArray._generate_range(
            ^^^^^^^^^^^^^^^^^^^^^^^^^^^^^^
  File "C:\Users\joaop\AppData\Local\Packages\PythonSoftwareFoundation.Python.3.12_qbz5n2kfra8p0\LocalCache\local-packages\Python312\site-packages\pandas\core\arrays\datetimes.py", line 404, in _generate_range
    freq = to_offset(freq)
           ^^^^^^^^^^^^^^^
  File "offsets.pyx", line 4460, in pandas._libs.tslibs.offsets.to_offset
  File "offsets.pyx", line 4557, in pandas._libs.tslibs.offsets.to_offset
ValueError: Invalid frequency: ME
[2025-03-19 23:51:48,706] [ERROR] [data_collection] - Erro na coleta de dados para precos_mercado
(<class 'ValueError'>, ValueError('Invalid frequency: ME'), <traceback object at 0x0000025EF9D61EC0>)
Traceback (most recent call last):
  File "offsets.pyx", line 4447, in pandas._libs.tslibs.offsets._get_offset
KeyError: 'ME'

The above exception was the direct cause of the following exception:

Traceback (most recent call last):
  File "offsets.pyx", line 4549, in pandas._libs.tslibs.offsets.to_offset
  File "offsets.pyx", line 4453, in pandas._libs.tslibs.offsets._get_offset
ValueError: Invalid frequency: ME

The above exception was the direct cause of the following exception:

Traceback (most recent call last):
  File "c:\Users\joaop\Downloads\Projetos Cursor\FIDCs 2.0\src\data\data_collection.py", line 32, in collect_cvm_data
    df = importa_dados(nome_arquivo_fonte=arquivo, data_inicio=data_inicio)
         ^^^^^^^^^^^^^^^^^^^^^^^^^^^^^^^^^^^^^^^^^^^^^^^^^^^^^^^^^^^^^^^^^^
  File "c:\Users\joaop\Downloads\Projetos Cursor\FIDCs 2.0\src\scraping\cvm_scraper.py", line 63, in importa_dados
    datas_a_baixar = pd.date_range(start=data_inicio, end=data_atual, freq='ME')
                     ^^^^^^^^^^^^^^^^^^^^^^^^^^^^^^^^^^^^^^^^^^^^^^^^^^^^^^^^^^^
  File "C:\Users\joaop\AppData\Local\Packages\PythonSoftwareFoundation.Python.3.12_qbz5n2kfra8p0\LocalCache\local-packages\Python312\site-packages\pandas\core\indexes\datetimes.py", line 1009, in date_range
    dtarr = DatetimeArray._generate_range(
            ^^^^^^^^^^^^^^^^^^^^^^^^^^^^^^
  File "C:\Users\joaop\AppData\Local\Packages\PythonSoftwareFoundation.Python.3.12_qbz5n2kfra8p0\LocalCache\local-packages\Python312\site-packages\pandas\core\arrays\datetimes.py", line 404, in _generate_range
    freq = to_offset(freq)
           ^^^^^^^^^^^^^^^
  File "offsets.pyx", line 4460, in pandas._libs.tslibs.offsets.to_offset
  File "offsets.pyx", line 4557, in pandas._libs.tslibs.offsets.to_offset
ValueError: Invalid frequency: ME
[2025-03-19 23:51:48,708] [ERROR] [data_collection] - Erro na coleta de dados para risco_credito
(<class 'ValueError'>, ValueError('Invalid frequency: ME'), <traceback object at 0x0000025EF9D61F40>)
Traceback (most recent call last):
  File "offsets.pyx", line 4447, in pandas._libs.tslibs.offsets._get_offset
KeyError: 'ME'

The above exception was the direct cause of the following exception:

Traceback (most recent call last):
  File "offsets.pyx", line 4549, in pandas._libs.tslibs.offsets.to_offset
  File "offsets.pyx", line 4453, in pandas._libs.tslibs.offsets._get_offset
ValueError: Invalid frequency: ME

The above exception was the direct cause of the following exception:

Traceback (most recent call last):
  File "c:\Users\joaop\Downloads\Projetos Cursor\FIDCs 2.0\src\data\data_collection.py", line 32, in collect_cvm_data
    df = importa_dados(nome_arquivo_fonte=arquivo, data_inicio=data_inicio)
         ^^^^^^^^^^^^^^^^^^^^^^^^^^^^^^^^^^^^^^^^^^^^^^^^^^^^^^^^^^^^^^^^^^
  File "c:\Users\joaop\Downloads\Projetos Cursor\FIDCs 2.0\src\scraping\cvm_scraper.py", line 63, in importa_dados
    datas_a_baixar = pd.date_range(start=data_inicio, end=data_atual, freq='ME')
                     ^^^^^^^^^^^^^^^^^^^^^^^^^^^^^^^^^^^^^^^^^^^^^^^^^^^^^^^^^^^
  File "C:\Users\joaop\AppData\Local\Packages\PythonSoftwareFoundation.Python.3.12_qbz5n2kfra8p0\LocalCache\local-packages\Python312\site-packages\pandas\core\indexes\datetimes.py", line 1009, in date_range
    dtarr = DatetimeArray._generate_range(
            ^^^^^^^^^^^^^^^^^^^^^^^^^^^^^^
  File "C:\Users\joaop\AppData\Local\Packages\PythonSoftwareFoundation.Python.3.12_qbz5n2kfra8p0\LocalCache\local-packages\Python312\site-packages\pandas\core\arrays\datetimes.py", line 404, in _generate_range
    freq = to_offset(freq)
           ^^^^^^^^^^^^^^^
  File "offsets.pyx", line 4460, in pandas._libs.tslibs.offsets.to_offset
  File "offsets.pyx", line 4557, in pandas._libs.tslibs.offsets.to_offset
ValueError: Invalid frequency: ME
[2025-03-19 23:51:48,712] [ERROR] [data_collection] - Erro na coleta de dados para classes_cotistas
(<class 'ValueError'>, ValueError('Invalid frequency: ME'), <traceback object at 0x0000025EF9D613C0>)
Traceback (most recent call last):
  File "offsets.pyx", line 4447, in pandas._libs.tslibs.offsets._get_offset
KeyError: 'ME'

The above exception was the direct cause of the following exception:

Traceback (most recent call last):
  File "offsets.pyx", line 4549, in pandas._libs.tslibs.offsets.to_offset
  File "offsets.pyx", line 4453, in pandas._libs.tslibs.offsets._get_offset
ValueError: Invalid frequency: ME

The above exception was the direct cause of the following exception:

Traceback (most recent call last):
  File "c:\Users\joaop\Downloads\Projetos Cursor\FIDCs 2.0\src\data\data_collection.py", line 32, in collect_cvm_data
    df = importa_dados(nome_arquivo_fonte=arquivo, data_inicio=data_inicio)
         ^^^^^^^^^^^^^^^^^^^^^^^^^^^^^^^^^^^^^^^^^^^^^^^^^^^^^^^^^^^^^^^^^^
  File "c:\Users\joaop\Downloads\Projetos Cursor\FIDCs 2.0\src\scraping\cvm_scraper.py", line 63, in importa_dados
    datas_a_baixar = pd.date_range(start=data_inicio, end=data_atual, freq='ME')
                     ^^^^^^^^^^^^^^^^^^^^^^^^^^^^^^^^^^^^^^^^^^^^^^^^^^^^^^^^^^^
  File "C:\Users\joaop\AppData\Local\Packages\PythonSoftwareFoundation.Python.3.12_qbz5n2kfra8p0\LocalCache\local-packages\Python312\site-packages\pandas\core\indexes\datetimes.py", line 1009, in date_range
    dtarr = DatetimeArray._generate_range(
            ^^^^^^^^^^^^^^^^^^^^^^^^^^^^^^
  File "C:\Users\joaop\AppData\Local\Packages\PythonSoftwareFoundation.Python.3.12_qbz5n2kfra8p0\LocalCache\local-packages\Python312\site-packages\pandas\core\arrays\datetimes.py", line 404, in _generate_range
    freq = to_offset(freq)
           ^^^^^^^^^^^^^^^
  File "offsets.pyx", line 4460, in pandas._libs.tslibs.offsets.to_offset
  File "offsets.pyx", line 4557, in pandas._libs.tslibs.offsets.to_offset
ValueError: Invalid frequency: ME
[2025-03-19 23:51:48,714] [ERROR] [data_collection] - Erro na coleta de dados para distribuicao_cotistas
(<class 'ValueError'>, ValueError('Invalid frequency: ME'), <traceback object at 0x0000025EF9D61080>)
Traceback (most recent call last):
  File "offsets.pyx", line 4447, in pandas._libs.tslibs.offsets._get_offset
KeyError: 'ME'

The above exception was the direct cause of the following exception:

Traceback (most recent call last):
  File "offsets.pyx", line 4549, in pandas._libs.tslibs.offsets.to_offset
  File "offsets.pyx", line 4453, in pandas._libs.tslibs.offsets._get_offset
ValueError: Invalid frequency: ME

The above exception was the direct cause of the following exception:

Traceback (most recent call last):
  File "c:\Users\joaop\Downloads\Projetos Cursor\FIDCs 2.0\src\data\data_collection.py", line 32, in collect_cvm_data
    df = importa_dados(nome_arquivo_fonte=arquivo, data_inicio=data_inicio)
         ^^^^^^^^^^^^^^^^^^^^^^^^^^^^^^^^^^^^^^^^^^^^^^^^^^^^^^^^^^^^^^^^^^
  File "c:\Users\joaop\Downloads\Projetos Cursor\FIDCs 2.0\src\scraping\cvm_scraper.py", line 63, in importa_dados
    datas_a_baixar = pd.date_range(start=data_inicio, end=data_atual, freq='ME')
                     ^^^^^^^^^^^^^^^^^^^^^^^^^^^^^^^^^^^^^^^^^^^^^^^^^^^^^^^^^^^
  File "C:\Users\joaop\AppData\Local\Packages\PythonSoftwareFoundation.Python.3.12_qbz5n2kfra8p0\LocalCache\local-packages\Python312\site-packages\pandas\core\indexes\datetimes.py", line 1009, in date_range
    dtarr = DatetimeArray._generate_range(
            ^^^^^^^^^^^^^^^^^^^^^^^^^^^^^^
  File "C:\Users\joaop\AppData\Local\Packages\PythonSoftwareFoundation.Python.3.12_qbz5n2kfra8p0\LocalCache\local-packages\Python312\site-packages\pandas\core\arrays\datetimes.py", line 404, in _generate_range
    freq = to_offset(freq)
           ^^^^^^^^^^^^^^^
  File "offsets.pyx", line 4460, in pandas._libs.tslibs.offsets.to_offset
  File "offsets.pyx", line 4557, in pandas._libs.tslibs.offsets.to_offset
ValueError: Invalid frequency: ME
[2025-03-19 23:51:48,716] [ERROR] [data_collection] - Erro na coleta de dados para cotas_valores
(<class 'ValueError'>, ValueError('Invalid frequency: ME'), <traceback object at 0x0000025EF9D623C0>)
Traceback (most recent call last):
  File "offsets.pyx", line 4447, in pandas._libs.tslibs.offsets._get_offset
KeyError: 'ME'

The above exception was the direct cause of the following exception:

Traceback (most recent call last):
  File "offsets.pyx", line 4549, in pandas._libs.tslibs.offsets.to_offset
  File "offsets.pyx", line 4453, in pandas._libs.tslibs.offsets._get_offset
ValueError: Invalid frequency: ME

The above exception was the direct cause of the following exception:

Traceback (most recent call last):
  File "c:\Users\joaop\Downloads\Projetos Cursor\FIDCs 2.0\src\data\data_collection.py", line 32, in collect_cvm_data
    df = importa_dados(nome_arquivo_fonte=arquivo, data_inicio=data_inicio)
         ^^^^^^^^^^^^^^^^^^^^^^^^^^^^^^^^^^^^^^^^^^^^^^^^^^^^^^^^^^^^^^^^^^
  File "c:\Users\joaop\Downloads\Projetos Cursor\FIDCs 2.0\src\scraping\cvm_scraper.py", line 63, in importa_dados
    datas_a_baixar = pd.date_range(start=data_inicio, end=data_atual, freq='ME')
                     ^^^^^^^^^^^^^^^^^^^^^^^^^^^^^^^^^^^^^^^^^^^^^^^^^^^^^^^^^^^
  File "C:\Users\joaop\AppData\Local\Packages\PythonSoftwareFoundation.Python.3.12_qbz5n2kfra8p0\LocalCache\local-packages\Python312\site-packages\pandas\core\indexes\datetimes.py", line 1009, in date_range
    dtarr = DatetimeArray._generate_range(
            ^^^^^^^^^^^^^^^^^^^^^^^^^^^^^^
  File "C:\Users\joaop\AppData\Local\Packages\PythonSoftwareFoundation.Python.3.12_qbz5n2kfra8p0\LocalCache\local-packages\Python312\site-packages\pandas\core\arrays\datetimes.py", line 404, in _generate_range
    freq = to_offset(freq)
           ^^^^^^^^^^^^^^^
  File "offsets.pyx", line 4460, in pandas._libs.tslibs.offsets.to_offset
  File "offsets.pyx", line 4557, in pandas._libs.tslibs.offsets.to_offset
ValueError: Invalid frequency: ME
[2025-03-19 23:51:48,718] [ERROR] [data_collection] - Erro na coleta de dados para rentabilidade
(<class 'ValueError'>, ValueError('Invalid frequency: ME'), <traceback object at 0x0000025EF9D61D40>)
Traceback (most recent call last):
  File "offsets.pyx", line 4447, in pandas._libs.tslibs.offsets._get_offset
KeyError: 'ME'

The above exception was the direct cause of the following exception:

Traceback (most recent call last):
  File "offsets.pyx", line 4549, in pandas._libs.tslibs.offsets.to_offset
  File "offsets.pyx", line 4453, in pandas._libs.tslibs.offsets._get_offset
ValueError: Invalid frequency: ME

The above exception was the direct cause of the following exception:

Traceback (most recent call last):
  File "c:\Users\joaop\Downloads\Projetos Cursor\FIDCs 2.0\src\data\data_collection.py", line 32, in collect_cvm_data
    df = importa_dados(nome_arquivo_fonte=arquivo, data_inicio=data_inicio)
         ^^^^^^^^^^^^^^^^^^^^^^^^^^^^^^^^^^^^^^^^^^^^^^^^^^^^^^^^^^^^^^^^^^
  File "c:\Users\joaop\Downloads\Projetos Cursor\FIDCs 2.0\src\scraping\cvm_scraper.py", line 63, in importa_dados
    datas_a_baixar = pd.date_range(start=data_inicio, end=data_atual, freq='ME')
                     ^^^^^^^^^^^^^^^^^^^^^^^^^^^^^^^^^^^^^^^^^^^^^^^^^^^^^^^^^^^
  File "C:\Users\joaop\AppData\Local\Packages\PythonSoftwareFoundation.Python.3.12_qbz5n2kfra8p0\LocalCache\local-packages\Python312\site-packages\pandas\core\indexes\datetimes.py", line 1009, in date_range
    dtarr = DatetimeArray._generate_range(
            ^^^^^^^^^^^^^^^^^^^^^^^^^^^^^^
  File "C:\Users\joaop\AppData\Local\Packages\PythonSoftwareFoundation.Python.3.12_qbz5n2kfra8p0\LocalCache\local-packages\Python312\site-packages\pandas\core\arrays\datetimes.py", line 404, in _generate_range
    freq = to_offset(freq)
           ^^^^^^^^^^^^^^^
  File "offsets.pyx", line 4460, in pandas._libs.tslibs.offsets.to_offset
  File "offsets.pyx", line 4557, in pandas._libs.tslibs.offsets.to_offset
ValueError: Invalid frequency: ME
[2025-03-19 23:51:48,721] [ERROR] [data_collection] - Erro na coleta de dados para operacoes_estruturadas
(<class 'ValueError'>, ValueError('Invalid frequency: ME'), <traceback object at 0x0000025EF9D61CC0>)
Traceback (most recent call last):
  File "offsets.pyx", line 4447, in pandas._libs.tslibs.offsets._get_offset
KeyError: 'ME'

The above exception was the direct cause of the following exception:

Traceback (most recent call last):
  File "offsets.pyx", line 4549, in pandas._libs.tslibs.offsets.to_offset
  File "offsets.pyx", line 4453, in pandas._libs.tslibs.offsets._get_offset
ValueError: Invalid frequency: ME

The above exception was the direct cause of the following exception:

Traceback (most recent call last):
  File "c:\Users\joaop\Downloads\Projetos Cursor\FIDCs 2.0\src\data\data_collection.py", line 32, in collect_cvm_data
    df = importa_dados(nome_arquivo_fonte=arquivo, data_inicio=data_inicio)
         ^^^^^^^^^^^^^^^^^^^^^^^^^^^^^^^^^^^^^^^^^^^^^^^^^^^^^^^^^^^^^^^^^^
  File "c:\Users\joaop\Downloads\Projetos Cursor\FIDCs 2.0\src\scraping\cvm_scraper.py", line 63, in importa_dados
    datas_a_baixar = pd.date_range(start=data_inicio, end=data_atual, freq='ME')
                     ^^^^^^^^^^^^^^^^^^^^^^^^^^^^^^^^^^^^^^^^^^^^^^^^^^^^^^^^^^^
  File "C:\Users\joaop\AppData\Local\Packages\PythonSoftwareFoundation.Python.3.12_qbz5n2kfra8p0\LocalCache\local-packages\Python312\site-packages\pandas\core\indexes\datetimes.py", line 1009, in date_range
    dtarr = DatetimeArray._generate_range(
            ^^^^^^^^^^^^^^^^^^^^^^^^^^^^^^
  File "C:\Users\joaop\AppData\Local\Packages\PythonSoftwareFoundation.Python.3.12_qbz5n2kfra8p0\LocalCache\local-packages\Python312\site-packages\pandas\core\arrays\datetimes.py", line 404, in _generate_range
    freq = to_offset(freq)
           ^^^^^^^^^^^^^^^
  File "offsets.pyx", line 4460, in pandas._libs.tslibs.offsets.to_offset
  File "offsets.pyx", line 4557, in pandas._libs.tslibs.offsets.to_offset
ValueError: Invalid frequency: ME
[2025-03-19 23:51:48,723] [ERROR] [data_collection] - Erro na coleta de dados para liquidez_ativos
(<class 'ValueError'>, ValueError('Invalid frequency: ME'), <traceback object at 0x0000025EF9D62700>)
Traceback (most recent call last):
  File "offsets.pyx", line 4447, in pandas._libs.tslibs.offsets._get_offset
KeyError: 'ME'

The above exception was the direct cause of the following exception:

Traceback (most recent call last):
  File "offsets.pyx", line 4549, in pandas._libs.tslibs.offsets.to_offset
  File "offsets.pyx", line 4453, in pandas._libs.tslibs.offsets._get_offset
ValueError: Invalid frequency: ME

The above exception was the direct cause of the following exception:

Traceback (most recent call last):
  File "c:\Users\joaop\Downloads\Projetos Cursor\FIDCs 2.0\src\data\data_collection.py", line 32, in collect_cvm_data
    df = importa_dados(nome_arquivo_fonte=arquivo, data_inicio=data_inicio)
         ^^^^^^^^^^^^^^^^^^^^^^^^^^^^^^^^^^^^^^^^^^^^^^^^^^^^^^^^^^^^^^^^^^
  File "c:\Users\joaop\Downloads\Projetos Cursor\FIDCs 2.0\src\scraping\cvm_scraper.py", line 63, in importa_dados
    datas_a_baixar = pd.date_range(start=data_inicio, end=data_atual, freq='ME')
                     ^^^^^^^^^^^^^^^^^^^^^^^^^^^^^^^^^^^^^^^^^^^^^^^^^^^^^^^^^^^
  File "C:\Users\joaop\AppData\Local\Packages\PythonSoftwareFoundation.Python.3.12_qbz5n2kfra8p0\LocalCache\local-packages\Python312\site-packages\pandas\core\indexes\datetimes.py", line 1009, in date_range
    dtarr = DatetimeArray._generate_range(
            ^^^^^^^^^^^^^^^^^^^^^^^^^^^^^^
  File "C:\Users\joaop\AppData\Local\Packages\PythonSoftwareFoundation.Python.3.12_qbz5n2kfra8p0\LocalCache\local-packages\Python312\site-packages\pandas\core\arrays\datetimes.py", line 404, in _generate_range
    freq = to_offset(freq)
           ^^^^^^^^^^^^^^^
  File "offsets.pyx", line 4460, in pandas._libs.tslibs.offsets.to_offset
  File "offsets.pyx", line 4557, in pandas._libs.tslibs.offsets.to_offset
ValueError: Invalid frequency: ME
[2025-03-19 23:51:48,725] [ERROR] [data_collection] - Erro na coleta de dados para performance_fundo
(<class 'ValueError'>, ValueError('Invalid frequency: ME'), <traceback object at 0x0000025EF9D62380>)
Traceback (most recent call last):
  File "offsets.pyx", line 4447, in pandas._libs.tslibs.offsets._get_offset
KeyError: 'ME'

The above exception was the direct cause of the following exception:

Traceback (most recent call last):
  File "offsets.pyx", line 4549, in pandas._libs.tslibs.offsets.to_offset
  File "offsets.pyx", line 4453, in pandas._libs.tslibs.offsets._get_offset
ValueError: Invalid frequency: ME

The above exception was the direct cause of the following exception:

Traceback (most recent call last):
  File "c:\Users\joaop\Downloads\Projetos Cursor\FIDCs 2.0\src\data\data_collection.py", line 32, in collect_cvm_data
    df = importa_dados(nome_arquivo_fonte=arquivo, data_inicio=data_inicio)
         ^^^^^^^^^^^^^^^^^^^^^^^^^^^^^^^^^^^^^^^^^^^^^^^^^^^^^^^^^^^^^^^^^^
  File "c:\Users\joaop\Downloads\Projetos Cursor\FIDCs 2.0\src\scraping\cvm_scraper.py", line 63, in importa_dados
    datas_a_baixar = pd.date_range(start=data_inicio, end=data_atual, freq='ME')
                     ^^^^^^^^^^^^^^^^^^^^^^^^^^^^^^^^^^^^^^^^^^^^^^^^^^^^^^^^^^^
  File "C:\Users\joaop\AppData\Local\Packages\PythonSoftwareFoundation.Python.3.12_qbz5n2kfra8p0\LocalCache\local-packages\Python312\site-packages\pandas\core\indexes\datetimes.py", line 1009, in date_range
    dtarr = DatetimeArray._generate_range(
            ^^^^^^^^^^^^^^^^^^^^^^^^^^^^^^
  File "C:\Users\joaop\AppData\Local\Packages\PythonSoftwareFoundation.Python.3.12_qbz5n2kfra8p0\LocalCache\local-packages\Python312\site-packages\pandas\core\arrays\datetimes.py", line 404, in _generate_range
    freq = to_offset(freq)
           ^^^^^^^^^^^^^^^
  File "offsets.pyx", line 4460, in pandas._libs.tslibs.offsets.to_offset
  File "offsets.pyx", line 4557, in pandas._libs.tslibs.offsets.to_offset
ValueError: Invalid frequency: ME
[2025-03-19 23:51:48,727] [ERROR] [data_collection] - Erro na coleta de dados para garantias_seguros
(<class 'ValueError'>, ValueError('Invalid frequency: ME'), <traceback object at 0x0000025EF9D62300>)
Traceback (most recent call last):
  File "offsets.pyx", line 4447, in pandas._libs.tslibs.offsets._get_offset
KeyError: 'ME'

The above exception was the direct cause of the following exception:

Traceback (most recent call last):
  File "offsets.pyx", line 4549, in pandas._libs.tslibs.offsets.to_offset
  File "offsets.pyx", line 4453, in pandas._libs.tslibs.offsets._get_offset
ValueError: Invalid frequency: ME

The above exception was the direct cause of the following exception:

Traceback (most recent call last):
  File "c:\Users\joaop\Downloads\Projetos Cursor\FIDCs 2.0\src\data\data_collection.py", line 32, in collect_cvm_data
    df = importa_dados(nome_arquivo_fonte=arquivo, data_inicio=data_inicio)
         ^^^^^^^^^^^^^^^^^^^^^^^^^^^^^^^^^^^^^^^^^^^^^^^^^^^^^^^^^^^^^^^^^^
  File "c:\Users\joaop\Downloads\Projetos Cursor\FIDCs 2.0\src\scraping\cvm_scraper.py", line 63, in importa_dados
    datas_a_baixar = pd.date_range(start=data_inicio, end=data_atual, freq='ME')
                     ^^^^^^^^^^^^^^^^^^^^^^^^^^^^^^^^^^^^^^^^^^^^^^^^^^^^^^^^^^^
  File "C:\Users\joaop\AppData\Local\Packages\PythonSoftwareFoundation.Python.3.12_qbz5n2kfra8p0\LocalCache\local-packages\Python312\site-packages\pandas\core\indexes\datetimes.py", line 1009, in date_range
    dtarr = DatetimeArray._generate_range(
            ^^^^^^^^^^^^^^^^^^^^^^^^^^^^^^
  File "C:\Users\joaop\AppData\Local\Packages\PythonSoftwareFoundation.Python.3.12_qbz5n2kfra8p0\LocalCache\local-packages\Python312\site-packages\pandas\core\arrays\datetimes.py", line 404, in _generate_range
    freq = to_offset(freq)
           ^^^^^^^^^^^^^^^
  File "offsets.pyx", line 4460, in pandas._libs.tslibs.offsets.to_offset
  File "offsets.pyx", line 4557, in pandas._libs.tslibs.offsets.to_offset
ValueError: Invalid frequency: ME
[2025-03-19 23:52:02,573] [ERROR] [data_collection] - Erro na coleta de dados para caracteristicas_fundo
(<class 'ValueError'>, ValueError('Invalid frequency: ME'), <traceback object at 0x0000019BC48CEB40>)
Traceback (most recent call last):
  File "offsets.pyx", line 4447, in pandas._libs.tslibs.offsets._get_offset
KeyError: 'ME'

The above exception was the direct cause of the following exception:

Traceback (most recent call last):
  File "offsets.pyx", line 4549, in pandas._libs.tslibs.offsets.to_offset
  File "offsets.pyx", line 4453, in pandas._libs.tslibs.offsets._get_offset
ValueError: Invalid frequency: ME

The above exception was the direct cause of the following exception:

Traceback (most recent call last):
  File "c:\Users\joaop\Downloads\Projetos Cursor\FIDCs 2.0\src\data\data_collection.py", line 32, in collect_cvm_data
    df = importa_dados(nome_arquivo_fonte=arquivo, data_inicio=data_inicio)
         ^^^^^^^^^^^^^^^^^^^^^^^^^^^^^^^^^^^^^^^^^^^^^^^^^^^^^^^^^^^^^^^^^^
  File "c:\Users\joaop\Downloads\Projetos Cursor\FIDCs 2.0\src\scraping\cvm_scraper.py", line 63, in importa_dados
    datas_a_baixar = pd.date_range(start=data_inicio, end=data_atual, freq='ME')
                     ^^^^^^^^^^^^^^^^^^^^^^^^^^^^^^^^^^^^^^^^^^^^^^^^^^^^^^^^^^^
  File "C:\Users\joaop\AppData\Local\Packages\PythonSoftwareFoundation.Python.3.12_qbz5n2kfra8p0\LocalCache\local-packages\Python312\site-packages\pandas\core\indexes\datetimes.py", line 1009, in date_range
    dtarr = DatetimeArray._generate_range(
            ^^^^^^^^^^^^^^^^^^^^^^^^^^^^^^
  File "C:\Users\joaop\AppData\Local\Packages\PythonSoftwareFoundation.Python.3.12_qbz5n2kfra8p0\LocalCache\local-packages\Python312\site-packages\pandas\core\arrays\datetimes.py", line 404, in _generate_range
    freq = to_offset(freq)
           ^^^^^^^^^^^^^^^
  File "offsets.pyx", line 4460, in pandas._libs.tslibs.offsets.to_offset
  File "offsets.pyx", line 4557, in pandas._libs.tslibs.offsets.to_offset
ValueError: Invalid frequency: ME
[2025-03-19 23:52:02,576] [ERROR] [data_collection] - Erro na coleta de dados para patrimonio_liquido
(<class 'ValueError'>, ValueError('Invalid frequency: ME'), <traceback object at 0x0000019BC4921100>)
Traceback (most recent call last):
  File "offsets.pyx", line 4447, in pandas._libs.tslibs.offsets._get_offset
KeyError: 'ME'

The above exception was the direct cause of the following exception:

Traceback (most recent call last):
  File "offsets.pyx", line 4549, in pandas._libs.tslibs.offsets.to_offset
  File "offsets.pyx", line 4453, in pandas._libs.tslibs.offsets._get_offset
ValueError: Invalid frequency: ME

The above exception was the direct cause of the following exception:

Traceback (most recent call last):
  File "c:\Users\joaop\Downloads\Projetos Cursor\FIDCs 2.0\src\data\data_collection.py", line 32, in collect_cvm_data
    df = importa_dados(nome_arquivo_fonte=arquivo, data_inicio=data_inicio)
         ^^^^^^^^^^^^^^^^^^^^^^^^^^^^^^^^^^^^^^^^^^^^^^^^^^^^^^^^^^^^^^^^^^
  File "c:\Users\joaop\Downloads\Projetos Cursor\FIDCs 2.0\src\scraping\cvm_scraper.py", line 63, in importa_dados
    datas_a_baixar = pd.date_range(start=data_inicio, end=data_atual, freq='ME')
                     ^^^^^^^^^^^^^^^^^^^^^^^^^^^^^^^^^^^^^^^^^^^^^^^^^^^^^^^^^^^
  File "C:\Users\joaop\AppData\Local\Packages\PythonSoftwareFoundation.Python.3.12_qbz5n2kfra8p0\LocalCache\local-packages\Python312\site-packages\pandas\core\indexes\datetimes.py", line 1009, in date_range
    dtarr = DatetimeArray._generate_range(
            ^^^^^^^^^^^^^^^^^^^^^^^^^^^^^^
  File "C:\Users\joaop\AppData\Local\Packages\PythonSoftwareFoundation.Python.3.12_qbz5n2kfra8p0\LocalCache\local-packages\Python312\site-packages\pandas\core\arrays\datetimes.py", line 404, in _generate_range
    freq = to_offset(freq)
           ^^^^^^^^^^^^^^^
  File "offsets.pyx", line 4460, in pandas._libs.tslibs.offsets.to_offset
  File "offsets.pyx", line 4557, in pandas._libs.tslibs.offsets.to_offset
ValueError: Invalid frequency: ME
[2025-03-19 23:52:02,577] [ERROR] [data_collection] - Erro na coleta de dados para carteira_ativos
(<class 'ValueError'>, ValueError('Invalid frequency: ME'), <traceback object at 0x0000019BC4920C40>)
Traceback (most recent call last):
  File "offsets.pyx", line 4447, in pandas._libs.tslibs.offsets._get_offset
KeyError: 'ME'

The above exception was the direct cause of the following exception:

Traceback (most recent call last):
  File "offsets.pyx", line 4549, in pandas._libs.tslibs.offsets.to_offset
  File "offsets.pyx", line 4453, in pandas._libs.tslibs.offsets._get_offset
ValueError: Invalid frequency: ME

The above exception was the direct cause of the following exception:

Traceback (most recent call last):
  File "c:\Users\joaop\Downloads\Projetos Cursor\FIDCs 2.0\src\data\data_collection.py", line 32, in collect_cvm_data
    df = importa_dados(nome_arquivo_fonte=arquivo, data_inicio=data_inicio)
         ^^^^^^^^^^^^^^^^^^^^^^^^^^^^^^^^^^^^^^^^^^^^^^^^^^^^^^^^^^^^^^^^^^
  File "c:\Users\joaop\Downloads\Projetos Cursor\FIDCs 2.0\src\scraping\cvm_scraper.py", line 63, in importa_dados
    datas_a_baixar = pd.date_range(start=data_inicio, end=data_atual, freq='ME')
                     ^^^^^^^^^^^^^^^^^^^^^^^^^^^^^^^^^^^^^^^^^^^^^^^^^^^^^^^^^^^
  File "C:\Users\joaop\AppData\Local\Packages\PythonSoftwareFoundation.Python.3.12_qbz5n2kfra8p0\LocalCache\local-packages\Python312\site-packages\pandas\core\indexes\datetimes.py", line 1009, in date_range
    dtarr = DatetimeArray._generate_range(
            ^^^^^^^^^^^^^^^^^^^^^^^^^^^^^^
  File "C:\Users\joaop\AppData\Local\Packages\PythonSoftwareFoundation.Python.3.12_qbz5n2kfra8p0\LocalCache\local-packages\Python312\site-packages\pandas\core\arrays\datetimes.py", line 404, in _generate_range
    freq = to_offset(freq)
           ^^^^^^^^^^^^^^^
  File "offsets.pyx", line 4460, in pandas._libs.tslibs.offsets.to_offset
  File "offsets.pyx", line 4557, in pandas._libs.tslibs.offsets.to_offset
ValueError: Invalid frequency: ME
[2025-03-19 23:52:02,579] [ERROR] [data_collection] - Erro na coleta de dados para passivos_derivativos
(<class 'ValueError'>, ValueError('Invalid frequency: ME'), <traceback object at 0x0000019BC4921E80>)
Traceback (most recent call last):
  File "offsets.pyx", line 4447, in pandas._libs.tslibs.offsets._get_offset
KeyError: 'ME'

The above exception was the direct cause of the following exception:

Traceback (most recent call last):
  File "offsets.pyx", line 4549, in pandas._libs.tslibs.offsets.to_offset
  File "offsets.pyx", line 4453, in pandas._libs.tslibs.offsets._get_offset
ValueError: Invalid frequency: ME

The above exception was the direct cause of the following exception:

Traceback (most recent call last):
  File "c:\Users\joaop\Downloads\Projetos Cursor\FIDCs 2.0\src\data\data_collection.py", line 32, in collect_cvm_data
    df = importa_dados(nome_arquivo_fonte=arquivo, data_inicio=data_inicio)
         ^^^^^^^^^^^^^^^^^^^^^^^^^^^^^^^^^^^^^^^^^^^^^^^^^^^^^^^^^^^^^^^^^^
  File "c:\Users\joaop\Downloads\Projetos Cursor\FIDCs 2.0\src\scraping\cvm_scraper.py", line 63, in importa_dados
    datas_a_baixar = pd.date_range(start=data_inicio, end=data_atual, freq='ME')
                     ^^^^^^^^^^^^^^^^^^^^^^^^^^^^^^^^^^^^^^^^^^^^^^^^^^^^^^^^^^^
  File "C:\Users\joaop\AppData\Local\Packages\PythonSoftwareFoundation.Python.3.12_qbz5n2kfra8p0\LocalCache\local-packages\Python312\site-packages\pandas\core\indexes\datetimes.py", line 1009, in date_range
    dtarr = DatetimeArray._generate_range(
            ^^^^^^^^^^^^^^^^^^^^^^^^^^^^^^
  File "C:\Users\joaop\AppData\Local\Packages\PythonSoftwareFoundation.Python.3.12_qbz5n2kfra8p0\LocalCache\local-packages\Python312\site-packages\pandas\core\arrays\datetimes.py", line 404, in _generate_range
    freq = to_offset(freq)
           ^^^^^^^^^^^^^^^
  File "offsets.pyx", line 4460, in pandas._libs.tslibs.offsets.to_offset
  File "offsets.pyx", line 4557, in pandas._libs.tslibs.offsets.to_offset
ValueError: Invalid frequency: ME
[2025-03-19 23:52:02,581] [ERROR] [data_collection] - Erro na coleta de dados para prazos_creditos
(<class 'ValueError'>, ValueError('Invalid frequency: ME'), <traceback object at 0x0000019BC4921DC0>)
Traceback (most recent call last):
  File "offsets.pyx", line 4447, in pandas._libs.tslibs.offsets._get_offset
KeyError: 'ME'

The above exception was the direct cause of the following exception:

Traceback (most recent call last):
  File "offsets.pyx", line 4549, in pandas._libs.tslibs.offsets.to_offset
  File "offsets.pyx", line 4453, in pandas._libs.tslibs.offsets._get_offset
ValueError: Invalid frequency: ME

The above exception was the direct cause of the following exception:

Traceback (most recent call last):
  File "c:\Users\joaop\Downloads\Projetos Cursor\FIDCs 2.0\src\data\data_collection.py", line 32, in collect_cvm_data
    df = importa_dados(nome_arquivo_fonte=arquivo, data_inicio=data_inicio)
         ^^^^^^^^^^^^^^^^^^^^^^^^^^^^^^^^^^^^^^^^^^^^^^^^^^^^^^^^^^^^^^^^^^
  File "c:\Users\joaop\Downloads\Projetos Cursor\FIDCs 2.0\src\scraping\cvm_scraper.py", line 63, in importa_dados
    datas_a_baixar = pd.date_range(start=data_inicio, end=data_atual, freq='ME')
                     ^^^^^^^^^^^^^^^^^^^^^^^^^^^^^^^^^^^^^^^^^^^^^^^^^^^^^^^^^^^
  File "C:\Users\joaop\AppData\Local\Packages\PythonSoftwareFoundation.Python.3.12_qbz5n2kfra8p0\LocalCache\local-packages\Python312\site-packages\pandas\core\indexes\datetimes.py", line 1009, in date_range
    dtarr = DatetimeArray._generate_range(
            ^^^^^^^^^^^^^^^^^^^^^^^^^^^^^^
  File "C:\Users\joaop\AppData\Local\Packages\PythonSoftwareFoundation.Python.3.12_qbz5n2kfra8p0\LocalCache\local-packages\Python312\site-packages\pandas\core\arrays\datetimes.py", line 404, in _generate_range
    freq = to_offset(freq)
           ^^^^^^^^^^^^^^^
  File "offsets.pyx", line 4460, in pandas._libs.tslibs.offsets.to_offset
  File "offsets.pyx", line 4557, in pandas._libs.tslibs.offsets.to_offset
ValueError: Invalid frequency: ME
[2025-03-19 23:52:02,582] [ERROR] [data_collection] - Erro na coleta de dados para inadimplencia
(<class 'ValueError'>, ValueError('Invalid frequency: ME'), <traceback object at 0x0000019BC4921FC0>)
Traceback (most recent call last):
  File "offsets.pyx", line 4447, in pandas._libs.tslibs.offsets._get_offset
KeyError: 'ME'

The above exception was the direct cause of the following exception:

Traceback (most recent call last):
  File "offsets.pyx", line 4549, in pandas._libs.tslibs.offsets.to_offset
  File "offsets.pyx", line 4453, in pandas._libs.tslibs.offsets._get_offset
ValueError: Invalid frequency: ME

The above exception was the direct cause of the following exception:

Traceback (most recent call last):
  File "c:\Users\joaop\Downloads\Projetos Cursor\FIDCs 2.0\src\data\data_collection.py", line 32, in collect_cvm_data
    df = importa_dados(nome_arquivo_fonte=arquivo, data_inicio=data_inicio)
         ^^^^^^^^^^^^^^^^^^^^^^^^^^^^^^^^^^^^^^^^^^^^^^^^^^^^^^^^^^^^^^^^^^
  File "c:\Users\joaop\Downloads\Projetos Cursor\FIDCs 2.0\src\scraping\cvm_scraper.py", line 63, in importa_dados
    datas_a_baixar = pd.date_range(start=data_inicio, end=data_atual, freq='ME')
                     ^^^^^^^^^^^^^^^^^^^^^^^^^^^^^^^^^^^^^^^^^^^^^^^^^^^^^^^^^^^
  File "C:\Users\joaop\AppData\Local\Packages\PythonSoftwareFoundation.Python.3.12_qbz5n2kfra8p0\LocalCache\local-packages\Python312\site-packages\pandas\core\indexes\datetimes.py", line 1009, in date_range
    dtarr = DatetimeArray._generate_range(
            ^^^^^^^^^^^^^^^^^^^^^^^^^^^^^^
  File "C:\Users\joaop\AppData\Local\Packages\PythonSoftwareFoundation.Python.3.12_qbz5n2kfra8p0\LocalCache\local-packages\Python312\site-packages\pandas\core\arrays\datetimes.py", line 404, in _generate_range
    freq = to_offset(freq)
           ^^^^^^^^^^^^^^^
  File "offsets.pyx", line 4460, in pandas._libs.tslibs.offsets.to_offset
  File "offsets.pyx", line 4557, in pandas._libs.tslibs.offsets.to_offset
ValueError: Invalid frequency: ME
[2025-03-19 23:52:02,584] [ERROR] [data_collection] - Erro na coleta de dados para cedentes_tomadores
(<class 'ValueError'>, ValueError('Invalid frequency: ME'), <traceback object at 0x0000019BC4922940>)
Traceback (most recent call last):
  File "offsets.pyx", line 4447, in pandas._libs.tslibs.offsets._get_offset
KeyError: 'ME'

The above exception was the direct cause of the following exception:

Traceback (most recent call last):
  File "offsets.pyx", line 4549, in pandas._libs.tslibs.offsets.to_offset
  File "offsets.pyx", line 4453, in pandas._libs.tslibs.offsets._get_offset
ValueError: Invalid frequency: ME

The above exception was the direct cause of the following exception:

Traceback (most recent call last):
  File "c:\Users\joaop\Downloads\Projetos Cursor\FIDCs 2.0\src\data\data_collection.py", line 32, in collect_cvm_data
    df = importa_dados(nome_arquivo_fonte=arquivo, data_inicio=data_inicio)
         ^^^^^^^^^^^^^^^^^^^^^^^^^^^^^^^^^^^^^^^^^^^^^^^^^^^^^^^^^^^^^^^^^^
  File "c:\Users\joaop\Downloads\Projetos Cursor\FIDCs 2.0\src\scraping\cvm_scraper.py", line 63, in importa_dados
    datas_a_baixar = pd.date_range(start=data_inicio, end=data_atual, freq='ME')
                     ^^^^^^^^^^^^^^^^^^^^^^^^^^^^^^^^^^^^^^^^^^^^^^^^^^^^^^^^^^^
  File "C:\Users\joaop\AppData\Local\Packages\PythonSoftwareFoundation.Python.3.12_qbz5n2kfra8p0\LocalCache\local-packages\Python312\site-packages\pandas\core\indexes\datetimes.py", line 1009, in date_range
    dtarr = DatetimeArray._generate_range(
            ^^^^^^^^^^^^^^^^^^^^^^^^^^^^^^
  File "C:\Users\joaop\AppData\Local\Packages\PythonSoftwareFoundation.Python.3.12_qbz5n2kfra8p0\LocalCache\local-packages\Python312\site-packages\pandas\core\arrays\datetimes.py", line 404, in _generate_range
    freq = to_offset(freq)
           ^^^^^^^^^^^^^^^
  File "offsets.pyx", line 4460, in pandas._libs.tslibs.offsets.to_offset
  File "offsets.pyx", line 4557, in pandas._libs.tslibs.offsets.to_offset
ValueError: Invalid frequency: ME
[2025-03-19 23:52:02,586] [ERROR] [data_collection] - Erro na coleta de dados para precos_mercado
(<class 'ValueError'>, ValueError('Invalid frequency: ME'), <traceback object at 0x0000019BC4921FC0>)
Traceback (most recent call last):
  File "offsets.pyx", line 4447, in pandas._libs.tslibs.offsets._get_offset
KeyError: 'ME'

The above exception was the direct cause of the following exception:

Traceback (most recent call last):
  File "offsets.pyx", line 4549, in pandas._libs.tslibs.offsets.to_offset
  File "offsets.pyx", line 4453, in pandas._libs.tslibs.offsets._get_offset
ValueError: Invalid frequency: ME

The above exception was the direct cause of the following exception:

Traceback (most recent call last):
  File "c:\Users\joaop\Downloads\Projetos Cursor\FIDCs 2.0\src\data\data_collection.py", line 32, in collect_cvm_data
    df = importa_dados(nome_arquivo_fonte=arquivo, data_inicio=data_inicio)
         ^^^^^^^^^^^^^^^^^^^^^^^^^^^^^^^^^^^^^^^^^^^^^^^^^^^^^^^^^^^^^^^^^^
  File "c:\Users\joaop\Downloads\Projetos Cursor\FIDCs 2.0\src\scraping\cvm_scraper.py", line 63, in importa_dados
    datas_a_baixar = pd.date_range(start=data_inicio, end=data_atual, freq='ME')
                     ^^^^^^^^^^^^^^^^^^^^^^^^^^^^^^^^^^^^^^^^^^^^^^^^^^^^^^^^^^^
  File "C:\Users\joaop\AppData\Local\Packages\PythonSoftwareFoundation.Python.3.12_qbz5n2kfra8p0\LocalCache\local-packages\Python312\site-packages\pandas\core\indexes\datetimes.py", line 1009, in date_range
    dtarr = DatetimeArray._generate_range(
            ^^^^^^^^^^^^^^^^^^^^^^^^^^^^^^
  File "C:\Users\joaop\AppData\Local\Packages\PythonSoftwareFoundation.Python.3.12_qbz5n2kfra8p0\LocalCache\local-packages\Python312\site-packages\pandas\core\arrays\datetimes.py", line 404, in _generate_range
    freq = to_offset(freq)
           ^^^^^^^^^^^^^^^
  File "offsets.pyx", line 4460, in pandas._libs.tslibs.offsets.to_offset
  File "offsets.pyx", line 4557, in pandas._libs.tslibs.offsets.to_offset
ValueError: Invalid frequency: ME
[2025-03-19 23:52:02,587] [ERROR] [data_collection] - Erro na coleta de dados para risco_credito
(<class 'ValueError'>, ValueError('Invalid frequency: ME'), <traceback object at 0x0000019BC4923580>)
Traceback (most recent call last):
  File "offsets.pyx", line 4447, in pandas._libs.tslibs.offsets._get_offset
KeyError: 'ME'

The above exception was the direct cause of the following exception:

Traceback (most recent call last):
  File "offsets.pyx", line 4549, in pandas._libs.tslibs.offsets.to_offset
  File "offsets.pyx", line 4453, in pandas._libs.tslibs.offsets._get_offset
ValueError: Invalid frequency: ME

The above exception was the direct cause of the following exception:

Traceback (most recent call last):
  File "c:\Users\joaop\Downloads\Projetos Cursor\FIDCs 2.0\src\data\data_collection.py", line 32, in collect_cvm_data
    df = importa_dados(nome_arquivo_fonte=arquivo, data_inicio=data_inicio)
         ^^^^^^^^^^^^^^^^^^^^^^^^^^^^^^^^^^^^^^^^^^^^^^^^^^^^^^^^^^^^^^^^^^
  File "c:\Users\joaop\Downloads\Projetos Cursor\FIDCs 2.0\src\scraping\cvm_scraper.py", line 63, in importa_dados
    datas_a_baixar = pd.date_range(start=data_inicio, end=data_atual, freq='ME')
                     ^^^^^^^^^^^^^^^^^^^^^^^^^^^^^^^^^^^^^^^^^^^^^^^^^^^^^^^^^^^
  File "C:\Users\joaop\AppData\Local\Packages\PythonSoftwareFoundation.Python.3.12_qbz5n2kfra8p0\LocalCache\local-packages\Python312\site-packages\pandas\core\indexes\datetimes.py", line 1009, in date_range
    dtarr = DatetimeArray._generate_range(
            ^^^^^^^^^^^^^^^^^^^^^^^^^^^^^^
  File "C:\Users\joaop\AppData\Local\Packages\PythonSoftwareFoundation.Python.3.12_qbz5n2kfra8p0\LocalCache\local-packages\Python312\site-packages\pandas\core\arrays\datetimes.py", line 404, in _generate_range
    freq = to_offset(freq)
           ^^^^^^^^^^^^^^^
  File "offsets.pyx", line 4460, in pandas._libs.tslibs.offsets.to_offset
  File "offsets.pyx", line 4557, in pandas._libs.tslibs.offsets.to_offset
ValueError: Invalid frequency: ME
[2025-03-19 23:52:02,589] [ERROR] [data_collection] - Erro na coleta de dados para classes_cotistas
(<class 'ValueError'>, ValueError('Invalid frequency: ME'), <traceback object at 0x0000019BC4922FC0>)
Traceback (most recent call last):
  File "offsets.pyx", line 4447, in pandas._libs.tslibs.offsets._get_offset
KeyError: 'ME'

The above exception was the direct cause of the following exception:

Traceback (most recent call last):
  File "offsets.pyx", line 4549, in pandas._libs.tslibs.offsets.to_offset
  File "offsets.pyx", line 4453, in pandas._libs.tslibs.offsets._get_offset
ValueError: Invalid frequency: ME

The above exception was the direct cause of the following exception:

Traceback (most recent call last):
  File "c:\Users\joaop\Downloads\Projetos Cursor\FIDCs 2.0\src\data\data_collection.py", line 32, in collect_cvm_data
    df = importa_dados(nome_arquivo_fonte=arquivo, data_inicio=data_inicio)
         ^^^^^^^^^^^^^^^^^^^^^^^^^^^^^^^^^^^^^^^^^^^^^^^^^^^^^^^^^^^^^^^^^^
  File "c:\Users\joaop\Downloads\Projetos Cursor\FIDCs 2.0\src\scraping\cvm_scraper.py", line 63, in importa_dados
    datas_a_baixar = pd.date_range(start=data_inicio, end=data_atual, freq='ME')
                     ^^^^^^^^^^^^^^^^^^^^^^^^^^^^^^^^^^^^^^^^^^^^^^^^^^^^^^^^^^^
  File "C:\Users\joaop\AppData\Local\Packages\PythonSoftwareFoundation.Python.3.12_qbz5n2kfra8p0\LocalCache\local-packages\Python312\site-packages\pandas\core\indexes\datetimes.py", line 1009, in date_range
    dtarr = DatetimeArray._generate_range(
            ^^^^^^^^^^^^^^^^^^^^^^^^^^^^^^
  File "C:\Users\joaop\AppData\Local\Packages\PythonSoftwareFoundation.Python.3.12_qbz5n2kfra8p0\LocalCache\local-packages\Python312\site-packages\pandas\core\arrays\datetimes.py", line 404, in _generate_range
    freq = to_offset(freq)
           ^^^^^^^^^^^^^^^
  File "offsets.pyx", line 4460, in pandas._libs.tslibs.offsets.to_offset
  File "offsets.pyx", line 4557, in pandas._libs.tslibs.offsets.to_offset
ValueError: Invalid frequency: ME
[2025-03-19 23:52:02,591] [ERROR] [data_collection] - Erro na coleta de dados para distribuicao_cotistas
(<class 'ValueError'>, ValueError('Invalid frequency: ME'), <traceback object at 0x0000019BC4921FC0>)
Traceback (most recent call last):
  File "offsets.pyx", line 4447, in pandas._libs.tslibs.offsets._get_offset
KeyError: 'ME'

The above exception was the direct cause of the following exception:

Traceback (most recent call last):
  File "offsets.pyx", line 4549, in pandas._libs.tslibs.offsets.to_offset
  File "offsets.pyx", line 4453, in pandas._libs.tslibs.offsets._get_offset
ValueError: Invalid frequency: ME

The above exception was the direct cause of the following exception:

Traceback (most recent call last):
  File "c:\Users\joaop\Downloads\Projetos Cursor\FIDCs 2.0\src\data\data_collection.py", line 32, in collect_cvm_data
    df = importa_dados(nome_arquivo_fonte=arquivo, data_inicio=data_inicio)
         ^^^^^^^^^^^^^^^^^^^^^^^^^^^^^^^^^^^^^^^^^^^^^^^^^^^^^^^^^^^^^^^^^^
  File "c:\Users\joaop\Downloads\Projetos Cursor\FIDCs 2.0\src\scraping\cvm_scraper.py", line 63, in importa_dados
    datas_a_baixar = pd.date_range(start=data_inicio, end=data_atual, freq='ME')
                     ^^^^^^^^^^^^^^^^^^^^^^^^^^^^^^^^^^^^^^^^^^^^^^^^^^^^^^^^^^^
  File "C:\Users\joaop\AppData\Local\Packages\PythonSoftwareFoundation.Python.3.12_qbz5n2kfra8p0\LocalCache\local-packages\Python312\site-packages\pandas\core\indexes\datetimes.py", line 1009, in date_range
    dtarr = DatetimeArray._generate_range(
            ^^^^^^^^^^^^^^^^^^^^^^^^^^^^^^
  File "C:\Users\joaop\AppData\Local\Packages\PythonSoftwareFoundation.Python.3.12_qbz5n2kfra8p0\LocalCache\local-packages\Python312\site-packages\pandas\core\arrays\datetimes.py", line 404, in _generate_range
    freq = to_offset(freq)
           ^^^^^^^^^^^^^^^
  File "offsets.pyx", line 4460, in pandas._libs.tslibs.offsets.to_offset
  File "offsets.pyx", line 4557, in pandas._libs.tslibs.offsets.to_offset
ValueError: Invalid frequency: ME
[2025-03-19 23:52:02,592] [ERROR] [data_collection] - Erro na coleta de dados para cotas_valores
(<class 'ValueError'>, ValueError('Invalid frequency: ME'), <traceback object at 0x0000019BC492C280>)
Traceback (most recent call last):
  File "offsets.pyx", line 4447, in pandas._libs.tslibs.offsets._get_offset
KeyError: 'ME'

The above exception was the direct cause of the following exception:

Traceback (most recent call last):
  File "offsets.pyx", line 4549, in pandas._libs.tslibs.offsets.to_offset
  File "offsets.pyx", line 4453, in pandas._libs.tslibs.offsets._get_offset
ValueError: Invalid frequency: ME

The above exception was the direct cause of the following exception:

Traceback (most recent call last):
  File "c:\Users\joaop\Downloads\Projetos Cursor\FIDCs 2.0\src\data\data_collection.py", line 32, in collect_cvm_data
    df = importa_dados(nome_arquivo_fonte=arquivo, data_inicio=data_inicio)
         ^^^^^^^^^^^^^^^^^^^^^^^^^^^^^^^^^^^^^^^^^^^^^^^^^^^^^^^^^^^^^^^^^^
  File "c:\Users\joaop\Downloads\Projetos Cursor\FIDCs 2.0\src\scraping\cvm_scraper.py", line 63, in importa_dados
    datas_a_baixar = pd.date_range(start=data_inicio, end=data_atual, freq='ME')
                     ^^^^^^^^^^^^^^^^^^^^^^^^^^^^^^^^^^^^^^^^^^^^^^^^^^^^^^^^^^^
  File "C:\Users\joaop\AppData\Local\Packages\PythonSoftwareFoundation.Python.3.12_qbz5n2kfra8p0\LocalCache\local-packages\Python312\site-packages\pandas\core\indexes\datetimes.py", line 1009, in date_range
    dtarr = DatetimeArray._generate_range(
            ^^^^^^^^^^^^^^^^^^^^^^^^^^^^^^
  File "C:\Users\joaop\AppData\Local\Packages\PythonSoftwareFoundation.Python.3.12_qbz5n2kfra8p0\LocalCache\local-packages\Python312\site-packages\pandas\core\arrays\datetimes.py", line 404, in _generate_range
    freq = to_offset(freq)
           ^^^^^^^^^^^^^^^
  File "offsets.pyx", line 4460, in pandas._libs.tslibs.offsets.to_offset
  File "offsets.pyx", line 4557, in pandas._libs.tslibs.offsets.to_offset
ValueError: Invalid frequency: ME
[2025-03-19 23:52:02,594] [ERROR] [data_collection] - Erro na coleta de dados para rentabilidade
(<class 'ValueError'>, ValueError('Invalid frequency: ME'), <traceback object at 0x0000019BC49238C0>)
Traceback (most recent call last):
  File "offsets.pyx", line 4447, in pandas._libs.tslibs.offsets._get_offset
KeyError: 'ME'

The above exception was the direct cause of the following exception:

Traceback (most recent call last):
  File "offsets.pyx", line 4549, in pandas._libs.tslibs.offsets.to_offset
  File "offsets.pyx", line 4453, in pandas._libs.tslibs.offsets._get_offset
ValueError: Invalid frequency: ME

The above exception was the direct cause of the following exception:

Traceback (most recent call last):
  File "c:\Users\joaop\Downloads\Projetos Cursor\FIDCs 2.0\src\data\data_collection.py", line 32, in collect_cvm_data
    df = importa_dados(nome_arquivo_fonte=arquivo, data_inicio=data_inicio)
         ^^^^^^^^^^^^^^^^^^^^^^^^^^^^^^^^^^^^^^^^^^^^^^^^^^^^^^^^^^^^^^^^^^
  File "c:\Users\joaop\Downloads\Projetos Cursor\FIDCs 2.0\src\scraping\cvm_scraper.py", line 63, in importa_dados
    datas_a_baixar = pd.date_range(start=data_inicio, end=data_atual, freq='ME')
                     ^^^^^^^^^^^^^^^^^^^^^^^^^^^^^^^^^^^^^^^^^^^^^^^^^^^^^^^^^^^
  File "C:\Users\joaop\AppData\Local\Packages\PythonSoftwareFoundation.Python.3.12_qbz5n2kfra8p0\LocalCache\local-packages\Python312\site-packages\pandas\core\indexes\datetimes.py", line 1009, in date_range
    dtarr = DatetimeArray._generate_range(
            ^^^^^^^^^^^^^^^^^^^^^^^^^^^^^^
  File "C:\Users\joaop\AppData\Local\Packages\PythonSoftwareFoundation.Python.3.12_qbz5n2kfra8p0\LocalCache\local-packages\Python312\site-packages\pandas\core\arrays\datetimes.py", line 404, in _generate_range
    freq = to_offset(freq)
           ^^^^^^^^^^^^^^^
  File "offsets.pyx", line 4460, in pandas._libs.tslibs.offsets.to_offset
  File "offsets.pyx", line 4557, in pandas._libs.tslibs.offsets.to_offset
ValueError: Invalid frequency: ME
[2025-03-19 23:52:02,596] [ERROR] [data_collection] - Erro na coleta de dados para operacoes_estruturadas
(<class 'ValueError'>, ValueError('Invalid frequency: ME'), <traceback object at 0x0000019BC492C640>)
Traceback (most recent call last):
  File "offsets.pyx", line 4447, in pandas._libs.tslibs.offsets._get_offset
KeyError: 'ME'

The above exception was the direct cause of the following exception:

Traceback (most recent call last):
  File "offsets.pyx", line 4549, in pandas._libs.tslibs.offsets.to_offset
  File "offsets.pyx", line 4453, in pandas._libs.tslibs.offsets._get_offset
ValueError: Invalid frequency: ME

The above exception was the direct cause of the following exception:

Traceback (most recent call last):
  File "c:\Users\joaop\Downloads\Projetos Cursor\FIDCs 2.0\src\data\data_collection.py", line 32, in collect_cvm_data
    df = importa_dados(nome_arquivo_fonte=arquivo, data_inicio=data_inicio)
         ^^^^^^^^^^^^^^^^^^^^^^^^^^^^^^^^^^^^^^^^^^^^^^^^^^^^^^^^^^^^^^^^^^
  File "c:\Users\joaop\Downloads\Projetos Cursor\FIDCs 2.0\src\scraping\cvm_scraper.py", line 63, in importa_dados
    datas_a_baixar = pd.date_range(start=data_inicio, end=data_atual, freq='ME')
                     ^^^^^^^^^^^^^^^^^^^^^^^^^^^^^^^^^^^^^^^^^^^^^^^^^^^^^^^^^^^
  File "C:\Users\joaop\AppData\Local\Packages\PythonSoftwareFoundation.Python.3.12_qbz5n2kfra8p0\LocalCache\local-packages\Python312\site-packages\pandas\core\indexes\datetimes.py", line 1009, in date_range
    dtarr = DatetimeArray._generate_range(
            ^^^^^^^^^^^^^^^^^^^^^^^^^^^^^^
  File "C:\Users\joaop\AppData\Local\Packages\PythonSoftwareFoundation.Python.3.12_qbz5n2kfra8p0\LocalCache\local-packages\Python312\site-packages\pandas\core\arrays\datetimes.py", line 404, in _generate_range
    freq = to_offset(freq)
           ^^^^^^^^^^^^^^^
  File "offsets.pyx", line 4460, in pandas._libs.tslibs.offsets.to_offset
  File "offsets.pyx", line 4557, in pandas._libs.tslibs.offsets.to_offset
ValueError: Invalid frequency: ME
[2025-03-19 23:52:02,597] [ERROR] [data_collection] - Erro na coleta de dados para liquidez_ativos
(<class 'ValueError'>, ValueError('Invalid frequency: ME'), <traceback object at 0x0000019BC4923640>)
Traceback (most recent call last):
  File "offsets.pyx", line 4447, in pandas._libs.tslibs.offsets._get_offset
KeyError: 'ME'

The above exception was the direct cause of the following exception:

Traceback (most recent call last):
  File "offsets.pyx", line 4549, in pandas._libs.tslibs.offsets.to_offset
  File "offsets.pyx", line 4453, in pandas._libs.tslibs.offsets._get_offset
ValueError: Invalid frequency: ME

The above exception was the direct cause of the following exception:

Traceback (most recent call last):
  File "c:\Users\joaop\Downloads\Projetos Cursor\FIDCs 2.0\src\data\data_collection.py", line 32, in collect_cvm_data
    df = importa_dados(nome_arquivo_fonte=arquivo, data_inicio=data_inicio)
         ^^^^^^^^^^^^^^^^^^^^^^^^^^^^^^^^^^^^^^^^^^^^^^^^^^^^^^^^^^^^^^^^^^
  File "c:\Users\joaop\Downloads\Projetos Cursor\FIDCs 2.0\src\scraping\cvm_scraper.py", line 63, in importa_dados
    datas_a_baixar = pd.date_range(start=data_inicio, end=data_atual, freq='ME')
                     ^^^^^^^^^^^^^^^^^^^^^^^^^^^^^^^^^^^^^^^^^^^^^^^^^^^^^^^^^^^
  File "C:\Users\joaop\AppData\Local\Packages\PythonSoftwareFoundation.Python.3.12_qbz5n2kfra8p0\LocalCache\local-packages\Python312\site-packages\pandas\core\indexes\datetimes.py", line 1009, in date_range
    dtarr = DatetimeArray._generate_range(
            ^^^^^^^^^^^^^^^^^^^^^^^^^^^^^^
  File "C:\Users\joaop\AppData\Local\Packages\PythonSoftwareFoundation.Python.3.12_qbz5n2kfra8p0\LocalCache\local-packages\Python312\site-packages\pandas\core\arrays\datetimes.py", line 404, in _generate_range
    freq = to_offset(freq)
           ^^^^^^^^^^^^^^^
  File "offsets.pyx", line 4460, in pandas._libs.tslibs.offsets.to_offset
  File "offsets.pyx", line 4557, in pandas._libs.tslibs.offsets.to_offset
ValueError: Invalid frequency: ME
[2025-03-19 23:52:02,599] [ERROR] [data_collection] - Erro na coleta de dados para performance_fundo
(<class 'ValueError'>, ValueError('Invalid frequency: ME'), <traceback object at 0x0000019BC49238C0>)
Traceback (most recent call last):
  File "offsets.pyx", line 4447, in pandas._libs.tslibs.offsets._get_offset
KeyError: 'ME'

The above exception was the direct cause of the following exception:

Traceback (most recent call last):
  File "offsets.pyx", line 4549, in pandas._libs.tslibs.offsets.to_offset
  File "offsets.pyx", line 4453, in pandas._libs.tslibs.offsets._get_offset
ValueError: Invalid frequency: ME

The above exception was the direct cause of the following exception:

Traceback (most recent call last):
  File "c:\Users\joaop\Downloads\Projetos Cursor\FIDCs 2.0\src\data\data_collection.py", line 32, in collect_cvm_data
    df = importa_dados(nome_arquivo_fonte=arquivo, data_inicio=data_inicio)
         ^^^^^^^^^^^^^^^^^^^^^^^^^^^^^^^^^^^^^^^^^^^^^^^^^^^^^^^^^^^^^^^^^^
  File "c:\Users\joaop\Downloads\Projetos Cursor\FIDCs 2.0\src\scraping\cvm_scraper.py", line 63, in importa_dados
    datas_a_baixar = pd.date_range(start=data_inicio, end=data_atual, freq='ME')
                     ^^^^^^^^^^^^^^^^^^^^^^^^^^^^^^^^^^^^^^^^^^^^^^^^^^^^^^^^^^^
  File "C:\Users\joaop\AppData\Local\Packages\PythonSoftwareFoundation.Python.3.12_qbz5n2kfra8p0\LocalCache\local-packages\Python312\site-packages\pandas\core\indexes\datetimes.py", line 1009, in date_range
    dtarr = DatetimeArray._generate_range(
            ^^^^^^^^^^^^^^^^^^^^^^^^^^^^^^
  File "C:\Users\joaop\AppData\Local\Packages\PythonSoftwareFoundation.Python.3.12_qbz5n2kfra8p0\LocalCache\local-packages\Python312\site-packages\pandas\core\arrays\datetimes.py", line 404, in _generate_range
    freq = to_offset(freq)
           ^^^^^^^^^^^^^^^
  File "offsets.pyx", line 4460, in pandas._libs.tslibs.offsets.to_offset
  File "offsets.pyx", line 4557, in pandas._libs.tslibs.offsets.to_offset
ValueError: Invalid frequency: ME
[2025-03-19 23:52:02,601] [ERROR] [data_collection] - Erro na coleta de dados para garantias_seguros
(<class 'ValueError'>, ValueError('Invalid frequency: ME'), <traceback object at 0x0000019BC4921AC0>)
Traceback (most recent call last):
  File "offsets.pyx", line 4447, in pandas._libs.tslibs.offsets._get_offset
KeyError: 'ME'

The above exception was the direct cause of the following exception:

Traceback (most recent call last):
  File "offsets.pyx", line 4549, in pandas._libs.tslibs.offsets.to_offset
  File "offsets.pyx", line 4453, in pandas._libs.tslibs.offsets._get_offset
ValueError: Invalid frequency: ME

The above exception was the direct cause of the following exception:

Traceback (most recent call last):
  File "c:\Users\joaop\Downloads\Projetos Cursor\FIDCs 2.0\src\data\data_collection.py", line 32, in collect_cvm_data
    df = importa_dados(nome_arquivo_fonte=arquivo, data_inicio=data_inicio)
         ^^^^^^^^^^^^^^^^^^^^^^^^^^^^^^^^^^^^^^^^^^^^^^^^^^^^^^^^^^^^^^^^^^
  File "c:\Users\joaop\Downloads\Projetos Cursor\FIDCs 2.0\src\scraping\cvm_scraper.py", line 63, in importa_dados
    datas_a_baixar = pd.date_range(start=data_inicio, end=data_atual, freq='ME')
                     ^^^^^^^^^^^^^^^^^^^^^^^^^^^^^^^^^^^^^^^^^^^^^^^^^^^^^^^^^^^
  File "C:\Users\joaop\AppData\Local\Packages\PythonSoftwareFoundation.Python.3.12_qbz5n2kfra8p0\LocalCache\local-packages\Python312\site-packages\pandas\core\indexes\datetimes.py", line 1009, in date_range
    dtarr = DatetimeArray._generate_range(
            ^^^^^^^^^^^^^^^^^^^^^^^^^^^^^^
  File "C:\Users\joaop\AppData\Local\Packages\PythonSoftwareFoundation.Python.3.12_qbz5n2kfra8p0\LocalCache\local-packages\Python312\site-packages\pandas\core\arrays\datetimes.py", line 404, in _generate_range
    freq = to_offset(freq)
           ^^^^^^^^^^^^^^^
  File "offsets.pyx", line 4460, in pandas._libs.tslibs.offsets.to_offset
  File "offsets.pyx", line 4557, in pandas._libs.tslibs.offsets.to_offset
ValueError: Invalid frequency: ME
[2025-03-19 23:52:52,266] [ERROR] [data_collection] - Erro na coleta de dados para caracteristicas_fundo
(<class 'ValueError'>, ValueError('Invalid frequency: ME'), <traceback object at 0x000001B881DCEAC0>)
Traceback (most recent call last):
  File "offsets.pyx", line 4447, in pandas._libs.tslibs.offsets._get_offset
KeyError: 'ME'

The above exception was the direct cause of the following exception:

Traceback (most recent call last):
  File "offsets.pyx", line 4549, in pandas._libs.tslibs.offsets.to_offset
  File "offsets.pyx", line 4453, in pandas._libs.tslibs.offsets._get_offset
ValueError: Invalid frequency: ME

The above exception was the direct cause of the following exception:

Traceback (most recent call last):
  File "c:\Users\joaop\Downloads\Projetos Cursor\FIDCs 2.0\src\data\data_collection.py", line 32, in collect_cvm_data
    df = importa_dados(nome_arquivo_fonte=arquivo, data_inicio=data_inicio)
         ^^^^^^^^^^^^^^^^^^^^^^^^^^^^^^^^^^^^^^^^^^^^^^^^^^^^^^^^^^^^^^^^^^
  File "c:\Users\joaop\Downloads\Projetos Cursor\FIDCs 2.0\src\scraping\cvm_scraper.py", line 63, in importa_dados
    datas_a_baixar = pd.date_range(start=data_inicio, end=data_atual, freq='ME')
                     ^^^^^^^^^^^^^^^^^^^^^^^^^^^^^^^^^^^^^^^^^^^^^^^^^^^^^^^^^^^
  File "C:\Users\joaop\AppData\Local\Packages\PythonSoftwareFoundation.Python.3.12_qbz5n2kfra8p0\LocalCache\local-packages\Python312\site-packages\pandas\core\indexes\datetimes.py", line 1009, in date_range
    dtarr = DatetimeArray._generate_range(
            ^^^^^^^^^^^^^^^^^^^^^^^^^^^^^^
  File "C:\Users\joaop\AppData\Local\Packages\PythonSoftwareFoundation.Python.3.12_qbz5n2kfra8p0\LocalCache\local-packages\Python312\site-packages\pandas\core\arrays\datetimes.py", line 404, in _generate_range
    freq = to_offset(freq)
           ^^^^^^^^^^^^^^^
  File "offsets.pyx", line 4460, in pandas._libs.tslibs.offsets.to_offset
  File "offsets.pyx", line 4557, in pandas._libs.tslibs.offsets.to_offset
ValueError: Invalid frequency: ME
[2025-03-19 23:52:52,269] [ERROR] [data_collection] - Erro na coleta de dados para patrimonio_liquido
(<class 'ValueError'>, ValueError('Invalid frequency: ME'), <traceback object at 0x000001B881E24CC0>)
Traceback (most recent call last):
  File "offsets.pyx", line 4447, in pandas._libs.tslibs.offsets._get_offset
KeyError: 'ME'

The above exception was the direct cause of the following exception:

Traceback (most recent call last):
  File "offsets.pyx", line 4549, in pandas._libs.tslibs.offsets.to_offset
  File "offsets.pyx", line 4453, in pandas._libs.tslibs.offsets._get_offset
ValueError: Invalid frequency: ME

The above exception was the direct cause of the following exception:

Traceback (most recent call last):
  File "c:\Users\joaop\Downloads\Projetos Cursor\FIDCs 2.0\src\data\data_collection.py", line 32, in collect_cvm_data
    df = importa_dados(nome_arquivo_fonte=arquivo, data_inicio=data_inicio)
         ^^^^^^^^^^^^^^^^^^^^^^^^^^^^^^^^^^^^^^^^^^^^^^^^^^^^^^^^^^^^^^^^^^
  File "c:\Users\joaop\Downloads\Projetos Cursor\FIDCs 2.0\src\scraping\cvm_scraper.py", line 63, in importa_dados
    datas_a_baixar = pd.date_range(start=data_inicio, end=data_atual, freq='ME')
                     ^^^^^^^^^^^^^^^^^^^^^^^^^^^^^^^^^^^^^^^^^^^^^^^^^^^^^^^^^^^
  File "C:\Users\joaop\AppData\Local\Packages\PythonSoftwareFoundation.Python.3.12_qbz5n2kfra8p0\LocalCache\local-packages\Python312\site-packages\pandas\core\indexes\datetimes.py", line 1009, in date_range
    dtarr = DatetimeArray._generate_range(
            ^^^^^^^^^^^^^^^^^^^^^^^^^^^^^^
  File "C:\Users\joaop\AppData\Local\Packages\PythonSoftwareFoundation.Python.3.12_qbz5n2kfra8p0\LocalCache\local-packages\Python312\site-packages\pandas\core\arrays\datetimes.py", line 404, in _generate_range
    freq = to_offset(freq)
           ^^^^^^^^^^^^^^^
  File "offsets.pyx", line 4460, in pandas._libs.tslibs.offsets.to_offset
  File "offsets.pyx", line 4557, in pandas._libs.tslibs.offsets.to_offset
ValueError: Invalid frequency: ME
[2025-03-19 23:52:52,270] [ERROR] [data_collection] - Erro na coleta de dados para carteira_ativos
(<class 'ValueError'>, ValueError('Invalid frequency: ME'), <traceback object at 0x000001B881E24C40>)
Traceback (most recent call last):
  File "offsets.pyx", line 4447, in pandas._libs.tslibs.offsets._get_offset
KeyError: 'ME'

The above exception was the direct cause of the following exception:

Traceback (most recent call last):
  File "offsets.pyx", line 4549, in pandas._libs.tslibs.offsets.to_offset
  File "offsets.pyx", line 4453, in pandas._libs.tslibs.offsets._get_offset
ValueError: Invalid frequency: ME

The above exception was the direct cause of the following exception:

Traceback (most recent call last):
  File "c:\Users\joaop\Downloads\Projetos Cursor\FIDCs 2.0\src\data\data_collection.py", line 32, in collect_cvm_data
    df = importa_dados(nome_arquivo_fonte=arquivo, data_inicio=data_inicio)
         ^^^^^^^^^^^^^^^^^^^^^^^^^^^^^^^^^^^^^^^^^^^^^^^^^^^^^^^^^^^^^^^^^^
  File "c:\Users\joaop\Downloads\Projetos Cursor\FIDCs 2.0\src\scraping\cvm_scraper.py", line 63, in importa_dados
    datas_a_baixar = pd.date_range(start=data_inicio, end=data_atual, freq='ME')
                     ^^^^^^^^^^^^^^^^^^^^^^^^^^^^^^^^^^^^^^^^^^^^^^^^^^^^^^^^^^^
  File "C:\Users\joaop\AppData\Local\Packages\PythonSoftwareFoundation.Python.3.12_qbz5n2kfra8p0\LocalCache\local-packages\Python312\site-packages\pandas\core\indexes\datetimes.py", line 1009, in date_range
    dtarr = DatetimeArray._generate_range(
            ^^^^^^^^^^^^^^^^^^^^^^^^^^^^^^
  File "C:\Users\joaop\AppData\Local\Packages\PythonSoftwareFoundation.Python.3.12_qbz5n2kfra8p0\LocalCache\local-packages\Python312\site-packages\pandas\core\arrays\datetimes.py", line 404, in _generate_range
    freq = to_offset(freq)
           ^^^^^^^^^^^^^^^
  File "offsets.pyx", line 4460, in pandas._libs.tslibs.offsets.to_offset
  File "offsets.pyx", line 4557, in pandas._libs.tslibs.offsets.to_offset
ValueError: Invalid frequency: ME
[2025-03-19 23:52:52,272] [ERROR] [data_collection] - Erro na coleta de dados para passivos_derivativos
(<class 'ValueError'>, ValueError('Invalid frequency: ME'), <traceback object at 0x000001B881E25400>)
Traceback (most recent call last):
  File "offsets.pyx", line 4447, in pandas._libs.tslibs.offsets._get_offset
KeyError: 'ME'

The above exception was the direct cause of the following exception:

Traceback (most recent call last):
  File "offsets.pyx", line 4549, in pandas._libs.tslibs.offsets.to_offset
  File "offsets.pyx", line 4453, in pandas._libs.tslibs.offsets._get_offset
ValueError: Invalid frequency: ME

The above exception was the direct cause of the following exception:

Traceback (most recent call last):
  File "c:\Users\joaop\Downloads\Projetos Cursor\FIDCs 2.0\src\data\data_collection.py", line 32, in collect_cvm_data
    df = importa_dados(nome_arquivo_fonte=arquivo, data_inicio=data_inicio)
         ^^^^^^^^^^^^^^^^^^^^^^^^^^^^^^^^^^^^^^^^^^^^^^^^^^^^^^^^^^^^^^^^^^
  File "c:\Users\joaop\Downloads\Projetos Cursor\FIDCs 2.0\src\scraping\cvm_scraper.py", line 63, in importa_dados
    datas_a_baixar = pd.date_range(start=data_inicio, end=data_atual, freq='ME')
                     ^^^^^^^^^^^^^^^^^^^^^^^^^^^^^^^^^^^^^^^^^^^^^^^^^^^^^^^^^^^
  File "C:\Users\joaop\AppData\Local\Packages\PythonSoftwareFoundation.Python.3.12_qbz5n2kfra8p0\LocalCache\local-packages\Python312\site-packages\pandas\core\indexes\datetimes.py", line 1009, in date_range
    dtarr = DatetimeArray._generate_range(
            ^^^^^^^^^^^^^^^^^^^^^^^^^^^^^^
  File "C:\Users\joaop\AppData\Local\Packages\PythonSoftwareFoundation.Python.3.12_qbz5n2kfra8p0\LocalCache\local-packages\Python312\site-packages\pandas\core\arrays\datetimes.py", line 404, in _generate_range
    freq = to_offset(freq)
           ^^^^^^^^^^^^^^^
  File "offsets.pyx", line 4460, in pandas._libs.tslibs.offsets.to_offset
  File "offsets.pyx", line 4557, in pandas._libs.tslibs.offsets.to_offset
ValueError: Invalid frequency: ME
[2025-03-19 23:52:52,273] [ERROR] [data_collection] - Erro na coleta de dados para prazos_creditos
(<class 'ValueError'>, ValueError('Invalid frequency: ME'), <traceback object at 0x000001B881E248C0>)
Traceback (most recent call last):
  File "offsets.pyx", line 4447, in pandas._libs.tslibs.offsets._get_offset
KeyError: 'ME'

The above exception was the direct cause of the following exception:

Traceback (most recent call last):
  File "offsets.pyx", line 4549, in pandas._libs.tslibs.offsets.to_offset
  File "offsets.pyx", line 4453, in pandas._libs.tslibs.offsets._get_offset
ValueError: Invalid frequency: ME

The above exception was the direct cause of the following exception:

Traceback (most recent call last):
  File "c:\Users\joaop\Downloads\Projetos Cursor\FIDCs 2.0\src\data\data_collection.py", line 32, in collect_cvm_data
    df = importa_dados(nome_arquivo_fonte=arquivo, data_inicio=data_inicio)
         ^^^^^^^^^^^^^^^^^^^^^^^^^^^^^^^^^^^^^^^^^^^^^^^^^^^^^^^^^^^^^^^^^^
  File "c:\Users\joaop\Downloads\Projetos Cursor\FIDCs 2.0\src\scraping\cvm_scraper.py", line 63, in importa_dados
    datas_a_baixar = pd.date_range(start=data_inicio, end=data_atual, freq='ME')
                     ^^^^^^^^^^^^^^^^^^^^^^^^^^^^^^^^^^^^^^^^^^^^^^^^^^^^^^^^^^^
  File "C:\Users\joaop\AppData\Local\Packages\PythonSoftwareFoundation.Python.3.12_qbz5n2kfra8p0\LocalCache\local-packages\Python312\site-packages\pandas\core\indexes\datetimes.py", line 1009, in date_range
    dtarr = DatetimeArray._generate_range(
            ^^^^^^^^^^^^^^^^^^^^^^^^^^^^^^
  File "C:\Users\joaop\AppData\Local\Packages\PythonSoftwareFoundation.Python.3.12_qbz5n2kfra8p0\LocalCache\local-packages\Python312\site-packages\pandas\core\arrays\datetimes.py", line 404, in _generate_range
    freq = to_offset(freq)
           ^^^^^^^^^^^^^^^
  File "offsets.pyx", line 4460, in pandas._libs.tslibs.offsets.to_offset
  File "offsets.pyx", line 4557, in pandas._libs.tslibs.offsets.to_offset
ValueError: Invalid frequency: ME
[2025-03-19 23:52:52,275] [ERROR] [data_collection] - Erro na coleta de dados para inadimplencia
(<class 'ValueError'>, ValueError('Invalid frequency: ME'), <traceback object at 0x000001B881E25280>)
Traceback (most recent call last):
  File "offsets.pyx", line 4447, in pandas._libs.tslibs.offsets._get_offset
KeyError: 'ME'

The above exception was the direct cause of the following exception:

Traceback (most recent call last):
  File "offsets.pyx", line 4549, in pandas._libs.tslibs.offsets.to_offset
  File "offsets.pyx", line 4453, in pandas._libs.tslibs.offsets._get_offset
ValueError: Invalid frequency: ME

The above exception was the direct cause of the following exception:

Traceback (most recent call last):
  File "c:\Users\joaop\Downloads\Projetos Cursor\FIDCs 2.0\src\data\data_collection.py", line 32, in collect_cvm_data
    df = importa_dados(nome_arquivo_fonte=arquivo, data_inicio=data_inicio)
         ^^^^^^^^^^^^^^^^^^^^^^^^^^^^^^^^^^^^^^^^^^^^^^^^^^^^^^^^^^^^^^^^^^
  File "c:\Users\joaop\Downloads\Projetos Cursor\FIDCs 2.0\src\scraping\cvm_scraper.py", line 63, in importa_dados
    datas_a_baixar = pd.date_range(start=data_inicio, end=data_atual, freq='ME')
                     ^^^^^^^^^^^^^^^^^^^^^^^^^^^^^^^^^^^^^^^^^^^^^^^^^^^^^^^^^^^
  File "C:\Users\joaop\AppData\Local\Packages\PythonSoftwareFoundation.Python.3.12_qbz5n2kfra8p0\LocalCache\local-packages\Python312\site-packages\pandas\core\indexes\datetimes.py", line 1009, in date_range
    dtarr = DatetimeArray._generate_range(
            ^^^^^^^^^^^^^^^^^^^^^^^^^^^^^^
  File "C:\Users\joaop\AppData\Local\Packages\PythonSoftwareFoundation.Python.3.12_qbz5n2kfra8p0\LocalCache\local-packages\Python312\site-packages\pandas\core\arrays\datetimes.py", line 404, in _generate_range
    freq = to_offset(freq)
           ^^^^^^^^^^^^^^^
  File "offsets.pyx", line 4460, in pandas._libs.tslibs.offsets.to_offset
  File "offsets.pyx", line 4557, in pandas._libs.tslibs.offsets.to_offset
ValueError: Invalid frequency: ME
[2025-03-19 23:52:52,276] [ERROR] [data_collection] - Erro na coleta de dados para cedentes_tomadores
(<class 'ValueError'>, ValueError('Invalid frequency: ME'), <traceback object at 0x000001B881E25780>)
Traceback (most recent call last):
  File "offsets.pyx", line 4447, in pandas._libs.tslibs.offsets._get_offset
KeyError: 'ME'

The above exception was the direct cause of the following exception:

Traceback (most recent call last):
  File "offsets.pyx", line 4549, in pandas._libs.tslibs.offsets.to_offset
  File "offsets.pyx", line 4453, in pandas._libs.tslibs.offsets._get_offset
ValueError: Invalid frequency: ME

The above exception was the direct cause of the following exception:

Traceback (most recent call last):
  File "c:\Users\joaop\Downloads\Projetos Cursor\FIDCs 2.0\src\data\data_collection.py", line 32, in collect_cvm_data
    df = importa_dados(nome_arquivo_fonte=arquivo, data_inicio=data_inicio)
         ^^^^^^^^^^^^^^^^^^^^^^^^^^^^^^^^^^^^^^^^^^^^^^^^^^^^^^^^^^^^^^^^^^
  File "c:\Users\joaop\Downloads\Projetos Cursor\FIDCs 2.0\src\scraping\cvm_scraper.py", line 63, in importa_dados
    datas_a_baixar = pd.date_range(start=data_inicio, end=data_atual, freq='ME')
                     ^^^^^^^^^^^^^^^^^^^^^^^^^^^^^^^^^^^^^^^^^^^^^^^^^^^^^^^^^^^
  File "C:\Users\joaop\AppData\Local\Packages\PythonSoftwareFoundation.Python.3.12_qbz5n2kfra8p0\LocalCache\local-packages\Python312\site-packages\pandas\core\indexes\datetimes.py", line 1009, in date_range
    dtarr = DatetimeArray._generate_range(
            ^^^^^^^^^^^^^^^^^^^^^^^^^^^^^^
  File "C:\Users\joaop\AppData\Local\Packages\PythonSoftwareFoundation.Python.3.12_qbz5n2kfra8p0\LocalCache\local-packages\Python312\site-packages\pandas\core\arrays\datetimes.py", line 404, in _generate_range
    freq = to_offset(freq)
           ^^^^^^^^^^^^^^^
  File "offsets.pyx", line 4460, in pandas._libs.tslibs.offsets.to_offset
  File "offsets.pyx", line 4557, in pandas._libs.tslibs.offsets.to_offset
ValueError: Invalid frequency: ME
[2025-03-19 23:52:52,278] [ERROR] [data_collection] - Erro na coleta de dados para precos_mercado
(<class 'ValueError'>, ValueError('Invalid frequency: ME'), <traceback object at 0x000001B881E24A80>)
Traceback (most recent call last):
  File "offsets.pyx", line 4447, in pandas._libs.tslibs.offsets._get_offset
KeyError: 'ME'

The above exception was the direct cause of the following exception:

Traceback (most recent call last):
  File "offsets.pyx", line 4549, in pandas._libs.tslibs.offsets.to_offset
  File "offsets.pyx", line 4453, in pandas._libs.tslibs.offsets._get_offset
ValueError: Invalid frequency: ME

The above exception was the direct cause of the following exception:

Traceback (most recent call last):
  File "c:\Users\joaop\Downloads\Projetos Cursor\FIDCs 2.0\src\data\data_collection.py", line 32, in collect_cvm_data
    df = importa_dados(nome_arquivo_fonte=arquivo, data_inicio=data_inicio)
         ^^^^^^^^^^^^^^^^^^^^^^^^^^^^^^^^^^^^^^^^^^^^^^^^^^^^^^^^^^^^^^^^^^
  File "c:\Users\joaop\Downloads\Projetos Cursor\FIDCs 2.0\src\scraping\cvm_scraper.py", line 63, in importa_dados
    datas_a_baixar = pd.date_range(start=data_inicio, end=data_atual, freq='ME')
                     ^^^^^^^^^^^^^^^^^^^^^^^^^^^^^^^^^^^^^^^^^^^^^^^^^^^^^^^^^^^
  File "C:\Users\joaop\AppData\Local\Packages\PythonSoftwareFoundation.Python.3.12_qbz5n2kfra8p0\LocalCache\local-packages\Python312\site-packages\pandas\core\indexes\datetimes.py", line 1009, in date_range
    dtarr = DatetimeArray._generate_range(
            ^^^^^^^^^^^^^^^^^^^^^^^^^^^^^^
  File "C:\Users\joaop\AppData\Local\Packages\PythonSoftwareFoundation.Python.3.12_qbz5n2kfra8p0\LocalCache\local-packages\Python312\site-packages\pandas\core\arrays\datetimes.py", line 404, in _generate_range
    freq = to_offset(freq)
           ^^^^^^^^^^^^^^^
  File "offsets.pyx", line 4460, in pandas._libs.tslibs.offsets.to_offset
  File "offsets.pyx", line 4557, in pandas._libs.tslibs.offsets.to_offset
ValueError: Invalid frequency: ME
[2025-03-19 23:52:52,279] [ERROR] [data_collection] - Erro na coleta de dados para risco_credito
(<class 'ValueError'>, ValueError('Invalid frequency: ME'), <traceback object at 0x000001B881E25940>)
Traceback (most recent call last):
  File "offsets.pyx", line 4447, in pandas._libs.tslibs.offsets._get_offset
KeyError: 'ME'

The above exception was the direct cause of the following exception:

Traceback (most recent call last):
  File "offsets.pyx", line 4549, in pandas._libs.tslibs.offsets.to_offset
  File "offsets.pyx", line 4453, in pandas._libs.tslibs.offsets._get_offset
ValueError: Invalid frequency: ME

The above exception was the direct cause of the following exception:

Traceback (most recent call last):
  File "c:\Users\joaop\Downloads\Projetos Cursor\FIDCs 2.0\src\data\data_collection.py", line 32, in collect_cvm_data
    df = importa_dados(nome_arquivo_fonte=arquivo, data_inicio=data_inicio)
         ^^^^^^^^^^^^^^^^^^^^^^^^^^^^^^^^^^^^^^^^^^^^^^^^^^^^^^^^^^^^^^^^^^
  File "c:\Users\joaop\Downloads\Projetos Cursor\FIDCs 2.0\src\scraping\cvm_scraper.py", line 63, in importa_dados
    datas_a_baixar = pd.date_range(start=data_inicio, end=data_atual, freq='ME')
                     ^^^^^^^^^^^^^^^^^^^^^^^^^^^^^^^^^^^^^^^^^^^^^^^^^^^^^^^^^^^
  File "C:\Users\joaop\AppData\Local\Packages\PythonSoftwareFoundation.Python.3.12_qbz5n2kfra8p0\LocalCache\local-packages\Python312\site-packages\pandas\core\indexes\datetimes.py", line 1009, in date_range
    dtarr = DatetimeArray._generate_range(
            ^^^^^^^^^^^^^^^^^^^^^^^^^^^^^^
  File "C:\Users\joaop\AppData\Local\Packages\PythonSoftwareFoundation.Python.3.12_qbz5n2kfra8p0\LocalCache\local-packages\Python312\site-packages\pandas\core\arrays\datetimes.py", line 404, in _generate_range
    freq = to_offset(freq)
           ^^^^^^^^^^^^^^^
  File "offsets.pyx", line 4460, in pandas._libs.tslibs.offsets.to_offset
  File "offsets.pyx", line 4557, in pandas._libs.tslibs.offsets.to_offset
ValueError: Invalid frequency: ME
[2025-03-19 23:52:52,281] [ERROR] [data_collection] - Erro na coleta de dados para classes_cotistas
(<class 'ValueError'>, ValueError('Invalid frequency: ME'), <traceback object at 0x000001B881E25200>)
Traceback (most recent call last):
  File "offsets.pyx", line 4447, in pandas._libs.tslibs.offsets._get_offset
KeyError: 'ME'

The above exception was the direct cause of the following exception:

Traceback (most recent call last):
  File "offsets.pyx", line 4549, in pandas._libs.tslibs.offsets.to_offset
  File "offsets.pyx", line 4453, in pandas._libs.tslibs.offsets._get_offset
ValueError: Invalid frequency: ME

The above exception was the direct cause of the following exception:

Traceback (most recent call last):
  File "c:\Users\joaop\Downloads\Projetos Cursor\FIDCs 2.0\src\data\data_collection.py", line 32, in collect_cvm_data
    df = importa_dados(nome_arquivo_fonte=arquivo, data_inicio=data_inicio)
         ^^^^^^^^^^^^^^^^^^^^^^^^^^^^^^^^^^^^^^^^^^^^^^^^^^^^^^^^^^^^^^^^^^
  File "c:\Users\joaop\Downloads\Projetos Cursor\FIDCs 2.0\src\scraping\cvm_scraper.py", line 63, in importa_dados
    datas_a_baixar = pd.date_range(start=data_inicio, end=data_atual, freq='ME')
                     ^^^^^^^^^^^^^^^^^^^^^^^^^^^^^^^^^^^^^^^^^^^^^^^^^^^^^^^^^^^
  File "C:\Users\joaop\AppData\Local\Packages\PythonSoftwareFoundation.Python.3.12_qbz5n2kfra8p0\LocalCache\local-packages\Python312\site-packages\pandas\core\indexes\datetimes.py", line 1009, in date_range
    dtarr = DatetimeArray._generate_range(
            ^^^^^^^^^^^^^^^^^^^^^^^^^^^^^^
  File "C:\Users\joaop\AppData\Local\Packages\PythonSoftwareFoundation.Python.3.12_qbz5n2kfra8p0\LocalCache\local-packages\Python312\site-packages\pandas\core\arrays\datetimes.py", line 404, in _generate_range
    freq = to_offset(freq)
           ^^^^^^^^^^^^^^^
  File "offsets.pyx", line 4460, in pandas._libs.tslibs.offsets.to_offset
  File "offsets.pyx", line 4557, in pandas._libs.tslibs.offsets.to_offset
ValueError: Invalid frequency: ME
[2025-03-19 23:52:52,282] [ERROR] [data_collection] - Erro na coleta de dados para distribuicao_cotistas
(<class 'ValueError'>, ValueError('Invalid frequency: ME'), <traceback object at 0x000001B881E25E40>)
Traceback (most recent call last):
  File "offsets.pyx", line 4447, in pandas._libs.tslibs.offsets._get_offset
KeyError: 'ME'

The above exception was the direct cause of the following exception:

Traceback (most recent call last):
  File "offsets.pyx", line 4549, in pandas._libs.tslibs.offsets.to_offset
  File "offsets.pyx", line 4453, in pandas._libs.tslibs.offsets._get_offset
ValueError: Invalid frequency: ME

The above exception was the direct cause of the following exception:

Traceback (most recent call last):
  File "c:\Users\joaop\Downloads\Projetos Cursor\FIDCs 2.0\src\data\data_collection.py", line 32, in collect_cvm_data
    df = importa_dados(nome_arquivo_fonte=arquivo, data_inicio=data_inicio)
         ^^^^^^^^^^^^^^^^^^^^^^^^^^^^^^^^^^^^^^^^^^^^^^^^^^^^^^^^^^^^^^^^^^
  File "c:\Users\joaop\Downloads\Projetos Cursor\FIDCs 2.0\src\scraping\cvm_scraper.py", line 63, in importa_dados
    datas_a_baixar = pd.date_range(start=data_inicio, end=data_atual, freq='ME')
                     ^^^^^^^^^^^^^^^^^^^^^^^^^^^^^^^^^^^^^^^^^^^^^^^^^^^^^^^^^^^
  File "C:\Users\joaop\AppData\Local\Packages\PythonSoftwareFoundation.Python.3.12_qbz5n2kfra8p0\LocalCache\local-packages\Python312\site-packages\pandas\core\indexes\datetimes.py", line 1009, in date_range
    dtarr = DatetimeArray._generate_range(
            ^^^^^^^^^^^^^^^^^^^^^^^^^^^^^^
  File "C:\Users\joaop\AppData\Local\Packages\PythonSoftwareFoundation.Python.3.12_qbz5n2kfra8p0\LocalCache\local-packages\Python312\site-packages\pandas\core\arrays\datetimes.py", line 404, in _generate_range
    freq = to_offset(freq)
           ^^^^^^^^^^^^^^^
  File "offsets.pyx", line 4460, in pandas._libs.tslibs.offsets.to_offset
  File "offsets.pyx", line 4557, in pandas._libs.tslibs.offsets.to_offset
ValueError: Invalid frequency: ME
[2025-03-19 23:52:52,283] [ERROR] [data_collection] - Erro na coleta de dados para cotas_valores
(<class 'ValueError'>, ValueError('Invalid frequency: ME'), <traceback object at 0x000001B881E25600>)
Traceback (most recent call last):
  File "offsets.pyx", line 4447, in pandas._libs.tslibs.offsets._get_offset
KeyError: 'ME'

The above exception was the direct cause of the following exception:

Traceback (most recent call last):
  File "offsets.pyx", line 4549, in pandas._libs.tslibs.offsets.to_offset
  File "offsets.pyx", line 4453, in pandas._libs.tslibs.offsets._get_offset
ValueError: Invalid frequency: ME

The above exception was the direct cause of the following exception:

Traceback (most recent call last):
  File "c:\Users\joaop\Downloads\Projetos Cursor\FIDCs 2.0\src\data\data_collection.py", line 32, in collect_cvm_data
    df = importa_dados(nome_arquivo_fonte=arquivo, data_inicio=data_inicio)
         ^^^^^^^^^^^^^^^^^^^^^^^^^^^^^^^^^^^^^^^^^^^^^^^^^^^^^^^^^^^^^^^^^^
  File "c:\Users\joaop\Downloads\Projetos Cursor\FIDCs 2.0\src\scraping\cvm_scraper.py", line 63, in importa_dados
    datas_a_baixar = pd.date_range(start=data_inicio, end=data_atual, freq='ME')
                     ^^^^^^^^^^^^^^^^^^^^^^^^^^^^^^^^^^^^^^^^^^^^^^^^^^^^^^^^^^^
  File "C:\Users\joaop\AppData\Local\Packages\PythonSoftwareFoundation.Python.3.12_qbz5n2kfra8p0\LocalCache\local-packages\Python312\site-packages\pandas\core\indexes\datetimes.py", line 1009, in date_range
    dtarr = DatetimeArray._generate_range(
            ^^^^^^^^^^^^^^^^^^^^^^^^^^^^^^
  File "C:\Users\joaop\AppData\Local\Packages\PythonSoftwareFoundation.Python.3.12_qbz5n2kfra8p0\LocalCache\local-packages\Python312\site-packages\pandas\core\arrays\datetimes.py", line 404, in _generate_range
    freq = to_offset(freq)
           ^^^^^^^^^^^^^^^
  File "offsets.pyx", line 4460, in pandas._libs.tslibs.offsets.to_offset
  File "offsets.pyx", line 4557, in pandas._libs.tslibs.offsets.to_offset
ValueError: Invalid frequency: ME
[2025-03-19 23:52:52,285] [ERROR] [data_collection] - Erro na coleta de dados para rentabilidade
(<class 'ValueError'>, ValueError('Invalid frequency: ME'), <traceback object at 0x000001B881E26040>)
Traceback (most recent call last):
  File "offsets.pyx", line 4447, in pandas._libs.tslibs.offsets._get_offset
KeyError: 'ME'

The above exception was the direct cause of the following exception:

Traceback (most recent call last):
  File "offsets.pyx", line 4549, in pandas._libs.tslibs.offsets.to_offset
  File "offsets.pyx", line 4453, in pandas._libs.tslibs.offsets._get_offset
ValueError: Invalid frequency: ME

The above exception was the direct cause of the following exception:

Traceback (most recent call last):
  File "c:\Users\joaop\Downloads\Projetos Cursor\FIDCs 2.0\src\data\data_collection.py", line 32, in collect_cvm_data
    df = importa_dados(nome_arquivo_fonte=arquivo, data_inicio=data_inicio)
         ^^^^^^^^^^^^^^^^^^^^^^^^^^^^^^^^^^^^^^^^^^^^^^^^^^^^^^^^^^^^^^^^^^
  File "c:\Users\joaop\Downloads\Projetos Cursor\FIDCs 2.0\src\scraping\cvm_scraper.py", line 63, in importa_dados
    datas_a_baixar = pd.date_range(start=data_inicio, end=data_atual, freq='ME')
                     ^^^^^^^^^^^^^^^^^^^^^^^^^^^^^^^^^^^^^^^^^^^^^^^^^^^^^^^^^^^
  File "C:\Users\joaop\AppData\Local\Packages\PythonSoftwareFoundation.Python.3.12_qbz5n2kfra8p0\LocalCache\local-packages\Python312\site-packages\pandas\core\indexes\datetimes.py", line 1009, in date_range
    dtarr = DatetimeArray._generate_range(
            ^^^^^^^^^^^^^^^^^^^^^^^^^^^^^^
  File "C:\Users\joaop\AppData\Local\Packages\PythonSoftwareFoundation.Python.3.12_qbz5n2kfra8p0\LocalCache\local-packages\Python312\site-packages\pandas\core\arrays\datetimes.py", line 404, in _generate_range
    freq = to_offset(freq)
           ^^^^^^^^^^^^^^^
  File "offsets.pyx", line 4460, in pandas._libs.tslibs.offsets.to_offset
  File "offsets.pyx", line 4557, in pandas._libs.tslibs.offsets.to_offset
ValueError: Invalid frequency: ME
[2025-03-19 23:52:52,286] [ERROR] [data_collection] - Erro na coleta de dados para operacoes_estruturadas
(<class 'ValueError'>, ValueError('Invalid frequency: ME'), <traceback object at 0x000001B881E25A80>)
Traceback (most recent call last):
  File "offsets.pyx", line 4447, in pandas._libs.tslibs.offsets._get_offset
KeyError: 'ME'

The above exception was the direct cause of the following exception:

Traceback (most recent call last):
  File "offsets.pyx", line 4549, in pandas._libs.tslibs.offsets.to_offset
  File "offsets.pyx", line 4453, in pandas._libs.tslibs.offsets._get_offset
ValueError: Invalid frequency: ME

The above exception was the direct cause of the following exception:

Traceback (most recent call last):
  File "c:\Users\joaop\Downloads\Projetos Cursor\FIDCs 2.0\src\data\data_collection.py", line 32, in collect_cvm_data
    df = importa_dados(nome_arquivo_fonte=arquivo, data_inicio=data_inicio)
         ^^^^^^^^^^^^^^^^^^^^^^^^^^^^^^^^^^^^^^^^^^^^^^^^^^^^^^^^^^^^^^^^^^
  File "c:\Users\joaop\Downloads\Projetos Cursor\FIDCs 2.0\src\scraping\cvm_scraper.py", line 63, in importa_dados
    datas_a_baixar = pd.date_range(start=data_inicio, end=data_atual, freq='ME')
                     ^^^^^^^^^^^^^^^^^^^^^^^^^^^^^^^^^^^^^^^^^^^^^^^^^^^^^^^^^^^
  File "C:\Users\joaop\AppData\Local\Packages\PythonSoftwareFoundation.Python.3.12_qbz5n2kfra8p0\LocalCache\local-packages\Python312\site-packages\pandas\core\indexes\datetimes.py", line 1009, in date_range
    dtarr = DatetimeArray._generate_range(
            ^^^^^^^^^^^^^^^^^^^^^^^^^^^^^^
  File "C:\Users\joaop\AppData\Local\Packages\PythonSoftwareFoundation.Python.3.12_qbz5n2kfra8p0\LocalCache\local-packages\Python312\site-packages\pandas\core\arrays\datetimes.py", line 404, in _generate_range
    freq = to_offset(freq)
           ^^^^^^^^^^^^^^^
  File "offsets.pyx", line 4460, in pandas._libs.tslibs.offsets.to_offset
  File "offsets.pyx", line 4557, in pandas._libs.tslibs.offsets.to_offset
ValueError: Invalid frequency: ME
[2025-03-19 23:52:52,287] [ERROR] [data_collection] - Erro na coleta de dados para liquidez_ativos
(<class 'ValueError'>, ValueError('Invalid frequency: ME'), <traceback object at 0x000001B881E25280>)
Traceback (most recent call last):
  File "offsets.pyx", line 4447, in pandas._libs.tslibs.offsets._get_offset
KeyError: 'ME'

The above exception was the direct cause of the following exception:

Traceback (most recent call last):
  File "offsets.pyx", line 4549, in pandas._libs.tslibs.offsets.to_offset
  File "offsets.pyx", line 4453, in pandas._libs.tslibs.offsets._get_offset
ValueError: Invalid frequency: ME

The above exception was the direct cause of the following exception:

Traceback (most recent call last):
  File "c:\Users\joaop\Downloads\Projetos Cursor\FIDCs 2.0\src\data\data_collection.py", line 32, in collect_cvm_data
    df = importa_dados(nome_arquivo_fonte=arquivo, data_inicio=data_inicio)
         ^^^^^^^^^^^^^^^^^^^^^^^^^^^^^^^^^^^^^^^^^^^^^^^^^^^^^^^^^^^^^^^^^^
  File "c:\Users\joaop\Downloads\Projetos Cursor\FIDCs 2.0\src\scraping\cvm_scraper.py", line 63, in importa_dados
    datas_a_baixar = pd.date_range(start=data_inicio, end=data_atual, freq='ME')
                     ^^^^^^^^^^^^^^^^^^^^^^^^^^^^^^^^^^^^^^^^^^^^^^^^^^^^^^^^^^^
  File "C:\Users\joaop\AppData\Local\Packages\PythonSoftwareFoundation.Python.3.12_qbz5n2kfra8p0\LocalCache\local-packages\Python312\site-packages\pandas\core\indexes\datetimes.py", line 1009, in date_range
    dtarr = DatetimeArray._generate_range(
            ^^^^^^^^^^^^^^^^^^^^^^^^^^^^^^
  File "C:\Users\joaop\AppData\Local\Packages\PythonSoftwareFoundation.Python.3.12_qbz5n2kfra8p0\LocalCache\local-packages\Python312\site-packages\pandas\core\arrays\datetimes.py", line 404, in _generate_range
    freq = to_offset(freq)
           ^^^^^^^^^^^^^^^
  File "offsets.pyx", line 4460, in pandas._libs.tslibs.offsets.to_offset
  File "offsets.pyx", line 4557, in pandas._libs.tslibs.offsets.to_offset
ValueError: Invalid frequency: ME
[2025-03-19 23:52:52,289] [ERROR] [data_collection] - Erro na coleta de dados para performance_fundo
(<class 'ValueError'>, ValueError('Invalid frequency: ME'), <traceback object at 0x000001B881E26400>)
Traceback (most recent call last):
  File "offsets.pyx", line 4447, in pandas._libs.tslibs.offsets._get_offset
KeyError: 'ME'

The above exception was the direct cause of the following exception:

Traceback (most recent call last):
  File "offsets.pyx", line 4549, in pandas._libs.tslibs.offsets.to_offset
  File "offsets.pyx", line 4453, in pandas._libs.tslibs.offsets._get_offset
ValueError: Invalid frequency: ME

The above exception was the direct cause of the following exception:

Traceback (most recent call last):
  File "c:\Users\joaop\Downloads\Projetos Cursor\FIDCs 2.0\src\data\data_collection.py", line 32, in collect_cvm_data
    df = importa_dados(nome_arquivo_fonte=arquivo, data_inicio=data_inicio)
         ^^^^^^^^^^^^^^^^^^^^^^^^^^^^^^^^^^^^^^^^^^^^^^^^^^^^^^^^^^^^^^^^^^
  File "c:\Users\joaop\Downloads\Projetos Cursor\FIDCs 2.0\src\scraping\cvm_scraper.py", line 63, in importa_dados
    datas_a_baixar = pd.date_range(start=data_inicio, end=data_atual, freq='ME')
                     ^^^^^^^^^^^^^^^^^^^^^^^^^^^^^^^^^^^^^^^^^^^^^^^^^^^^^^^^^^^
  File "C:\Users\joaop\AppData\Local\Packages\PythonSoftwareFoundation.Python.3.12_qbz5n2kfra8p0\LocalCache\local-packages\Python312\site-packages\pandas\core\indexes\datetimes.py", line 1009, in date_range
    dtarr = DatetimeArray._generate_range(
            ^^^^^^^^^^^^^^^^^^^^^^^^^^^^^^
  File "C:\Users\joaop\AppData\Local\Packages\PythonSoftwareFoundation.Python.3.12_qbz5n2kfra8p0\LocalCache\local-packages\Python312\site-packages\pandas\core\arrays\datetimes.py", line 404, in _generate_range
    freq = to_offset(freq)
           ^^^^^^^^^^^^^^^
  File "offsets.pyx", line 4460, in pandas._libs.tslibs.offsets.to_offset
  File "offsets.pyx", line 4557, in pandas._libs.tslibs.offsets.to_offset
ValueError: Invalid frequency: ME
[2025-03-19 23:52:52,291] [ERROR] [data_collection] - Erro na coleta de dados para garantias_seguros
(<class 'ValueError'>, ValueError('Invalid frequency: ME'), <traceback object at 0x000001B881E260C0>)
Traceback (most recent call last):
  File "offsets.pyx", line 4447, in pandas._libs.tslibs.offsets._get_offset
KeyError: 'ME'

The above exception was the direct cause of the following exception:

Traceback (most recent call last):
  File "offsets.pyx", line 4549, in pandas._libs.tslibs.offsets.to_offset
  File "offsets.pyx", line 4453, in pandas._libs.tslibs.offsets._get_offset
ValueError: Invalid frequency: ME

The above exception was the direct cause of the following exception:

Traceback (most recent call last):
  File "c:\Users\joaop\Downloads\Projetos Cursor\FIDCs 2.0\src\data\data_collection.py", line 32, in collect_cvm_data
    df = importa_dados(nome_arquivo_fonte=arquivo, data_inicio=data_inicio)
         ^^^^^^^^^^^^^^^^^^^^^^^^^^^^^^^^^^^^^^^^^^^^^^^^^^^^^^^^^^^^^^^^^^
  File "c:\Users\joaop\Downloads\Projetos Cursor\FIDCs 2.0\src\scraping\cvm_scraper.py", line 63, in importa_dados
    datas_a_baixar = pd.date_range(start=data_inicio, end=data_atual, freq='ME')
                     ^^^^^^^^^^^^^^^^^^^^^^^^^^^^^^^^^^^^^^^^^^^^^^^^^^^^^^^^^^^
  File "C:\Users\joaop\AppData\Local\Packages\PythonSoftwareFoundation.Python.3.12_qbz5n2kfra8p0\LocalCache\local-packages\Python312\site-packages\pandas\core\indexes\datetimes.py", line 1009, in date_range
    dtarr = DatetimeArray._generate_range(
            ^^^^^^^^^^^^^^^^^^^^^^^^^^^^^^
  File "C:\Users\joaop\AppData\Local\Packages\PythonSoftwareFoundation.Python.3.12_qbz5n2kfra8p0\LocalCache\local-packages\Python312\site-packages\pandas\core\arrays\datetimes.py", line 404, in _generate_range
    freq = to_offset(freq)
           ^^^^^^^^^^^^^^^
  File "offsets.pyx", line 4460, in pandas._libs.tslibs.offsets.to_offset
  File "offsets.pyx", line 4557, in pandas._libs.tslibs.offsets.to_offset
ValueError: Invalid frequency: ME
[2025-03-19 23:54:22,305] [ERROR] [data_collection] - Erro na coleta de dados para caracteristicas_fundo
(<class 'ValueError'>, ValueError('Invalid frequency: ME'), <traceback object at 0x0000013A16236580>)
Traceback (most recent call last):
  File "offsets.pyx", line 4447, in pandas._libs.tslibs.offsets._get_offset
KeyError: 'ME'

The above exception was the direct cause of the following exception:

Traceback (most recent call last):
  File "offsets.pyx", line 4549, in pandas._libs.tslibs.offsets.to_offset
  File "offsets.pyx", line 4453, in pandas._libs.tslibs.offsets._get_offset
ValueError: Invalid frequency: ME

The above exception was the direct cause of the following exception:

Traceback (most recent call last):
  File "C:\Users\joaop\Downloads\Projetos Cursor\FIDCs 2.0\src\data\data_collection.py", line 32, in collect_cvm_data
    df = importa_dados(nome_arquivo_fonte=arquivo, data_inicio=data_inicio)
         ^^^^^^^^^^^^^^^^^^^^^^^^^^^^^^^^^^^^^^^^^^^^^^^^^^^^^^^^^^^^^^^^^^
  File "C:\Users\joaop\Downloads\Projetos Cursor\FIDCs 2.0\src\scraping\cvm_scraper.py", line 63, in importa_dados
    datas_a_baixar = pd.date_range(start=data_inicio, end=data_atual, freq='ME')
                     ^^^^^^^^^^^^^^^^^^^^^^^^^^^^^^^^^^^^^^^^^^^^^^^^^^^^^^^^^^^
  File "C:\Users\joaop\AppData\Local\Packages\PythonSoftwareFoundation.Python.3.12_qbz5n2kfra8p0\LocalCache\local-packages\Python312\site-packages\pandas\core\indexes\datetimes.py", line 1009, in date_range
    dtarr = DatetimeArray._generate_range(
            ^^^^^^^^^^^^^^^^^^^^^^^^^^^^^^
  File "C:\Users\joaop\AppData\Local\Packages\PythonSoftwareFoundation.Python.3.12_qbz5n2kfra8p0\LocalCache\local-packages\Python312\site-packages\pandas\core\arrays\datetimes.py", line 404, in _generate_range
    freq = to_offset(freq)
           ^^^^^^^^^^^^^^^
  File "offsets.pyx", line 4460, in pandas._libs.tslibs.offsets.to_offset
  File "offsets.pyx", line 4557, in pandas._libs.tslibs.offsets.to_offset
ValueError: Invalid frequency: ME
[2025-03-19 23:54:22,314] [ERROR] [data_collection] - Erro na coleta de dados para patrimonio_liquido
(<class 'ValueError'>, ValueError('Invalid frequency: ME'), <traceback object at 0x0000013A16285E80>)
Traceback (most recent call last):
  File "offsets.pyx", line 4447, in pandas._libs.tslibs.offsets._get_offset
KeyError: 'ME'

The above exception was the direct cause of the following exception:

Traceback (most recent call last):
  File "offsets.pyx", line 4549, in pandas._libs.tslibs.offsets.to_offset
  File "offsets.pyx", line 4453, in pandas._libs.tslibs.offsets._get_offset
ValueError: Invalid frequency: ME

The above exception was the direct cause of the following exception:

Traceback (most recent call last):
  File "C:\Users\joaop\Downloads\Projetos Cursor\FIDCs 2.0\src\data\data_collection.py", line 32, in collect_cvm_data
    df = importa_dados(nome_arquivo_fonte=arquivo, data_inicio=data_inicio)
         ^^^^^^^^^^^^^^^^^^^^^^^^^^^^^^^^^^^^^^^^^^^^^^^^^^^^^^^^^^^^^^^^^^
  File "C:\Users\joaop\Downloads\Projetos Cursor\FIDCs 2.0\src\scraping\cvm_scraper.py", line 63, in importa_dados
    datas_a_baixar = pd.date_range(start=data_inicio, end=data_atual, freq='ME')
                     ^^^^^^^^^^^^^^^^^^^^^^^^^^^^^^^^^^^^^^^^^^^^^^^^^^^^^^^^^^^
  File "C:\Users\joaop\AppData\Local\Packages\PythonSoftwareFoundation.Python.3.12_qbz5n2kfra8p0\LocalCache\local-packages\Python312\site-packages\pandas\core\indexes\datetimes.py", line 1009, in date_range
    dtarr = DatetimeArray._generate_range(
            ^^^^^^^^^^^^^^^^^^^^^^^^^^^^^^
  File "C:\Users\joaop\AppData\Local\Packages\PythonSoftwareFoundation.Python.3.12_qbz5n2kfra8p0\LocalCache\local-packages\Python312\site-packages\pandas\core\arrays\datetimes.py", line 404, in _generate_range
    freq = to_offset(freq)
           ^^^^^^^^^^^^^^^
  File "offsets.pyx", line 4460, in pandas._libs.tslibs.offsets.to_offset
  File "offsets.pyx", line 4557, in pandas._libs.tslibs.offsets.to_offset
ValueError: Invalid frequency: ME
[2025-03-19 23:54:22,319] [ERROR] [data_collection] - Erro na coleta de dados para carteira_ativos
(<class 'ValueError'>, ValueError('Invalid frequency: ME'), <traceback object at 0x0000013A16285E00>)
Traceback (most recent call last):
  File "offsets.pyx", line 4447, in pandas._libs.tslibs.offsets._get_offset
KeyError: 'ME'

The above exception was the direct cause of the following exception:

Traceback (most recent call last):
  File "offsets.pyx", line 4549, in pandas._libs.tslibs.offsets.to_offset
  File "offsets.pyx", line 4453, in pandas._libs.tslibs.offsets._get_offset
ValueError: Invalid frequency: ME

The above exception was the direct cause of the following exception:

Traceback (most recent call last):
  File "C:\Users\joaop\Downloads\Projetos Cursor\FIDCs 2.0\src\data\data_collection.py", line 32, in collect_cvm_data
    df = importa_dados(nome_arquivo_fonte=arquivo, data_inicio=data_inicio)
         ^^^^^^^^^^^^^^^^^^^^^^^^^^^^^^^^^^^^^^^^^^^^^^^^^^^^^^^^^^^^^^^^^^
  File "C:\Users\joaop\Downloads\Projetos Cursor\FIDCs 2.0\src\scraping\cvm_scraper.py", line 63, in importa_dados
    datas_a_baixar = pd.date_range(start=data_inicio, end=data_atual, freq='ME')
                     ^^^^^^^^^^^^^^^^^^^^^^^^^^^^^^^^^^^^^^^^^^^^^^^^^^^^^^^^^^^
  File "C:\Users\joaop\AppData\Local\Packages\PythonSoftwareFoundation.Python.3.12_qbz5n2kfra8p0\LocalCache\local-packages\Python312\site-packages\pandas\core\indexes\datetimes.py", line 1009, in date_range
    dtarr = DatetimeArray._generate_range(
            ^^^^^^^^^^^^^^^^^^^^^^^^^^^^^^
  File "C:\Users\joaop\AppData\Local\Packages\PythonSoftwareFoundation.Python.3.12_qbz5n2kfra8p0\LocalCache\local-packages\Python312\site-packages\pandas\core\arrays\datetimes.py", line 404, in _generate_range
    freq = to_offset(freq)
           ^^^^^^^^^^^^^^^
  File "offsets.pyx", line 4460, in pandas._libs.tslibs.offsets.to_offset
  File "offsets.pyx", line 4557, in pandas._libs.tslibs.offsets.to_offset
ValueError: Invalid frequency: ME
[2025-03-19 23:54:22,324] [ERROR] [data_collection] - Erro na coleta de dados para passivos_derivativos
(<class 'ValueError'>, ValueError('Invalid frequency: ME'), <traceback object at 0x0000013A16286680>)
Traceback (most recent call last):
  File "offsets.pyx", line 4447, in pandas._libs.tslibs.offsets._get_offset
KeyError: 'ME'

The above exception was the direct cause of the following exception:

Traceback (most recent call last):
  File "offsets.pyx", line 4549, in pandas._libs.tslibs.offsets.to_offset
  File "offsets.pyx", line 4453, in pandas._libs.tslibs.offsets._get_offset
ValueError: Invalid frequency: ME

The above exception was the direct cause of the following exception:

Traceback (most recent call last):
  File "C:\Users\joaop\Downloads\Projetos Cursor\FIDCs 2.0\src\data\data_collection.py", line 32, in collect_cvm_data
    df = importa_dados(nome_arquivo_fonte=arquivo, data_inicio=data_inicio)
         ^^^^^^^^^^^^^^^^^^^^^^^^^^^^^^^^^^^^^^^^^^^^^^^^^^^^^^^^^^^^^^^^^^
  File "C:\Users\joaop\Downloads\Projetos Cursor\FIDCs 2.0\src\scraping\cvm_scraper.py", line 63, in importa_dados
    datas_a_baixar = pd.date_range(start=data_inicio, end=data_atual, freq='ME')
                     ^^^^^^^^^^^^^^^^^^^^^^^^^^^^^^^^^^^^^^^^^^^^^^^^^^^^^^^^^^^
  File "C:\Users\joaop\AppData\Local\Packages\PythonSoftwareFoundation.Python.3.12_qbz5n2kfra8p0\LocalCache\local-packages\Python312\site-packages\pandas\core\indexes\datetimes.py", line 1009, in date_range
    dtarr = DatetimeArray._generate_range(
            ^^^^^^^^^^^^^^^^^^^^^^^^^^^^^^
  File "C:\Users\joaop\AppData\Local\Packages\PythonSoftwareFoundation.Python.3.12_qbz5n2kfra8p0\LocalCache\local-packages\Python312\site-packages\pandas\core\arrays\datetimes.py", line 404, in _generate_range
    freq = to_offset(freq)
           ^^^^^^^^^^^^^^^
  File "offsets.pyx", line 4460, in pandas._libs.tslibs.offsets.to_offset
  File "offsets.pyx", line 4557, in pandas._libs.tslibs.offsets.to_offset
ValueError: Invalid frequency: ME
[2025-03-19 23:54:22,330] [ERROR] [data_collection] - Erro na coleta de dados para prazos_creditos
(<class 'ValueError'>, ValueError('Invalid frequency: ME'), <traceback object at 0x0000013A16286280>)
Traceback (most recent call last):
  File "offsets.pyx", line 4447, in pandas._libs.tslibs.offsets._get_offset
KeyError: 'ME'

The above exception was the direct cause of the following exception:

Traceback (most recent call last):
  File "offsets.pyx", line 4549, in pandas._libs.tslibs.offsets.to_offset
  File "offsets.pyx", line 4453, in pandas._libs.tslibs.offsets._get_offset
ValueError: Invalid frequency: ME

The above exception was the direct cause of the following exception:

Traceback (most recent call last):
  File "C:\Users\joaop\Downloads\Projetos Cursor\FIDCs 2.0\src\data\data_collection.py", line 32, in collect_cvm_data
    df = importa_dados(nome_arquivo_fonte=arquivo, data_inicio=data_inicio)
         ^^^^^^^^^^^^^^^^^^^^^^^^^^^^^^^^^^^^^^^^^^^^^^^^^^^^^^^^^^^^^^^^^^
  File "C:\Users\joaop\Downloads\Projetos Cursor\FIDCs 2.0\src\scraping\cvm_scraper.py", line 63, in importa_dados
    datas_a_baixar = pd.date_range(start=data_inicio, end=data_atual, freq='ME')
                     ^^^^^^^^^^^^^^^^^^^^^^^^^^^^^^^^^^^^^^^^^^^^^^^^^^^^^^^^^^^
  File "C:\Users\joaop\AppData\Local\Packages\PythonSoftwareFoundation.Python.3.12_qbz5n2kfra8p0\LocalCache\local-packages\Python312\site-packages\pandas\core\indexes\datetimes.py", line 1009, in date_range
    dtarr = DatetimeArray._generate_range(
            ^^^^^^^^^^^^^^^^^^^^^^^^^^^^^^
  File "C:\Users\joaop\AppData\Local\Packages\PythonSoftwareFoundation.Python.3.12_qbz5n2kfra8p0\LocalCache\local-packages\Python312\site-packages\pandas\core\arrays\datetimes.py", line 404, in _generate_range
    freq = to_offset(freq)
           ^^^^^^^^^^^^^^^
  File "offsets.pyx", line 4460, in pandas._libs.tslibs.offsets.to_offset
  File "offsets.pyx", line 4557, in pandas._libs.tslibs.offsets.to_offset
ValueError: Invalid frequency: ME
[2025-03-19 23:54:22,334] [ERROR] [data_collection] - Erro na coleta de dados para inadimplencia
(<class 'ValueError'>, ValueError('Invalid frequency: ME'), <traceback object at 0x0000013A16285A80>)
Traceback (most recent call last):
  File "offsets.pyx", line 4447, in pandas._libs.tslibs.offsets._get_offset
KeyError: 'ME'

The above exception was the direct cause of the following exception:

Traceback (most recent call last):
  File "offsets.pyx", line 4549, in pandas._libs.tslibs.offsets.to_offset
  File "offsets.pyx", line 4453, in pandas._libs.tslibs.offsets._get_offset
ValueError: Invalid frequency: ME

The above exception was the direct cause of the following exception:

Traceback (most recent call last):
  File "C:\Users\joaop\Downloads\Projetos Cursor\FIDCs 2.0\src\data\data_collection.py", line 32, in collect_cvm_data
    df = importa_dados(nome_arquivo_fonte=arquivo, data_inicio=data_inicio)
         ^^^^^^^^^^^^^^^^^^^^^^^^^^^^^^^^^^^^^^^^^^^^^^^^^^^^^^^^^^^^^^^^^^
  File "C:\Users\joaop\Downloads\Projetos Cursor\FIDCs 2.0\src\scraping\cvm_scraper.py", line 63, in importa_dados
    datas_a_baixar = pd.date_range(start=data_inicio, end=data_atual, freq='ME')
                     ^^^^^^^^^^^^^^^^^^^^^^^^^^^^^^^^^^^^^^^^^^^^^^^^^^^^^^^^^^^
  File "C:\Users\joaop\AppData\Local\Packages\PythonSoftwareFoundation.Python.3.12_qbz5n2kfra8p0\LocalCache\local-packages\Python312\site-packages\pandas\core\indexes\datetimes.py", line 1009, in date_range
    dtarr = DatetimeArray._generate_range(
            ^^^^^^^^^^^^^^^^^^^^^^^^^^^^^^
  File "C:\Users\joaop\AppData\Local\Packages\PythonSoftwareFoundation.Python.3.12_qbz5n2kfra8p0\LocalCache\local-packages\Python312\site-packages\pandas\core\arrays\datetimes.py", line 404, in _generate_range
    freq = to_offset(freq)
           ^^^^^^^^^^^^^^^
  File "offsets.pyx", line 4460, in pandas._libs.tslibs.offsets.to_offset
  File "offsets.pyx", line 4557, in pandas._libs.tslibs.offsets.to_offset
ValueError: Invalid frequency: ME
[2025-03-19 23:54:22,338] [ERROR] [data_collection] - Erro na coleta de dados para cedentes_tomadores
(<class 'ValueError'>, ValueError('Invalid frequency: ME'), <traceback object at 0x0000013A162863C0>)
Traceback (most recent call last):
  File "offsets.pyx", line 4447, in pandas._libs.tslibs.offsets._get_offset
KeyError: 'ME'

The above exception was the direct cause of the following exception:

Traceback (most recent call last):
  File "offsets.pyx", line 4549, in pandas._libs.tslibs.offsets.to_offset
  File "offsets.pyx", line 4453, in pandas._libs.tslibs.offsets._get_offset
ValueError: Invalid frequency: ME

The above exception was the direct cause of the following exception:

Traceback (most recent call last):
  File "C:\Users\joaop\Downloads\Projetos Cursor\FIDCs 2.0\src\data\data_collection.py", line 32, in collect_cvm_data
    df = importa_dados(nome_arquivo_fonte=arquivo, data_inicio=data_inicio)
         ^^^^^^^^^^^^^^^^^^^^^^^^^^^^^^^^^^^^^^^^^^^^^^^^^^^^^^^^^^^^^^^^^^
  File "C:\Users\joaop\Downloads\Projetos Cursor\FIDCs 2.0\src\scraping\cvm_scraper.py", line 63, in importa_dados
    datas_a_baixar = pd.date_range(start=data_inicio, end=data_atual, freq='ME')
                     ^^^^^^^^^^^^^^^^^^^^^^^^^^^^^^^^^^^^^^^^^^^^^^^^^^^^^^^^^^^
  File "C:\Users\joaop\AppData\Local\Packages\PythonSoftwareFoundation.Python.3.12_qbz5n2kfra8p0\LocalCache\local-packages\Python312\site-packages\pandas\core\indexes\datetimes.py", line 1009, in date_range
    dtarr = DatetimeArray._generate_range(
            ^^^^^^^^^^^^^^^^^^^^^^^^^^^^^^
  File "C:\Users\joaop\AppData\Local\Packages\PythonSoftwareFoundation.Python.3.12_qbz5n2kfra8p0\LocalCache\local-packages\Python312\site-packages\pandas\core\arrays\datetimes.py", line 404, in _generate_range
    freq = to_offset(freq)
           ^^^^^^^^^^^^^^^
  File "offsets.pyx", line 4460, in pandas._libs.tslibs.offsets.to_offset
  File "offsets.pyx", line 4557, in pandas._libs.tslibs.offsets.to_offset
ValueError: Invalid frequency: ME
[2025-03-19 23:54:22,344] [ERROR] [data_collection] - Erro na coleta de dados para precos_mercado
(<class 'ValueError'>, ValueError('Invalid frequency: ME'), <traceback object at 0x0000013A16286A80>)
Traceback (most recent call last):
  File "offsets.pyx", line 4447, in pandas._libs.tslibs.offsets._get_offset
KeyError: 'ME'

The above exception was the direct cause of the following exception:

Traceback (most recent call last):
  File "offsets.pyx", line 4549, in pandas._libs.tslibs.offsets.to_offset
  File "offsets.pyx", line 4453, in pandas._libs.tslibs.offsets._get_offset
ValueError: Invalid frequency: ME

The above exception was the direct cause of the following exception:

Traceback (most recent call last):
  File "C:\Users\joaop\Downloads\Projetos Cursor\FIDCs 2.0\src\data\data_collection.py", line 32, in collect_cvm_data
    df = importa_dados(nome_arquivo_fonte=arquivo, data_inicio=data_inicio)
         ^^^^^^^^^^^^^^^^^^^^^^^^^^^^^^^^^^^^^^^^^^^^^^^^^^^^^^^^^^^^^^^^^^
  File "C:\Users\joaop\Downloads\Projetos Cursor\FIDCs 2.0\src\scraping\cvm_scraper.py", line 63, in importa_dados
    datas_a_baixar = pd.date_range(start=data_inicio, end=data_atual, freq='ME')
                     ^^^^^^^^^^^^^^^^^^^^^^^^^^^^^^^^^^^^^^^^^^^^^^^^^^^^^^^^^^^
  File "C:\Users\joaop\AppData\Local\Packages\PythonSoftwareFoundation.Python.3.12_qbz5n2kfra8p0\LocalCache\local-packages\Python312\site-packages\pandas\core\indexes\datetimes.py", line 1009, in date_range
    dtarr = DatetimeArray._generate_range(
            ^^^^^^^^^^^^^^^^^^^^^^^^^^^^^^
  File "C:\Users\joaop\AppData\Local\Packages\PythonSoftwareFoundation.Python.3.12_qbz5n2kfra8p0\LocalCache\local-packages\Python312\site-packages\pandas\core\arrays\datetimes.py", line 404, in _generate_range
    freq = to_offset(freq)
           ^^^^^^^^^^^^^^^
  File "offsets.pyx", line 4460, in pandas._libs.tslibs.offsets.to_offset
  File "offsets.pyx", line 4557, in pandas._libs.tslibs.offsets.to_offset
ValueError: Invalid frequency: ME
[2025-03-19 23:54:22,348] [ERROR] [data_collection] - Erro na coleta de dados para risco_credito
(<class 'ValueError'>, ValueError('Invalid frequency: ME'), <traceback object at 0x0000013A16286300>)
Traceback (most recent call last):
  File "offsets.pyx", line 4447, in pandas._libs.tslibs.offsets._get_offset
KeyError: 'ME'

The above exception was the direct cause of the following exception:

Traceback (most recent call last):
  File "offsets.pyx", line 4549, in pandas._libs.tslibs.offsets.to_offset
  File "offsets.pyx", line 4453, in pandas._libs.tslibs.offsets._get_offset
ValueError: Invalid frequency: ME

The above exception was the direct cause of the following exception:

Traceback (most recent call last):
  File "C:\Users\joaop\Downloads\Projetos Cursor\FIDCs 2.0\src\data\data_collection.py", line 32, in collect_cvm_data
    df = importa_dados(nome_arquivo_fonte=arquivo, data_inicio=data_inicio)
         ^^^^^^^^^^^^^^^^^^^^^^^^^^^^^^^^^^^^^^^^^^^^^^^^^^^^^^^^^^^^^^^^^^
  File "C:\Users\joaop\Downloads\Projetos Cursor\FIDCs 2.0\src\scraping\cvm_scraper.py", line 63, in importa_dados
    datas_a_baixar = pd.date_range(start=data_inicio, end=data_atual, freq='ME')
                     ^^^^^^^^^^^^^^^^^^^^^^^^^^^^^^^^^^^^^^^^^^^^^^^^^^^^^^^^^^^
  File "C:\Users\joaop\AppData\Local\Packages\PythonSoftwareFoundation.Python.3.12_qbz5n2kfra8p0\LocalCache\local-packages\Python312\site-packages\pandas\core\indexes\datetimes.py", line 1009, in date_range
    dtarr = DatetimeArray._generate_range(
            ^^^^^^^^^^^^^^^^^^^^^^^^^^^^^^
  File "C:\Users\joaop\AppData\Local\Packages\PythonSoftwareFoundation.Python.3.12_qbz5n2kfra8p0\LocalCache\local-packages\Python312\site-packages\pandas\core\arrays\datetimes.py", line 404, in _generate_range
    freq = to_offset(freq)
           ^^^^^^^^^^^^^^^
  File "offsets.pyx", line 4460, in pandas._libs.tslibs.offsets.to_offset
  File "offsets.pyx", line 4557, in pandas._libs.tslibs.offsets.to_offset
ValueError: Invalid frequency: ME
[2025-03-19 23:54:22,355] [ERROR] [data_collection] - Erro na coleta de dados para classes_cotistas
(<class 'ValueError'>, ValueError('Invalid frequency: ME'), <traceback object at 0x0000013A162866C0>)
Traceback (most recent call last):
  File "offsets.pyx", line 4447, in pandas._libs.tslibs.offsets._get_offset
KeyError: 'ME'

The above exception was the direct cause of the following exception:

Traceback (most recent call last):
  File "offsets.pyx", line 4549, in pandas._libs.tslibs.offsets.to_offset
  File "offsets.pyx", line 4453, in pandas._libs.tslibs.offsets._get_offset
ValueError: Invalid frequency: ME

The above exception was the direct cause of the following exception:

Traceback (most recent call last):
  File "C:\Users\joaop\Downloads\Projetos Cursor\FIDCs 2.0\src\data\data_collection.py", line 32, in collect_cvm_data
    df = importa_dados(nome_arquivo_fonte=arquivo, data_inicio=data_inicio)
         ^^^^^^^^^^^^^^^^^^^^^^^^^^^^^^^^^^^^^^^^^^^^^^^^^^^^^^^^^^^^^^^^^^
  File "C:\Users\joaop\Downloads\Projetos Cursor\FIDCs 2.0\src\scraping\cvm_scraper.py", line 63, in importa_dados
    datas_a_baixar = pd.date_range(start=data_inicio, end=data_atual, freq='ME')
                     ^^^^^^^^^^^^^^^^^^^^^^^^^^^^^^^^^^^^^^^^^^^^^^^^^^^^^^^^^^^
  File "C:\Users\joaop\AppData\Local\Packages\PythonSoftwareFoundation.Python.3.12_qbz5n2kfra8p0\LocalCache\local-packages\Python312\site-packages\pandas\core\indexes\datetimes.py", line 1009, in date_range
    dtarr = DatetimeArray._generate_range(
            ^^^^^^^^^^^^^^^^^^^^^^^^^^^^^^
  File "C:\Users\joaop\AppData\Local\Packages\PythonSoftwareFoundation.Python.3.12_qbz5n2kfra8p0\LocalCache\local-packages\Python312\site-packages\pandas\core\arrays\datetimes.py", line 404, in _generate_range
    freq = to_offset(freq)
           ^^^^^^^^^^^^^^^
  File "offsets.pyx", line 4460, in pandas._libs.tslibs.offsets.to_offset
  File "offsets.pyx", line 4557, in pandas._libs.tslibs.offsets.to_offset
ValueError: Invalid frequency: ME
[2025-03-19 23:54:22,360] [ERROR] [data_collection] - Erro na coleta de dados para distribuicao_cotistas
(<class 'ValueError'>, ValueError('Invalid frequency: ME'), <traceback object at 0x0000013A16286480>)
Traceback (most recent call last):
  File "offsets.pyx", line 4447, in pandas._libs.tslibs.offsets._get_offset
KeyError: 'ME'

The above exception was the direct cause of the following exception:

Traceback (most recent call last):
  File "offsets.pyx", line 4549, in pandas._libs.tslibs.offsets.to_offset
  File "offsets.pyx", line 4453, in pandas._libs.tslibs.offsets._get_offset
ValueError: Invalid frequency: ME

The above exception was the direct cause of the following exception:

Traceback (most recent call last):
  File "C:\Users\joaop\Downloads\Projetos Cursor\FIDCs 2.0\src\data\data_collection.py", line 32, in collect_cvm_data
    df = importa_dados(nome_arquivo_fonte=arquivo, data_inicio=data_inicio)
         ^^^^^^^^^^^^^^^^^^^^^^^^^^^^^^^^^^^^^^^^^^^^^^^^^^^^^^^^^^^^^^^^^^
  File "C:\Users\joaop\Downloads\Projetos Cursor\FIDCs 2.0\src\scraping\cvm_scraper.py", line 63, in importa_dados
    datas_a_baixar = pd.date_range(start=data_inicio, end=data_atual, freq='ME')
                     ^^^^^^^^^^^^^^^^^^^^^^^^^^^^^^^^^^^^^^^^^^^^^^^^^^^^^^^^^^^
  File "C:\Users\joaop\AppData\Local\Packages\PythonSoftwareFoundation.Python.3.12_qbz5n2kfra8p0\LocalCache\local-packages\Python312\site-packages\pandas\core\indexes\datetimes.py", line 1009, in date_range
    dtarr = DatetimeArray._generate_range(
            ^^^^^^^^^^^^^^^^^^^^^^^^^^^^^^
  File "C:\Users\joaop\AppData\Local\Packages\PythonSoftwareFoundation.Python.3.12_qbz5n2kfra8p0\LocalCache\local-packages\Python312\site-packages\pandas\core\arrays\datetimes.py", line 404, in _generate_range
    freq = to_offset(freq)
           ^^^^^^^^^^^^^^^
  File "offsets.pyx", line 4460, in pandas._libs.tslibs.offsets.to_offset
  File "offsets.pyx", line 4557, in pandas._libs.tslibs.offsets.to_offset
ValueError: Invalid frequency: ME
[2025-03-19 23:54:22,366] [ERROR] [data_collection] - Erro na coleta de dados para cotas_valores
(<class 'ValueError'>, ValueError('Invalid frequency: ME'), <traceback object at 0x0000013A16286400>)
Traceback (most recent call last):
  File "offsets.pyx", line 4447, in pandas._libs.tslibs.offsets._get_offset
KeyError: 'ME'

The above exception was the direct cause of the following exception:

Traceback (most recent call last):
  File "offsets.pyx", line 4549, in pandas._libs.tslibs.offsets.to_offset
  File "offsets.pyx", line 4453, in pandas._libs.tslibs.offsets._get_offset
ValueError: Invalid frequency: ME

The above exception was the direct cause of the following exception:

Traceback (most recent call last):
  File "C:\Users\joaop\Downloads\Projetos Cursor\FIDCs 2.0\src\data\data_collection.py", line 32, in collect_cvm_data
    df = importa_dados(nome_arquivo_fonte=arquivo, data_inicio=data_inicio)
         ^^^^^^^^^^^^^^^^^^^^^^^^^^^^^^^^^^^^^^^^^^^^^^^^^^^^^^^^^^^^^^^^^^
  File "C:\Users\joaop\Downloads\Projetos Cursor\FIDCs 2.0\src\scraping\cvm_scraper.py", line 63, in importa_dados
    datas_a_baixar = pd.date_range(start=data_inicio, end=data_atual, freq='ME')
                     ^^^^^^^^^^^^^^^^^^^^^^^^^^^^^^^^^^^^^^^^^^^^^^^^^^^^^^^^^^^
  File "C:\Users\joaop\AppData\Local\Packages\PythonSoftwareFoundation.Python.3.12_qbz5n2kfra8p0\LocalCache\local-packages\Python312\site-packages\pandas\core\indexes\datetimes.py", line 1009, in date_range
    dtarr = DatetimeArray._generate_range(
            ^^^^^^^^^^^^^^^^^^^^^^^^^^^^^^
  File "C:\Users\joaop\AppData\Local\Packages\PythonSoftwareFoundation.Python.3.12_qbz5n2kfra8p0\LocalCache\local-packages\Python312\site-packages\pandas\core\arrays\datetimes.py", line 404, in _generate_range
    freq = to_offset(freq)
           ^^^^^^^^^^^^^^^
  File "offsets.pyx", line 4460, in pandas._libs.tslibs.offsets.to_offset
  File "offsets.pyx", line 4557, in pandas._libs.tslibs.offsets.to_offset
ValueError: Invalid frequency: ME
[2025-03-19 23:54:22,373] [ERROR] [data_collection] - Erro na coleta de dados para rentabilidade
(<class 'ValueError'>, ValueError('Invalid frequency: ME'), <traceback object at 0x0000013A16286680>)
Traceback (most recent call last):
  File "offsets.pyx", line 4447, in pandas._libs.tslibs.offsets._get_offset
KeyError: 'ME'

The above exception was the direct cause of the following exception:

Traceback (most recent call last):
  File "offsets.pyx", line 4549, in pandas._libs.tslibs.offsets.to_offset
  File "offsets.pyx", line 4453, in pandas._libs.tslibs.offsets._get_offset
ValueError: Invalid frequency: ME

The above exception was the direct cause of the following exception:

Traceback (most recent call last):
  File "C:\Users\joaop\Downloads\Projetos Cursor\FIDCs 2.0\src\data\data_collection.py", line 32, in collect_cvm_data
    df = importa_dados(nome_arquivo_fonte=arquivo, data_inicio=data_inicio)
         ^^^^^^^^^^^^^^^^^^^^^^^^^^^^^^^^^^^^^^^^^^^^^^^^^^^^^^^^^^^^^^^^^^
  File "C:\Users\joaop\Downloads\Projetos Cursor\FIDCs 2.0\src\scraping\cvm_scraper.py", line 63, in importa_dados
    datas_a_baixar = pd.date_range(start=data_inicio, end=data_atual, freq='ME')
                     ^^^^^^^^^^^^^^^^^^^^^^^^^^^^^^^^^^^^^^^^^^^^^^^^^^^^^^^^^^^
  File "C:\Users\joaop\AppData\Local\Packages\PythonSoftwareFoundation.Python.3.12_qbz5n2kfra8p0\LocalCache\local-packages\Python312\site-packages\pandas\core\indexes\datetimes.py", line 1009, in date_range
    dtarr = DatetimeArray._generate_range(
            ^^^^^^^^^^^^^^^^^^^^^^^^^^^^^^
  File "C:\Users\joaop\AppData\Local\Packages\PythonSoftwareFoundation.Python.3.12_qbz5n2kfra8p0\LocalCache\local-packages\Python312\site-packages\pandas\core\arrays\datetimes.py", line 404, in _generate_range
    freq = to_offset(freq)
           ^^^^^^^^^^^^^^^
  File "offsets.pyx", line 4460, in pandas._libs.tslibs.offsets.to_offset
  File "offsets.pyx", line 4557, in pandas._libs.tslibs.offsets.to_offset
ValueError: Invalid frequency: ME
[2025-03-19 23:54:22,379] [ERROR] [data_collection] - Erro na coleta de dados para operacoes_estruturadas
(<class 'ValueError'>, ValueError('Invalid frequency: ME'), <traceback object at 0x0000013A16287000>)
Traceback (most recent call last):
  File "offsets.pyx", line 4447, in pandas._libs.tslibs.offsets._get_offset
KeyError: 'ME'

The above exception was the direct cause of the following exception:

Traceback (most recent call last):
  File "offsets.pyx", line 4549, in pandas._libs.tslibs.offsets.to_offset
  File "offsets.pyx", line 4453, in pandas._libs.tslibs.offsets._get_offset
ValueError: Invalid frequency: ME

The above exception was the direct cause of the following exception:

Traceback (most recent call last):
  File "C:\Users\joaop\Downloads\Projetos Cursor\FIDCs 2.0\src\data\data_collection.py", line 32, in collect_cvm_data
    df = importa_dados(nome_arquivo_fonte=arquivo, data_inicio=data_inicio)
         ^^^^^^^^^^^^^^^^^^^^^^^^^^^^^^^^^^^^^^^^^^^^^^^^^^^^^^^^^^^^^^^^^^
  File "C:\Users\joaop\Downloads\Projetos Cursor\FIDCs 2.0\src\scraping\cvm_scraper.py", line 63, in importa_dados
    datas_a_baixar = pd.date_range(start=data_inicio, end=data_atual, freq='ME')
                     ^^^^^^^^^^^^^^^^^^^^^^^^^^^^^^^^^^^^^^^^^^^^^^^^^^^^^^^^^^^
  File "C:\Users\joaop\AppData\Local\Packages\PythonSoftwareFoundation.Python.3.12_qbz5n2kfra8p0\LocalCache\local-packages\Python312\site-packages\pandas\core\indexes\datetimes.py", line 1009, in date_range
    dtarr = DatetimeArray._generate_range(
            ^^^^^^^^^^^^^^^^^^^^^^^^^^^^^^
  File "C:\Users\joaop\AppData\Local\Packages\PythonSoftwareFoundation.Python.3.12_qbz5n2kfra8p0\LocalCache\local-packages\Python312\site-packages\pandas\core\arrays\datetimes.py", line 404, in _generate_range
    freq = to_offset(freq)
           ^^^^^^^^^^^^^^^
  File "offsets.pyx", line 4460, in pandas._libs.tslibs.offsets.to_offset
  File "offsets.pyx", line 4557, in pandas._libs.tslibs.offsets.to_offset
ValueError: Invalid frequency: ME
[2025-03-19 23:54:22,385] [ERROR] [data_collection] - Erro na coleta de dados para liquidez_ativos
(<class 'ValueError'>, ValueError('Invalid frequency: ME'), <traceback object at 0x0000013A16286D00>)
Traceback (most recent call last):
  File "offsets.pyx", line 4447, in pandas._libs.tslibs.offsets._get_offset
KeyError: 'ME'

The above exception was the direct cause of the following exception:

Traceback (most recent call last):
  File "offsets.pyx", line 4549, in pandas._libs.tslibs.offsets.to_offset
  File "offsets.pyx", line 4453, in pandas._libs.tslibs.offsets._get_offset
ValueError: Invalid frequency: ME

The above exception was the direct cause of the following exception:

Traceback (most recent call last):
  File "C:\Users\joaop\Downloads\Projetos Cursor\FIDCs 2.0\src\data\data_collection.py", line 32, in collect_cvm_data
    df = importa_dados(nome_arquivo_fonte=arquivo, data_inicio=data_inicio)
         ^^^^^^^^^^^^^^^^^^^^^^^^^^^^^^^^^^^^^^^^^^^^^^^^^^^^^^^^^^^^^^^^^^
  File "C:\Users\joaop\Downloads\Projetos Cursor\FIDCs 2.0\src\scraping\cvm_scraper.py", line 63, in importa_dados
    datas_a_baixar = pd.date_range(start=data_inicio, end=data_atual, freq='ME')
                     ^^^^^^^^^^^^^^^^^^^^^^^^^^^^^^^^^^^^^^^^^^^^^^^^^^^^^^^^^^^
  File "C:\Users\joaop\AppData\Local\Packages\PythonSoftwareFoundation.Python.3.12_qbz5n2kfra8p0\LocalCache\local-packages\Python312\site-packages\pandas\core\indexes\datetimes.py", line 1009, in date_range
    dtarr = DatetimeArray._generate_range(
            ^^^^^^^^^^^^^^^^^^^^^^^^^^^^^^
  File "C:\Users\joaop\AppData\Local\Packages\PythonSoftwareFoundation.Python.3.12_qbz5n2kfra8p0\LocalCache\local-packages\Python312\site-packages\pandas\core\arrays\datetimes.py", line 404, in _generate_range
    freq = to_offset(freq)
           ^^^^^^^^^^^^^^^
  File "offsets.pyx", line 4460, in pandas._libs.tslibs.offsets.to_offset
  File "offsets.pyx", line 4557, in pandas._libs.tslibs.offsets.to_offset
ValueError: Invalid frequency: ME
[2025-03-19 23:54:22,391] [ERROR] [data_collection] - Erro na coleta de dados para performance_fundo
(<class 'ValueError'>, ValueError('Invalid frequency: ME'), <traceback object at 0x0000013A16287100>)
Traceback (most recent call last):
  File "offsets.pyx", line 4447, in pandas._libs.tslibs.offsets._get_offset
KeyError: 'ME'

The above exception was the direct cause of the following exception:

Traceback (most recent call last):
  File "offsets.pyx", line 4549, in pandas._libs.tslibs.offsets.to_offset
  File "offsets.pyx", line 4453, in pandas._libs.tslibs.offsets._get_offset
ValueError: Invalid frequency: ME

The above exception was the direct cause of the following exception:

Traceback (most recent call last):
  File "C:\Users\joaop\Downloads\Projetos Cursor\FIDCs 2.0\src\data\data_collection.py", line 32, in collect_cvm_data
    df = importa_dados(nome_arquivo_fonte=arquivo, data_inicio=data_inicio)
         ^^^^^^^^^^^^^^^^^^^^^^^^^^^^^^^^^^^^^^^^^^^^^^^^^^^^^^^^^^^^^^^^^^
  File "C:\Users\joaop\Downloads\Projetos Cursor\FIDCs 2.0\src\scraping\cvm_scraper.py", line 63, in importa_dados
    datas_a_baixar = pd.date_range(start=data_inicio, end=data_atual, freq='ME')
                     ^^^^^^^^^^^^^^^^^^^^^^^^^^^^^^^^^^^^^^^^^^^^^^^^^^^^^^^^^^^
  File "C:\Users\joaop\AppData\Local\Packages\PythonSoftwareFoundation.Python.3.12_qbz5n2kfra8p0\LocalCache\local-packages\Python312\site-packages\pandas\core\indexes\datetimes.py", line 1009, in date_range
    dtarr = DatetimeArray._generate_range(
            ^^^^^^^^^^^^^^^^^^^^^^^^^^^^^^
  File "C:\Users\joaop\AppData\Local\Packages\PythonSoftwareFoundation.Python.3.12_qbz5n2kfra8p0\LocalCache\local-packages\Python312\site-packages\pandas\core\arrays\datetimes.py", line 404, in _generate_range
    freq = to_offset(freq)
           ^^^^^^^^^^^^^^^
  File "offsets.pyx", line 4460, in pandas._libs.tslibs.offsets.to_offset
  File "offsets.pyx", line 4557, in pandas._libs.tslibs.offsets.to_offset
ValueError: Invalid frequency: ME
[2025-03-19 23:54:22,397] [ERROR] [data_collection] - Erro na coleta de dados para garantias_seguros
(<class 'ValueError'>, ValueError('Invalid frequency: ME'), <traceback object at 0x0000013A16285B00>)
Traceback (most recent call last):
  File "offsets.pyx", line 4447, in pandas._libs.tslibs.offsets._get_offset
KeyError: 'ME'

The above exception was the direct cause of the following exception:

Traceback (most recent call last):
  File "offsets.pyx", line 4549, in pandas._libs.tslibs.offsets.to_offset
  File "offsets.pyx", line 4453, in pandas._libs.tslibs.offsets._get_offset
ValueError: Invalid frequency: ME

The above exception was the direct cause of the following exception:

Traceback (most recent call last):
  File "C:\Users\joaop\Downloads\Projetos Cursor\FIDCs 2.0\src\data\data_collection.py", line 32, in collect_cvm_data
    df = importa_dados(nome_arquivo_fonte=arquivo, data_inicio=data_inicio)
         ^^^^^^^^^^^^^^^^^^^^^^^^^^^^^^^^^^^^^^^^^^^^^^^^^^^^^^^^^^^^^^^^^^
  File "C:\Users\joaop\Downloads\Projetos Cursor\FIDCs 2.0\src\scraping\cvm_scraper.py", line 63, in importa_dados
    datas_a_baixar = pd.date_range(start=data_inicio, end=data_atual, freq='ME')
                     ^^^^^^^^^^^^^^^^^^^^^^^^^^^^^^^^^^^^^^^^^^^^^^^^^^^^^^^^^^^
  File "C:\Users\joaop\AppData\Local\Packages\PythonSoftwareFoundation.Python.3.12_qbz5n2kfra8p0\LocalCache\local-packages\Python312\site-packages\pandas\core\indexes\datetimes.py", line 1009, in date_range
    dtarr = DatetimeArray._generate_range(
            ^^^^^^^^^^^^^^^^^^^^^^^^^^^^^^
  File "C:\Users\joaop\AppData\Local\Packages\PythonSoftwareFoundation.Python.3.12_qbz5n2kfra8p0\LocalCache\local-packages\Python312\site-packages\pandas\core\arrays\datetimes.py", line 404, in _generate_range
    freq = to_offset(freq)
           ^^^^^^^^^^^^^^^
  File "offsets.pyx", line 4460, in pandas._libs.tslibs.offsets.to_offset
  File "offsets.pyx", line 4557, in pandas._libs.tslibs.offsets.to_offset
ValueError: Invalid frequency: ME
[2025-03-19 23:57:18,989] [ERROR] [data_collection] - Erro na coleta de dados para caracteristicas_fundo
(<class 'ValueError'>, ValueError('Invalid frequency: ME'), <traceback object at 0x0000020B072CE240>)
Traceback (most recent call last):
  File "offsets.pyx", line 4447, in pandas._libs.tslibs.offsets._get_offset
KeyError: 'ME'

The above exception was the direct cause of the following exception:

Traceback (most recent call last):
  File "offsets.pyx", line 4549, in pandas._libs.tslibs.offsets.to_offset
  File "offsets.pyx", line 4453, in pandas._libs.tslibs.offsets._get_offset
ValueError: Invalid frequency: ME

The above exception was the direct cause of the following exception:

Traceback (most recent call last):
  File "c:\Users\joaop\Downloads\Projetos Cursor\FIDCs 2.0\src\data\data_collection.py", line 32, in collect_cvm_data
    df = importa_dados(nome_arquivo_fonte=arquivo, data_inicio=data_inicio)
         ^^^^^^^^^^^^^^^^^^^^^^^^^^^^^^^^^^^^^^^^^^^^^^^^^^^^^^^^^^^^^^^^^^
  File "c:\Users\joaop\Downloads\Projetos Cursor\FIDCs 2.0\src\scraping\cvm_scraper.py", line 63, in importa_dados
    datas_a_baixar = pd.date_range(start=data_inicio, end=data_atual, freq='ME')
                     ^^^^^^^^^^^^^^^^^^^^^^^^^^^^^^^^^^^^^^^^^^^^^^^^^^^^^^^^^^^
  File "C:\Users\joaop\AppData\Local\Packages\PythonSoftwareFoundation.Python.3.12_qbz5n2kfra8p0\LocalCache\local-packages\Python312\site-packages\pandas\core\indexes\datetimes.py", line 1009, in date_range
    dtarr = DatetimeArray._generate_range(
            ^^^^^^^^^^^^^^^^^^^^^^^^^^^^^^
  File "C:\Users\joaop\AppData\Local\Packages\PythonSoftwareFoundation.Python.3.12_qbz5n2kfra8p0\LocalCache\local-packages\Python312\site-packages\pandas\core\arrays\datetimes.py", line 404, in _generate_range
    freq = to_offset(freq)
           ^^^^^^^^^^^^^^^
  File "offsets.pyx", line 4460, in pandas._libs.tslibs.offsets.to_offset
  File "offsets.pyx", line 4557, in pandas._libs.tslibs.offsets.to_offset
ValueError: Invalid frequency: ME
[2025-03-19 23:57:18,993] [ERROR] [data_collection] - Erro na coleta de dados para patrimonio_liquido
(<class 'ValueError'>, ValueError('Invalid frequency: ME'), <traceback object at 0x0000020B072CE400>)
Traceback (most recent call last):
  File "offsets.pyx", line 4447, in pandas._libs.tslibs.offsets._get_offset
KeyError: 'ME'

The above exception was the direct cause of the following exception:

Traceback (most recent call last):
  File "offsets.pyx", line 4549, in pandas._libs.tslibs.offsets.to_offset
  File "offsets.pyx", line 4453, in pandas._libs.tslibs.offsets._get_offset
ValueError: Invalid frequency: ME

The above exception was the direct cause of the following exception:

Traceback (most recent call last):
  File "c:\Users\joaop\Downloads\Projetos Cursor\FIDCs 2.0\src\data\data_collection.py", line 32, in collect_cvm_data
    df = importa_dados(nome_arquivo_fonte=arquivo, data_inicio=data_inicio)
         ^^^^^^^^^^^^^^^^^^^^^^^^^^^^^^^^^^^^^^^^^^^^^^^^^^^^^^^^^^^^^^^^^^
  File "c:\Users\joaop\Downloads\Projetos Cursor\FIDCs 2.0\src\scraping\cvm_scraper.py", line 63, in importa_dados
    datas_a_baixar = pd.date_range(start=data_inicio, end=data_atual, freq='ME')
                     ^^^^^^^^^^^^^^^^^^^^^^^^^^^^^^^^^^^^^^^^^^^^^^^^^^^^^^^^^^^
  File "C:\Users\joaop\AppData\Local\Packages\PythonSoftwareFoundation.Python.3.12_qbz5n2kfra8p0\LocalCache\local-packages\Python312\site-packages\pandas\core\indexes\datetimes.py", line 1009, in date_range
    dtarr = DatetimeArray._generate_range(
            ^^^^^^^^^^^^^^^^^^^^^^^^^^^^^^
  File "C:\Users\joaop\AppData\Local\Packages\PythonSoftwareFoundation.Python.3.12_qbz5n2kfra8p0\LocalCache\local-packages\Python312\site-packages\pandas\core\arrays\datetimes.py", line 404, in _generate_range
    freq = to_offset(freq)
           ^^^^^^^^^^^^^^^
  File "offsets.pyx", line 4460, in pandas._libs.tslibs.offsets.to_offset
  File "offsets.pyx", line 4557, in pandas._libs.tslibs.offsets.to_offset
ValueError: Invalid frequency: ME
[2025-03-19 23:57:18,996] [ERROR] [data_collection] - Erro na coleta de dados para carteira_ativos
(<class 'ValueError'>, ValueError('Invalid frequency: ME'), <traceback object at 0x0000020B07328040>)
Traceback (most recent call last):
  File "offsets.pyx", line 4447, in pandas._libs.tslibs.offsets._get_offset
KeyError: 'ME'

The above exception was the direct cause of the following exception:

Traceback (most recent call last):
  File "offsets.pyx", line 4549, in pandas._libs.tslibs.offsets.to_offset
  File "offsets.pyx", line 4453, in pandas._libs.tslibs.offsets._get_offset
ValueError: Invalid frequency: ME

The above exception was the direct cause of the following exception:

Traceback (most recent call last):
  File "c:\Users\joaop\Downloads\Projetos Cursor\FIDCs 2.0\src\data\data_collection.py", line 32, in collect_cvm_data
    df = importa_dados(nome_arquivo_fonte=arquivo, data_inicio=data_inicio)
         ^^^^^^^^^^^^^^^^^^^^^^^^^^^^^^^^^^^^^^^^^^^^^^^^^^^^^^^^^^^^^^^^^^
  File "c:\Users\joaop\Downloads\Projetos Cursor\FIDCs 2.0\src\scraping\cvm_scraper.py", line 63, in importa_dados
    datas_a_baixar = pd.date_range(start=data_inicio, end=data_atual, freq='ME')
                     ^^^^^^^^^^^^^^^^^^^^^^^^^^^^^^^^^^^^^^^^^^^^^^^^^^^^^^^^^^^
  File "C:\Users\joaop\AppData\Local\Packages\PythonSoftwareFoundation.Python.3.12_qbz5n2kfra8p0\LocalCache\local-packages\Python312\site-packages\pandas\core\indexes\datetimes.py", line 1009, in date_range
    dtarr = DatetimeArray._generate_range(
            ^^^^^^^^^^^^^^^^^^^^^^^^^^^^^^
  File "C:\Users\joaop\AppData\Local\Packages\PythonSoftwareFoundation.Python.3.12_qbz5n2kfra8p0\LocalCache\local-packages\Python312\site-packages\pandas\core\arrays\datetimes.py", line 404, in _generate_range
    freq = to_offset(freq)
           ^^^^^^^^^^^^^^^
  File "offsets.pyx", line 4460, in pandas._libs.tslibs.offsets.to_offset
  File "offsets.pyx", line 4557, in pandas._libs.tslibs.offsets.to_offset
ValueError: Invalid frequency: ME
[2025-03-19 23:57:18,998] [ERROR] [data_collection] - Erro na coleta de dados para passivos_derivativos
(<class 'ValueError'>, ValueError('Invalid frequency: ME'), <traceback object at 0x0000020B07328D00>)
Traceback (most recent call last):
  File "offsets.pyx", line 4447, in pandas._libs.tslibs.offsets._get_offset
KeyError: 'ME'

The above exception was the direct cause of the following exception:

Traceback (most recent call last):
  File "offsets.pyx", line 4549, in pandas._libs.tslibs.offsets.to_offset
  File "offsets.pyx", line 4453, in pandas._libs.tslibs.offsets._get_offset
ValueError: Invalid frequency: ME

The above exception was the direct cause of the following exception:

Traceback (most recent call last):
  File "c:\Users\joaop\Downloads\Projetos Cursor\FIDCs 2.0\src\data\data_collection.py", line 32, in collect_cvm_data
    df = importa_dados(nome_arquivo_fonte=arquivo, data_inicio=data_inicio)
         ^^^^^^^^^^^^^^^^^^^^^^^^^^^^^^^^^^^^^^^^^^^^^^^^^^^^^^^^^^^^^^^^^^
  File "c:\Users\joaop\Downloads\Projetos Cursor\FIDCs 2.0\src\scraping\cvm_scraper.py", line 63, in importa_dados
    datas_a_baixar = pd.date_range(start=data_inicio, end=data_atual, freq='ME')
                     ^^^^^^^^^^^^^^^^^^^^^^^^^^^^^^^^^^^^^^^^^^^^^^^^^^^^^^^^^^^
  File "C:\Users\joaop\AppData\Local\Packages\PythonSoftwareFoundation.Python.3.12_qbz5n2kfra8p0\LocalCache\local-packages\Python312\site-packages\pandas\core\indexes\datetimes.py", line 1009, in date_range
    dtarr = DatetimeArray._generate_range(
            ^^^^^^^^^^^^^^^^^^^^^^^^^^^^^^
  File "C:\Users\joaop\AppData\Local\Packages\PythonSoftwareFoundation.Python.3.12_qbz5n2kfra8p0\LocalCache\local-packages\Python312\site-packages\pandas\core\arrays\datetimes.py", line 404, in _generate_range
    freq = to_offset(freq)
           ^^^^^^^^^^^^^^^
  File "offsets.pyx", line 4460, in pandas._libs.tslibs.offsets.to_offset
  File "offsets.pyx", line 4557, in pandas._libs.tslibs.offsets.to_offset
ValueError: Invalid frequency: ME
[2025-03-19 23:57:19,000] [ERROR] [data_collection] - Erro na coleta de dados para prazos_creditos
(<class 'ValueError'>, ValueError('Invalid frequency: ME'), <traceback object at 0x0000020B07329480>)
Traceback (most recent call last):
  File "offsets.pyx", line 4447, in pandas._libs.tslibs.offsets._get_offset
KeyError: 'ME'

The above exception was the direct cause of the following exception:

Traceback (most recent call last):
  File "offsets.pyx", line 4549, in pandas._libs.tslibs.offsets.to_offset
  File "offsets.pyx", line 4453, in pandas._libs.tslibs.offsets._get_offset
ValueError: Invalid frequency: ME

The above exception was the direct cause of the following exception:

Traceback (most recent call last):
  File "c:\Users\joaop\Downloads\Projetos Cursor\FIDCs 2.0\src\data\data_collection.py", line 32, in collect_cvm_data
    df = importa_dados(nome_arquivo_fonte=arquivo, data_inicio=data_inicio)
         ^^^^^^^^^^^^^^^^^^^^^^^^^^^^^^^^^^^^^^^^^^^^^^^^^^^^^^^^^^^^^^^^^^
  File "c:\Users\joaop\Downloads\Projetos Cursor\FIDCs 2.0\src\scraping\cvm_scraper.py", line 63, in importa_dados
    datas_a_baixar = pd.date_range(start=data_inicio, end=data_atual, freq='ME')
                     ^^^^^^^^^^^^^^^^^^^^^^^^^^^^^^^^^^^^^^^^^^^^^^^^^^^^^^^^^^^
  File "C:\Users\joaop\AppData\Local\Packages\PythonSoftwareFoundation.Python.3.12_qbz5n2kfra8p0\LocalCache\local-packages\Python312\site-packages\pandas\core\indexes\datetimes.py", line 1009, in date_range
    dtarr = DatetimeArray._generate_range(
            ^^^^^^^^^^^^^^^^^^^^^^^^^^^^^^
  File "C:\Users\joaop\AppData\Local\Packages\PythonSoftwareFoundation.Python.3.12_qbz5n2kfra8p0\LocalCache\local-packages\Python312\site-packages\pandas\core\arrays\datetimes.py", line 404, in _generate_range
    freq = to_offset(freq)
           ^^^^^^^^^^^^^^^
  File "offsets.pyx", line 4460, in pandas._libs.tslibs.offsets.to_offset
  File "offsets.pyx", line 4557, in pandas._libs.tslibs.offsets.to_offset
ValueError: Invalid frequency: ME
[2025-03-19 23:57:19,002] [ERROR] [data_collection] - Erro na coleta de dados para inadimplencia
(<class 'ValueError'>, ValueError('Invalid frequency: ME'), <traceback object at 0x0000020B073294C0>)
Traceback (most recent call last):
  File "offsets.pyx", line 4447, in pandas._libs.tslibs.offsets._get_offset
KeyError: 'ME'

The above exception was the direct cause of the following exception:

Traceback (most recent call last):
  File "offsets.pyx", line 4549, in pandas._libs.tslibs.offsets.to_offset
  File "offsets.pyx", line 4453, in pandas._libs.tslibs.offsets._get_offset
ValueError: Invalid frequency: ME

The above exception was the direct cause of the following exception:

Traceback (most recent call last):
  File "c:\Users\joaop\Downloads\Projetos Cursor\FIDCs 2.0\src\data\data_collection.py", line 32, in collect_cvm_data
    df = importa_dados(nome_arquivo_fonte=arquivo, data_inicio=data_inicio)
         ^^^^^^^^^^^^^^^^^^^^^^^^^^^^^^^^^^^^^^^^^^^^^^^^^^^^^^^^^^^^^^^^^^
  File "c:\Users\joaop\Downloads\Projetos Cursor\FIDCs 2.0\src\scraping\cvm_scraper.py", line 63, in importa_dados
    datas_a_baixar = pd.date_range(start=data_inicio, end=data_atual, freq='ME')
                     ^^^^^^^^^^^^^^^^^^^^^^^^^^^^^^^^^^^^^^^^^^^^^^^^^^^^^^^^^^^
  File "C:\Users\joaop\AppData\Local\Packages\PythonSoftwareFoundation.Python.3.12_qbz5n2kfra8p0\LocalCache\local-packages\Python312\site-packages\pandas\core\indexes\datetimes.py", line 1009, in date_range
    dtarr = DatetimeArray._generate_range(
            ^^^^^^^^^^^^^^^^^^^^^^^^^^^^^^
  File "C:\Users\joaop\AppData\Local\Packages\PythonSoftwareFoundation.Python.3.12_qbz5n2kfra8p0\LocalCache\local-packages\Python312\site-packages\pandas\core\arrays\datetimes.py", line 404, in _generate_range
    freq = to_offset(freq)
           ^^^^^^^^^^^^^^^
  File "offsets.pyx", line 4460, in pandas._libs.tslibs.offsets.to_offset
  File "offsets.pyx", line 4557, in pandas._libs.tslibs.offsets.to_offset
ValueError: Invalid frequency: ME
[2025-03-19 23:57:19,005] [ERROR] [data_collection] - Erro na coleta de dados para cedentes_tomadores
(<class 'ValueError'>, ValueError('Invalid frequency: ME'), <traceback object at 0x0000020B07328040>)
Traceback (most recent call last):
  File "offsets.pyx", line 4447, in pandas._libs.tslibs.offsets._get_offset
KeyError: 'ME'

The above exception was the direct cause of the following exception:

Traceback (most recent call last):
  File "offsets.pyx", line 4549, in pandas._libs.tslibs.offsets.to_offset
  File "offsets.pyx", line 4453, in pandas._libs.tslibs.offsets._get_offset
ValueError: Invalid frequency: ME

The above exception was the direct cause of the following exception:

Traceback (most recent call last):
  File "c:\Users\joaop\Downloads\Projetos Cursor\FIDCs 2.0\src\data\data_collection.py", line 32, in collect_cvm_data
    df = importa_dados(nome_arquivo_fonte=arquivo, data_inicio=data_inicio)
         ^^^^^^^^^^^^^^^^^^^^^^^^^^^^^^^^^^^^^^^^^^^^^^^^^^^^^^^^^^^^^^^^^^
  File "c:\Users\joaop\Downloads\Projetos Cursor\FIDCs 2.0\src\scraping\cvm_scraper.py", line 63, in importa_dados
    datas_a_baixar = pd.date_range(start=data_inicio, end=data_atual, freq='ME')
                     ^^^^^^^^^^^^^^^^^^^^^^^^^^^^^^^^^^^^^^^^^^^^^^^^^^^^^^^^^^^
  File "C:\Users\joaop\AppData\Local\Packages\PythonSoftwareFoundation.Python.3.12_qbz5n2kfra8p0\LocalCache\local-packages\Python312\site-packages\pandas\core\indexes\datetimes.py", line 1009, in date_range
    dtarr = DatetimeArray._generate_range(
            ^^^^^^^^^^^^^^^^^^^^^^^^^^^^^^
  File "C:\Users\joaop\AppData\Local\Packages\PythonSoftwareFoundation.Python.3.12_qbz5n2kfra8p0\LocalCache\local-packages\Python312\site-packages\pandas\core\arrays\datetimes.py", line 404, in _generate_range
    freq = to_offset(freq)
           ^^^^^^^^^^^^^^^
  File "offsets.pyx", line 4460, in pandas._libs.tslibs.offsets.to_offset
  File "offsets.pyx", line 4557, in pandas._libs.tslibs.offsets.to_offset
ValueError: Invalid frequency: ME
[2025-03-19 23:57:19,007] [ERROR] [data_collection] - Erro na coleta de dados para precos_mercado
(<class 'ValueError'>, ValueError('Invalid frequency: ME'), <traceback object at 0x0000020B07329640>)
Traceback (most recent call last):
  File "offsets.pyx", line 4447, in pandas._libs.tslibs.offsets._get_offset
KeyError: 'ME'

The above exception was the direct cause of the following exception:

Traceback (most recent call last):
  File "offsets.pyx", line 4549, in pandas._libs.tslibs.offsets.to_offset
  File "offsets.pyx", line 4453, in pandas._libs.tslibs.offsets._get_offset
ValueError: Invalid frequency: ME

The above exception was the direct cause of the following exception:

Traceback (most recent call last):
  File "c:\Users\joaop\Downloads\Projetos Cursor\FIDCs 2.0\src\data\data_collection.py", line 32, in collect_cvm_data
    df = importa_dados(nome_arquivo_fonte=arquivo, data_inicio=data_inicio)
         ^^^^^^^^^^^^^^^^^^^^^^^^^^^^^^^^^^^^^^^^^^^^^^^^^^^^^^^^^^^^^^^^^^
  File "c:\Users\joaop\Downloads\Projetos Cursor\FIDCs 2.0\src\scraping\cvm_scraper.py", line 63, in importa_dados
    datas_a_baixar = pd.date_range(start=data_inicio, end=data_atual, freq='ME')
                     ^^^^^^^^^^^^^^^^^^^^^^^^^^^^^^^^^^^^^^^^^^^^^^^^^^^^^^^^^^^
  File "C:\Users\joaop\AppData\Local\Packages\PythonSoftwareFoundation.Python.3.12_qbz5n2kfra8p0\LocalCache\local-packages\Python312\site-packages\pandas\core\indexes\datetimes.py", line 1009, in date_range
    dtarr = DatetimeArray._generate_range(
            ^^^^^^^^^^^^^^^^^^^^^^^^^^^^^^
  File "C:\Users\joaop\AppData\Local\Packages\PythonSoftwareFoundation.Python.3.12_qbz5n2kfra8p0\LocalCache\local-packages\Python312\site-packages\pandas\core\arrays\datetimes.py", line 404, in _generate_range
    freq = to_offset(freq)
           ^^^^^^^^^^^^^^^
  File "offsets.pyx", line 4460, in pandas._libs.tslibs.offsets.to_offset
  File "offsets.pyx", line 4557, in pandas._libs.tslibs.offsets.to_offset
ValueError: Invalid frequency: ME
[2025-03-19 23:57:19,009] [ERROR] [data_collection] - Erro na coleta de dados para risco_credito
(<class 'ValueError'>, ValueError('Invalid frequency: ME'), <traceback object at 0x0000020B0732A300>)
Traceback (most recent call last):
  File "offsets.pyx", line 4447, in pandas._libs.tslibs.offsets._get_offset
KeyError: 'ME'

The above exception was the direct cause of the following exception:

Traceback (most recent call last):
  File "offsets.pyx", line 4549, in pandas._libs.tslibs.offsets.to_offset
  File "offsets.pyx", line 4453, in pandas._libs.tslibs.offsets._get_offset
ValueError: Invalid frequency: ME

The above exception was the direct cause of the following exception:

Traceback (most recent call last):
  File "c:\Users\joaop\Downloads\Projetos Cursor\FIDCs 2.0\src\data\data_collection.py", line 32, in collect_cvm_data
    df = importa_dados(nome_arquivo_fonte=arquivo, data_inicio=data_inicio)
         ^^^^^^^^^^^^^^^^^^^^^^^^^^^^^^^^^^^^^^^^^^^^^^^^^^^^^^^^^^^^^^^^^^
  File "c:\Users\joaop\Downloads\Projetos Cursor\FIDCs 2.0\src\scraping\cvm_scraper.py", line 63, in importa_dados
    datas_a_baixar = pd.date_range(start=data_inicio, end=data_atual, freq='ME')
                     ^^^^^^^^^^^^^^^^^^^^^^^^^^^^^^^^^^^^^^^^^^^^^^^^^^^^^^^^^^^
  File "C:\Users\joaop\AppData\Local\Packages\PythonSoftwareFoundation.Python.3.12_qbz5n2kfra8p0\LocalCache\local-packages\Python312\site-packages\pandas\core\indexes\datetimes.py", line 1009, in date_range
    dtarr = DatetimeArray._generate_range(
            ^^^^^^^^^^^^^^^^^^^^^^^^^^^^^^
  File "C:\Users\joaop\AppData\Local\Packages\PythonSoftwareFoundation.Python.3.12_qbz5n2kfra8p0\LocalCache\local-packages\Python312\site-packages\pandas\core\arrays\datetimes.py", line 404, in _generate_range
    freq = to_offset(freq)
           ^^^^^^^^^^^^^^^
  File "offsets.pyx", line 4460, in pandas._libs.tslibs.offsets.to_offset
  File "offsets.pyx", line 4557, in pandas._libs.tslibs.offsets.to_offset
ValueError: Invalid frequency: ME
[2025-03-19 23:57:19,012] [ERROR] [data_collection] - Erro na coleta de dados para classes_cotistas
(<class 'ValueError'>, ValueError('Invalid frequency: ME'), <traceback object at 0x0000020B07328EC0>)
Traceback (most recent call last):
  File "offsets.pyx", line 4447, in pandas._libs.tslibs.offsets._get_offset
KeyError: 'ME'

The above exception was the direct cause of the following exception:

Traceback (most recent call last):
  File "offsets.pyx", line 4549, in pandas._libs.tslibs.offsets.to_offset
  File "offsets.pyx", line 4453, in pandas._libs.tslibs.offsets._get_offset
ValueError: Invalid frequency: ME

The above exception was the direct cause of the following exception:

Traceback (most recent call last):
  File "c:\Users\joaop\Downloads\Projetos Cursor\FIDCs 2.0\src\data\data_collection.py", line 32, in collect_cvm_data
    df = importa_dados(nome_arquivo_fonte=arquivo, data_inicio=data_inicio)
         ^^^^^^^^^^^^^^^^^^^^^^^^^^^^^^^^^^^^^^^^^^^^^^^^^^^^^^^^^^^^^^^^^^
  File "c:\Users\joaop\Downloads\Projetos Cursor\FIDCs 2.0\src\scraping\cvm_scraper.py", line 63, in importa_dados
    datas_a_baixar = pd.date_range(start=data_inicio, end=data_atual, freq='ME')
                     ^^^^^^^^^^^^^^^^^^^^^^^^^^^^^^^^^^^^^^^^^^^^^^^^^^^^^^^^^^^
  File "C:\Users\joaop\AppData\Local\Packages\PythonSoftwareFoundation.Python.3.12_qbz5n2kfra8p0\LocalCache\local-packages\Python312\site-packages\pandas\core\indexes\datetimes.py", line 1009, in date_range
    dtarr = DatetimeArray._generate_range(
            ^^^^^^^^^^^^^^^^^^^^^^^^^^^^^^
  File "C:\Users\joaop\AppData\Local\Packages\PythonSoftwareFoundation.Python.3.12_qbz5n2kfra8p0\LocalCache\local-packages\Python312\site-packages\pandas\core\arrays\datetimes.py", line 404, in _generate_range
    freq = to_offset(freq)
           ^^^^^^^^^^^^^^^
  File "offsets.pyx", line 4460, in pandas._libs.tslibs.offsets.to_offset
  File "offsets.pyx", line 4557, in pandas._libs.tslibs.offsets.to_offset
ValueError: Invalid frequency: ME
[2025-03-19 23:57:19,014] [ERROR] [data_collection] - Erro na coleta de dados para distribuicao_cotistas
(<class 'ValueError'>, ValueError('Invalid frequency: ME'), <traceback object at 0x0000020B0732A5C0>)
Traceback (most recent call last):
  File "offsets.pyx", line 4447, in pandas._libs.tslibs.offsets._get_offset
KeyError: 'ME'

The above exception was the direct cause of the following exception:

Traceback (most recent call last):
  File "offsets.pyx", line 4549, in pandas._libs.tslibs.offsets.to_offset
  File "offsets.pyx", line 4453, in pandas._libs.tslibs.offsets._get_offset
ValueError: Invalid frequency: ME

The above exception was the direct cause of the following exception:

Traceback (most recent call last):
  File "c:\Users\joaop\Downloads\Projetos Cursor\FIDCs 2.0\src\data\data_collection.py", line 32, in collect_cvm_data
    df = importa_dados(nome_arquivo_fonte=arquivo, data_inicio=data_inicio)
         ^^^^^^^^^^^^^^^^^^^^^^^^^^^^^^^^^^^^^^^^^^^^^^^^^^^^^^^^^^^^^^^^^^
  File "c:\Users\joaop\Downloads\Projetos Cursor\FIDCs 2.0\src\scraping\cvm_scraper.py", line 63, in importa_dados
    datas_a_baixar = pd.date_range(start=data_inicio, end=data_atual, freq='ME')
                     ^^^^^^^^^^^^^^^^^^^^^^^^^^^^^^^^^^^^^^^^^^^^^^^^^^^^^^^^^^^
  File "C:\Users\joaop\AppData\Local\Packages\PythonSoftwareFoundation.Python.3.12_qbz5n2kfra8p0\LocalCache\local-packages\Python312\site-packages\pandas\core\indexes\datetimes.py", line 1009, in date_range
    dtarr = DatetimeArray._generate_range(
            ^^^^^^^^^^^^^^^^^^^^^^^^^^^^^^
  File "C:\Users\joaop\AppData\Local\Packages\PythonSoftwareFoundation.Python.3.12_qbz5n2kfra8p0\LocalCache\local-packages\Python312\site-packages\pandas\core\arrays\datetimes.py", line 404, in _generate_range
    freq = to_offset(freq)
           ^^^^^^^^^^^^^^^
  File "offsets.pyx", line 4460, in pandas._libs.tslibs.offsets.to_offset
  File "offsets.pyx", line 4557, in pandas._libs.tslibs.offsets.to_offset
ValueError: Invalid frequency: ME
[2025-03-19 23:57:19,016] [ERROR] [data_collection] - Erro na coleta de dados para cotas_valores
(<class 'ValueError'>, ValueError('Invalid frequency: ME'), <traceback object at 0x0000020B07329B40>)
Traceback (most recent call last):
  File "offsets.pyx", line 4447, in pandas._libs.tslibs.offsets._get_offset
KeyError: 'ME'

The above exception was the direct cause of the following exception:

Traceback (most recent call last):
  File "offsets.pyx", line 4549, in pandas._libs.tslibs.offsets.to_offset
  File "offsets.pyx", line 4453, in pandas._libs.tslibs.offsets._get_offset
ValueError: Invalid frequency: ME

The above exception was the direct cause of the following exception:

Traceback (most recent call last):
  File "c:\Users\joaop\Downloads\Projetos Cursor\FIDCs 2.0\src\data\data_collection.py", line 32, in collect_cvm_data
    df = importa_dados(nome_arquivo_fonte=arquivo, data_inicio=data_inicio)
         ^^^^^^^^^^^^^^^^^^^^^^^^^^^^^^^^^^^^^^^^^^^^^^^^^^^^^^^^^^^^^^^^^^
  File "c:\Users\joaop\Downloads\Projetos Cursor\FIDCs 2.0\src\scraping\cvm_scraper.py", line 63, in importa_dados
    datas_a_baixar = pd.date_range(start=data_inicio, end=data_atual, freq='ME')
                     ^^^^^^^^^^^^^^^^^^^^^^^^^^^^^^^^^^^^^^^^^^^^^^^^^^^^^^^^^^^
  File "C:\Users\joaop\AppData\Local\Packages\PythonSoftwareFoundation.Python.3.12_qbz5n2kfra8p0\LocalCache\local-packages\Python312\site-packages\pandas\core\indexes\datetimes.py", line 1009, in date_range
    dtarr = DatetimeArray._generate_range(
            ^^^^^^^^^^^^^^^^^^^^^^^^^^^^^^
  File "C:\Users\joaop\AppData\Local\Packages\PythonSoftwareFoundation.Python.3.12_qbz5n2kfra8p0\LocalCache\local-packages\Python312\site-packages\pandas\core\arrays\datetimes.py", line 404, in _generate_range
    freq = to_offset(freq)
           ^^^^^^^^^^^^^^^
  File "offsets.pyx", line 4460, in pandas._libs.tslibs.offsets.to_offset
  File "offsets.pyx", line 4557, in pandas._libs.tslibs.offsets.to_offset
ValueError: Invalid frequency: ME
[2025-03-19 23:57:19,018] [ERROR] [data_collection] - Erro na coleta de dados para rentabilidade
(<class 'ValueError'>, ValueError('Invalid frequency: ME'), <traceback object at 0x0000020B0732B240>)
Traceback (most recent call last):
  File "offsets.pyx", line 4447, in pandas._libs.tslibs.offsets._get_offset
KeyError: 'ME'

The above exception was the direct cause of the following exception:

Traceback (most recent call last):
  File "offsets.pyx", line 4549, in pandas._libs.tslibs.offsets.to_offset
  File "offsets.pyx", line 4453, in pandas._libs.tslibs.offsets._get_offset
ValueError: Invalid frequency: ME

The above exception was the direct cause of the following exception:

Traceback (most recent call last):
  File "c:\Users\joaop\Downloads\Projetos Cursor\FIDCs 2.0\src\data\data_collection.py", line 32, in collect_cvm_data
    df = importa_dados(nome_arquivo_fonte=arquivo, data_inicio=data_inicio)
         ^^^^^^^^^^^^^^^^^^^^^^^^^^^^^^^^^^^^^^^^^^^^^^^^^^^^^^^^^^^^^^^^^^
  File "c:\Users\joaop\Downloads\Projetos Cursor\FIDCs 2.0\src\scraping\cvm_scraper.py", line 63, in importa_dados
    datas_a_baixar = pd.date_range(start=data_inicio, end=data_atual, freq='ME')
                     ^^^^^^^^^^^^^^^^^^^^^^^^^^^^^^^^^^^^^^^^^^^^^^^^^^^^^^^^^^^
  File "C:\Users\joaop\AppData\Local\Packages\PythonSoftwareFoundation.Python.3.12_qbz5n2kfra8p0\LocalCache\local-packages\Python312\site-packages\pandas\core\indexes\datetimes.py", line 1009, in date_range
    dtarr = DatetimeArray._generate_range(
            ^^^^^^^^^^^^^^^^^^^^^^^^^^^^^^
  File "C:\Users\joaop\AppData\Local\Packages\PythonSoftwareFoundation.Python.3.12_qbz5n2kfra8p0\LocalCache\local-packages\Python312\site-packages\pandas\core\arrays\datetimes.py", line 404, in _generate_range
    freq = to_offset(freq)
           ^^^^^^^^^^^^^^^
  File "offsets.pyx", line 4460, in pandas._libs.tslibs.offsets.to_offset
  File "offsets.pyx", line 4557, in pandas._libs.tslibs.offsets.to_offset
ValueError: Invalid frequency: ME
[2025-03-19 23:57:19,022] [ERROR] [data_collection] - Erro na coleta de dados para operacoes_estruturadas
(<class 'ValueError'>, ValueError('Invalid frequency: ME'), <traceback object at 0x0000020B0732A740>)
Traceback (most recent call last):
  File "offsets.pyx", line 4447, in pandas._libs.tslibs.offsets._get_offset
KeyError: 'ME'

The above exception was the direct cause of the following exception:

Traceback (most recent call last):
  File "offsets.pyx", line 4549, in pandas._libs.tslibs.offsets.to_offset
  File "offsets.pyx", line 4453, in pandas._libs.tslibs.offsets._get_offset
ValueError: Invalid frequency: ME

The above exception was the direct cause of the following exception:

Traceback (most recent call last):
  File "c:\Users\joaop\Downloads\Projetos Cursor\FIDCs 2.0\src\data\data_collection.py", line 32, in collect_cvm_data
    df = importa_dados(nome_arquivo_fonte=arquivo, data_inicio=data_inicio)
         ^^^^^^^^^^^^^^^^^^^^^^^^^^^^^^^^^^^^^^^^^^^^^^^^^^^^^^^^^^^^^^^^^^
  File "c:\Users\joaop\Downloads\Projetos Cursor\FIDCs 2.0\src\scraping\cvm_scraper.py", line 63, in importa_dados
    datas_a_baixar = pd.date_range(start=data_inicio, end=data_atual, freq='ME')
                     ^^^^^^^^^^^^^^^^^^^^^^^^^^^^^^^^^^^^^^^^^^^^^^^^^^^^^^^^^^^
  File "C:\Users\joaop\AppData\Local\Packages\PythonSoftwareFoundation.Python.3.12_qbz5n2kfra8p0\LocalCache\local-packages\Python312\site-packages\pandas\core\indexes\datetimes.py", line 1009, in date_range
    dtarr = DatetimeArray._generate_range(
            ^^^^^^^^^^^^^^^^^^^^^^^^^^^^^^
  File "C:\Users\joaop\AppData\Local\Packages\PythonSoftwareFoundation.Python.3.12_qbz5n2kfra8p0\LocalCache\local-packages\Python312\site-packages\pandas\core\arrays\datetimes.py", line 404, in _generate_range
    freq = to_offset(freq)
           ^^^^^^^^^^^^^^^
  File "offsets.pyx", line 4460, in pandas._libs.tslibs.offsets.to_offset
  File "offsets.pyx", line 4557, in pandas._libs.tslibs.offsets.to_offset
ValueError: Invalid frequency: ME
[2025-03-19 23:57:19,025] [ERROR] [data_collection] - Erro na coleta de dados para liquidez_ativos
(<class 'ValueError'>, ValueError('Invalid frequency: ME'), <traceback object at 0x0000020B0732AF80>)
Traceback (most recent call last):
  File "offsets.pyx", line 4447, in pandas._libs.tslibs.offsets._get_offset
KeyError: 'ME'

The above exception was the direct cause of the following exception:

Traceback (most recent call last):
  File "offsets.pyx", line 4549, in pandas._libs.tslibs.offsets.to_offset
  File "offsets.pyx", line 4453, in pandas._libs.tslibs.offsets._get_offset
ValueError: Invalid frequency: ME

The above exception was the direct cause of the following exception:

Traceback (most recent call last):
  File "c:\Users\joaop\Downloads\Projetos Cursor\FIDCs 2.0\src\data\data_collection.py", line 32, in collect_cvm_data
    df = importa_dados(nome_arquivo_fonte=arquivo, data_inicio=data_inicio)
         ^^^^^^^^^^^^^^^^^^^^^^^^^^^^^^^^^^^^^^^^^^^^^^^^^^^^^^^^^^^^^^^^^^
  File "c:\Users\joaop\Downloads\Projetos Cursor\FIDCs 2.0\src\scraping\cvm_scraper.py", line 63, in importa_dados
    datas_a_baixar = pd.date_range(start=data_inicio, end=data_atual, freq='ME')
                     ^^^^^^^^^^^^^^^^^^^^^^^^^^^^^^^^^^^^^^^^^^^^^^^^^^^^^^^^^^^
  File "C:\Users\joaop\AppData\Local\Packages\PythonSoftwareFoundation.Python.3.12_qbz5n2kfra8p0\LocalCache\local-packages\Python312\site-packages\pandas\core\indexes\datetimes.py", line 1009, in date_range
    dtarr = DatetimeArray._generate_range(
            ^^^^^^^^^^^^^^^^^^^^^^^^^^^^^^
  File "C:\Users\joaop\AppData\Local\Packages\PythonSoftwareFoundation.Python.3.12_qbz5n2kfra8p0\LocalCache\local-packages\Python312\site-packages\pandas\core\arrays\datetimes.py", line 404, in _generate_range
    freq = to_offset(freq)
           ^^^^^^^^^^^^^^^
  File "offsets.pyx", line 4460, in pandas._libs.tslibs.offsets.to_offset
  File "offsets.pyx", line 4557, in pandas._libs.tslibs.offsets.to_offset
ValueError: Invalid frequency: ME
[2025-03-19 23:57:19,028] [ERROR] [data_collection] - Erro na coleta de dados para performance_fundo
(<class 'ValueError'>, ValueError('Invalid frequency: ME'), <traceback object at 0x0000020B07329500>)
Traceback (most recent call last):
  File "offsets.pyx", line 4447, in pandas._libs.tslibs.offsets._get_offset
KeyError: 'ME'

The above exception was the direct cause of the following exception:

Traceback (most recent call last):
  File "offsets.pyx", line 4549, in pandas._libs.tslibs.offsets.to_offset
  File "offsets.pyx", line 4453, in pandas._libs.tslibs.offsets._get_offset
ValueError: Invalid frequency: ME

The above exception was the direct cause of the following exception:

Traceback (most recent call last):
  File "c:\Users\joaop\Downloads\Projetos Cursor\FIDCs 2.0\src\data\data_collection.py", line 32, in collect_cvm_data
    df = importa_dados(nome_arquivo_fonte=arquivo, data_inicio=data_inicio)
         ^^^^^^^^^^^^^^^^^^^^^^^^^^^^^^^^^^^^^^^^^^^^^^^^^^^^^^^^^^^^^^^^^^
  File "c:\Users\joaop\Downloads\Projetos Cursor\FIDCs 2.0\src\scraping\cvm_scraper.py", line 63, in importa_dados
    datas_a_baixar = pd.date_range(start=data_inicio, end=data_atual, freq='ME')
                     ^^^^^^^^^^^^^^^^^^^^^^^^^^^^^^^^^^^^^^^^^^^^^^^^^^^^^^^^^^^
  File "C:\Users\joaop\AppData\Local\Packages\PythonSoftwareFoundation.Python.3.12_qbz5n2kfra8p0\LocalCache\local-packages\Python312\site-packages\pandas\core\indexes\datetimes.py", line 1009, in date_range
    dtarr = DatetimeArray._generate_range(
            ^^^^^^^^^^^^^^^^^^^^^^^^^^^^^^
  File "C:\Users\joaop\AppData\Local\Packages\PythonSoftwareFoundation.Python.3.12_qbz5n2kfra8p0\LocalCache\local-packages\Python312\site-packages\pandas\core\arrays\datetimes.py", line 404, in _generate_range
    freq = to_offset(freq)
           ^^^^^^^^^^^^^^^
  File "offsets.pyx", line 4460, in pandas._libs.tslibs.offsets.to_offset
  File "offsets.pyx", line 4557, in pandas._libs.tslibs.offsets.to_offset
ValueError: Invalid frequency: ME
[2025-03-19 23:57:19,032] [ERROR] [data_collection] - Erro na coleta de dados para garantias_seguros
(<class 'ValueError'>, ValueError('Invalid frequency: ME'), <traceback object at 0x0000020B0732BA80>)
Traceback (most recent call last):
  File "offsets.pyx", line 4447, in pandas._libs.tslibs.offsets._get_offset
KeyError: 'ME'

The above exception was the direct cause of the following exception:

Traceback (most recent call last):
  File "offsets.pyx", line 4549, in pandas._libs.tslibs.offsets.to_offset
  File "offsets.pyx", line 4453, in pandas._libs.tslibs.offsets._get_offset
ValueError: Invalid frequency: ME

The above exception was the direct cause of the following exception:

Traceback (most recent call last):
  File "c:\Users\joaop\Downloads\Projetos Cursor\FIDCs 2.0\src\data\data_collection.py", line 32, in collect_cvm_data
    df = importa_dados(nome_arquivo_fonte=arquivo, data_inicio=data_inicio)
         ^^^^^^^^^^^^^^^^^^^^^^^^^^^^^^^^^^^^^^^^^^^^^^^^^^^^^^^^^^^^^^^^^^
  File "c:\Users\joaop\Downloads\Projetos Cursor\FIDCs 2.0\src\scraping\cvm_scraper.py", line 63, in importa_dados
    datas_a_baixar = pd.date_range(start=data_inicio, end=data_atual, freq='ME')
                     ^^^^^^^^^^^^^^^^^^^^^^^^^^^^^^^^^^^^^^^^^^^^^^^^^^^^^^^^^^^
  File "C:\Users\joaop\AppData\Local\Packages\PythonSoftwareFoundation.Python.3.12_qbz5n2kfra8p0\LocalCache\local-packages\Python312\site-packages\pandas\core\indexes\datetimes.py", line 1009, in date_range
    dtarr = DatetimeArray._generate_range(
            ^^^^^^^^^^^^^^^^^^^^^^^^^^^^^^
  File "C:\Users\joaop\AppData\Local\Packages\PythonSoftwareFoundation.Python.3.12_qbz5n2kfra8p0\LocalCache\local-packages\Python312\site-packages\pandas\core\arrays\datetimes.py", line 404, in _generate_range
    freq = to_offset(freq)
           ^^^^^^^^^^^^^^^
  File "offsets.pyx", line 4460, in pandas._libs.tslibs.offsets.to_offset
  File "offsets.pyx", line 4557, in pandas._libs.tslibs.offsets.to_offset
ValueError: Invalid frequency: ME
